Workbook

Sheet Boards
A1: ID | B1: Brand | C1: Type | D1: Size | E1: Volume | F1: Year | G1: Class | H1: Sessions | I1: bjorn.k.j comments | K1: ID2 | L1: Vol | M1: Width | N1: Length | P1: XMATCH | Q1: XLookUp "-1"
A2: 13502 | B2: Fanatic | C2: Blast | D2: 66 x 232 cm | E2: 115 l | F2: 2018 | G2: Slalom Medium | H2: Fanatic Blast | K2: =_xlfn.CONCAT(F2,"-",LEFT(B2,2),"-",LEFT(C2,3),"-",L2,"-",M2,"-",N2) -> 2018-Fa-Bla-115-66-232 | L2: =_xlfn.REGEXREPLACE(E2,"[^0-9.]","")+0 -> 115 | M2: =LEFT(D2, FIND(" x", D2)-1) -> 66 | N2: =MID(D2, FIND("x ", D2)+2, FIND(" cm", D2)-FIND("x ", D2)-2) -> 232 | P2: =_xlfn.IFNA(_xlfn.XMATCH(K2,'Boards Catalogue'!A:A),-1) -> 44 | Q2: =_xlfn.XLOOKUP(K2,'Boards Catalogue'!A:A,'Boards Catalogue'!A:A,,-1) -> 2018-Fa-Bla-115-66-232
A3: 10455 | B3: Fanatic | C3: Blast 100 LTD | D3: 62 x 231 cm | E3: 100 l | F3: 2018 | G3: Slalom Medium | H3: Fanatic Blast 100 LTD | K3: =_xlfn.CONCAT(F3,"-",LEFT(B3,2),"-",LEFT(C3,3),"-",L3,"-",M3,"-",N3) -> 2018-Fa-Bla-100-62-231 | L3: =_xlfn.REGEXREPLACE(E3,"[^0-9.]","")+0 -> 100 | M3: =LEFT(D3, FIND(" x", D3)-1) -> 62 | N3: =MID(D3, FIND("x ", D3)+2, FIND(" cm", D3)-FIND("x ", D3)-2) -> 231 | P3: =_xlfn.IFNA(_xlfn.XMATCH(K3,'Boards Catalogue'!A:A),-1) -> 43 | Q3: =_xlfn.XLOOKUP(K3,'Boards Catalogue'!A:A,'Boards Catalogue'!A:A,,-1) -> 2018-Fa-Bla-100-62-231
A4: 9740 | B4: Fanatic | C4: Blast 115 LTD | D4: 66 x 232 cm | E4: 115 l | F4: 2018 | G4: Slalom Medium | H4: Fanatic Blast 115 LTD | K4: =_xlfn.CONCAT(F4,"-",LEFT(B4,2),"-",LEFT(C4,3),"-",L4,"-",M4,"-",N4) -> 2018-Fa-Bla-115-66-232 | L4: =_xlfn.REGEXREPLACE(E4,"[^0-9.]","")+0 -> 115 | M4: =LEFT(D4, FIND(" x", D4)-1) -> 66 | N4: =MID(D4, FIND("x ", D4)+2, FIND(" cm", D4)-FIND("x ", D4)-2) -> 232 | P4: =_xlfn.IFNA(_xlfn.XMATCH(K4,'Boards Catalogue'!A:A),-1) -> 44 | Q4: =_xlfn.XLOOKUP(K4,'Boards Catalogue'!A:A,'Boards Catalogue'!A:A,,-1) -> 2018-Fa-Bla-115-66-232
A5: 10388 | B5: Fanatic | C5: Blast 130 LTD | D5: 70 x 233 cm | E5: 130 l | F5: 2018 | G5: Slalom Large | H5: Fanatic Blast 130 LTD | K5: =_xlfn.CONCAT(F5,"-",LEFT(B5,2),"-",LEFT(C5,3),"-",L5,"-",M5,"-",N5) -> 2018-Fa-Bla-130-70-233 | L5: =_xlfn.REGEXREPLACE(E5,"[^0-9.]","")+0 -> 130 | M5: =LEFT(D5, FIND(" x", D5)-1) -> 70 | N5: =MID(D5, FIND("x ", D5)+2, FIND(" cm", D5)-FIND("x ", D5)-2) -> 233 | P5: =_xlfn.IFNA(_xlfn.XMATCH(K5,'Boards Catalogue'!A:A),-1) -> 45 | Q5: =_xlfn.XLOOKUP(K5,'Boards Catalogue'!A:A,'Boards Catalogue'!A:A,,-1) -> 2018-Fa-Bla-130-70-233
A6: 12165 | B6: Fanatic | C6: Blast 130 LTD | D6: 73 x 233 cm | E6: 130 l | F6: 2018 | G6: Slalom Large | H6: Fanatic Blast 130 LTD | K6: =_xlfn.CONCAT(F6,"-",LEFT(B6,2),"-",LEFT(C6,3),"-",L6,"-",M6,"-",N6) -> 2018-Fa-Bla-130-73-233 | L6: =_xlfn.REGEXREPLACE(E6,"[^0-9.]","")+0 -> 130 | M6: =LEFT(D6, FIND(" x", D6)-1) -> 73 | N6: =MID(D6, FIND("x ", D6)+2, FIND(" cm", D6)-FIND("x ", D6)-2) -> 233 | P6: =_xlfn.IFNA(_xlfn.XMATCH(K6,'Boards Catalogue'!A:A),-1) -> -1 | Q6: =_xlfn.XLOOKUP(K6,'Boards Catalogue'!A:A,'Boards Catalogue'!A:A,,-1) -> 2018-Fa-Bla-130-70-233
A7: 11191 | B7: Fanatic | C7: Blast 145 LTD | D7: 77 x 235 cm | E7: 145 l | F7: 2018 | G7: Slalom Medium | H7: Fanatic Blast 145 LTD | K7: =_xlfn.CONCAT(F7,"-",LEFT(B7,2),"-",LEFT(C7,3),"-",L7,"-",M7,"-",N7) -> 2018-Fa-Bla-145-77-235 | L7: =_xlfn.REGEXREPLACE(E7,"[^0-9.]","")+0 -> 145 | M7: =LEFT(D7, FIND(" x", D7)-1) -> 77 | N7: =MID(D7, FIND("x ", D7)+2, FIND(" cm", D7)-FIND("x ", D7)-2) -> 235 | P7: =_xlfn.IFNA(_xlfn.XMATCH(K7,'Boards Catalogue'!A:A),-1) -> 46 | Q7: =_xlfn.XLOOKUP(K7,'Boards Catalogue'!A:A,'Boards Catalogue'!A:A,,-1) -> 2018-Fa-Bla-145-77-235
A8: 10662 | B8: Fanatic | C8: Falcon 114 TE | D8: 71 x 230 cm | E8: 114 l | F8: 2018 | G8: Slalom Medium | H8: Fanatic Falcon 114 TE | K8: =_xlfn.CONCAT(F8,"-",LEFT(B8,2),"-",LEFT(C8,3),"-",L8,"-",M8,"-",N8) -> 2018-Fa-Fal-114-71-230 | L8: =_xlfn.REGEXREPLACE(E8,"[^0-9.]","")+0 -> 114 | M8: =LEFT(D8, FIND(" x", D8)-1) -> 71 | N8: =MID(D8, FIND("x ", D8)+2, FIND(" cm", D8)-FIND("x ", D8)-2) -> 230 | P8: =_xlfn.IFNA(_xlfn.XMATCH(K8,'Boards Catalogue'!A:A),-1) -> 53 | Q8: =_xlfn.XLOOKUP(K8,'Boards Catalogue'!A:A,'Boards Catalogue'!A:A,,-1) -> 2018-Fa-Fal-114-71-230
A9: 10391 | B9: Fanatic | C9: Falcon 129 | D9: 80 x 230 cm | E9: 129 l | F9: 2018 | G9: Slalom Large | H9: Fanatic Falcon 129 | K9: =_xlfn.CONCAT(F9,"-",LEFT(B9,2),"-",LEFT(C9,3),"-",L9,"-",M9,"-",N9) -> 2018-Fa-Fal-129-80-230 | L9: =_xlfn.REGEXREPLACE(E9,"[^0-9.]","")+0 -> 129 | M9: =LEFT(D9, FIND(" x", D9)-1) -> 80 | N9: =MID(D9, FIND("x ", D9)+2, FIND(" cm", D9)-FIND("x ", D9)-2) -> 230 | P9: =_xlfn.IFNA(_xlfn.XMATCH(K9,'Boards Catalogue'!A:A),-1) -> 55 | Q9: =_xlfn.XLOOKUP(K9,'Boards Catalogue'!A:A,'Boards Catalogue'!A:A,,-1) -> 2018-Fa-Fal-129-80-230
A10: 10650 | B10: Fanatic | C10: Falcon 89 | D10: 60 x 235 cm | E10: 89 l | F10: 2018 | G10: Speed/Slalom Small | H10: Fanatic Falcon 89 | K10: =_xlfn.CONCAT(F10,"-",LEFT(B10,2),"-",LEFT(C10,3),"-",L10,"-",M10,"-",N10) -> 2018-Fa-Fal-89-60-235 | L10: =_xlfn.REGEXREPLACE(E10,"[^0-9.]","")+0 -> 89 | M10: =LEFT(D10, FIND(" x", D10)-1) -> 60 | N10: =MID(D10, FIND("x ", D10)+2, FIND(" cm", D10)-FIND("x ", D10)-2) -> 235 | P10: =_xlfn.IFNA(_xlfn.XMATCH(K10,'Boards Catalogue'!A:A),-1) -> 51 | Q10: =_xlfn.XLOOKUP(K10,'Boards Catalogue'!A:A,'Boards Catalogue'!A:A,,-1) -> 2018-Fa-Fal-89-60-235
A11: 10419 | B11: Fanatic | C11: Falcon Lightwind | D11: 90 x 230 cm | E11: 159 l | F11: 2018 | G11: Slalom Xtra Large | H11: Fanatic Falcon Lightwind | K11: =_xlfn.CONCAT(F11,"-",LEFT(B11,2),"-",LEFT(C11,3),"-",L11,"-",M11,"-",N11) -> 2018-Fa-Fal-159-90-230 | L11: =_xlfn.REGEXREPLACE(E11,"[^0-9.]","")+0 -> 159 | M11: =LEFT(D11, FIND(" x", D11)-1) -> 90 | N11: =MID(D11, FIND("x ", D11)+2, FIND(" cm", D11)-FIND("x ", D11)-2) -> 230 | P11: =_xlfn.IFNA(_xlfn.XMATCH(K11,'Boards Catalogue'!A:A),-1) -> 57 | Q11: =_xlfn.XLOOKUP(K11,'Boards Catalogue'!A:A,'Boards Catalogue'!A:A,,-1) -> 2018-Fa-Fal-159-90-230
A12: 10683 | B12: Fanatic | C12: Falcon Speed 40 | D12: 40 x 228 cm | E12: 55 l | F12: 2018 | G12: Speedboard | H12: Fanatic Falcon Speed 40 | K12: =_xlfn.CONCAT(F12,"-",LEFT(B12,2),"-",LEFT(C12,3),"-",L12,"-",M12,"-",N12) -> 2018-Fa-Fal-55-40-228 | L12: =_xlfn.REGEXREPLACE(E12,"[^0-9.]","")+0 -> 55 | M12: =LEFT(D12, FIND(" x", D12)-1) -> 40 | N12: =MID(D12, FIND("x ", D12)+2, FIND(" cm", D12)-FIND("x ", D12)-2) -> 228 | P12: =_xlfn.IFNA(_xlfn.XMATCH(K12,'Boards Catalogue'!A:A),-1) -> -1 | Q12: =_xlfn.XLOOKUP(K12,'Boards Catalogue'!A:A,'Boards Catalogue'!A:A,,-1) -> 2018-Fa-Fal-54-44-230
A13: 10290 | B13: Fanatic | C13: Falcon Speed 52.5 | D13: 525 x 235 cm | E13: 70 l | F13: 2018 | G13: Speed/Slalom Small | H13: Fanatic Falcon Speed 52.5 | K13: =_xlfn.CONCAT(F13,"-",LEFT(B13,2),"-",LEFT(C13,3),"-",L13,"-",M13,"-",N13) -> 2018-Fa-Fal-70-525-235 | L13: =_xlfn.REGEXREPLACE(E13,"[^0-9.]","")+0 -> 70 | M13: =LEFT(D13, FIND(" x", D13)-1) -> 525 | N13: =MID(D13, FIND("x ", D13)+2, FIND(" cm", D13)-FIND("x ", D13)-2) -> 235 | P13: =_xlfn.IFNA(_xlfn.XMATCH(K13,'Boards Catalogue'!A:A),-1) -> -1 | Q13: =_xlfn.XLOOKUP(K13,'Boards Catalogue'!A:A,'Boards Catalogue'!A:A,,-1) -> 2018-Fa-Fal-70-52-230
... A34: 13285 | B34: Fanatic | C34: Wave | D34: 64 x 232 cm | E34: 103 l | F34: 2018 | G34: Wave / Freestyle | H34: Fanatic Wave | K34: =_xlfn.CONCAT(F34,"-",LEFT(B34,2),"-",LEFT(C34,3),"-",L34,"-",M34,"-",N34) -> 2018-Fa-Wav-103-64-232 | L34: =_xlfn.REGEXREPLACE(E34,"[^0-9.]","")+0 -> 103 | M34: =LEFT(D34, FIND(" x", D34)-1) -> 64 | N34: =MID(D34, FIND("x ", D34)+2, FIND(" cm", D34)-FIND("x ", D34)-2) -> 232 | P34: =_xlfn.IFNA(_xlfn.XMATCH(K34,'Boards Catalogue'!A:A),-1) -> -1 | Q34: =_xlfn.XLOOKUP(K34,'Boards Catalogue'!A:A,'Boards Catalogue'!A:A,,-1) -> 2018-Fa-Vip-355-85-335

Sheet Boards Catalogue
A1: ID | B1: YEAR | C1: Brand | D1: MODELS | E1: VOLUME | F1: WIDTH | G1: LENGTH | H1: TECHNOLOGY | I1: FIN BOXES | J1: FINS | K1: REC. SAIL SIZES
A2: =_xlfn.CONCAT(B2,"-",LEFT(C2,2),"-",LEFT(D2,3),"-",E2,"-",TRUNC(F2),"-",TRUNC(G2)) -> 2018-Fa-Stu-76-55-212 | B2: 2018 | C2: Fanatic | D2: Stubby TE 76 | E2: 76 | F2: 55 | G2: 212 | H2: BXIC | I2: 2 × Slot Box,_x000D_Center US Box | J2: CF 2 × 12cm, 17cm | K2: Up to 5.3 m2
A3: =_xlfn.CONCAT(B3,"-",LEFT(C3,2),"-",LEFT(D3,3),"-",E3,"-",TRUNC(F3),"-",TRUNC(G3)) -> 2018-Fa-Stu-82-56-214 | B3: 2018 | C3: Fanatic | D3: Stubby TE 82 | E3: 82 | F3: 56 | G3: 214 | J3: CF 2 × 12cm, 17cm | K3: Up to 5.8 m2
A4: =_xlfn.CONCAT(B4,"-",LEFT(C4,2),"-",LEFT(D4,3),"-",E4,"-",TRUNC(F4),"-",TRUNC(G4)) -> 2018-Fa-Stu-89-57-215 | B4: 2018 | C4: Fanatic | D4: Stubby TE 89 | E4: 89 | F4: 57.5 | G4: 215 | J4: CF 2 × 12cm, 18cm | K4: Up to 6.2 m2
A5: =_xlfn.CONCAT(B5,"-",LEFT(C5,2),"-",LEFT(D5,3),"-",E5,"-",TRUNC(F5),"-",TRUNC(G5)) -> 2018-Fa-Stu-99-60-218 | B5: 2018 | C5: Fanatic | D5: Stubby TE 99 | E5: 99 | F5: 60 | G5: 218 | J5: CF 2 × 12cm, 18cm | K5: Up to 6.5 m2
A6: =_xlfn.CONCAT(B6,"-",LEFT(C6,2),"-",LEFT(D6,3),"-",E6,"-",TRUNC(F6),"-",TRUNC(G6)) -> 2018-Fa-Gri-68-54-220 | B6: 2018 | C6: Fanatic | D6: Grip TE 68 | E6: 68 | F6: 54 | G6: 220 | H6: BXIC | I6: 4 × Slot Box | J6: CF 2 × 9 cm, 2 × 14cm | K6: Up to 5.0 m2
A7: =_xlfn.CONCAT(B7,"-",LEFT(C7,2),"-",LEFT(D7,3),"-",E7,"-",TRUNC(F7),"-",TRUNC(G7)) -> 2018-Fa-Gri-76-56-222 | B7: 2018 | C7: Fanatic | D7: Grip TE 76 | E7: 76 | F7: 56 | G7: 222 | I7: 5 × Slot Box | J7: CF 2 × 9.5 cm, 2 × 14.5 cm | K7: Up to 5.3 m2
A8: =_xlfn.CONCAT(B8,"-",LEFT(C8,2),"-",LEFT(D8,3),"-",E8,"-",TRUNC(F8),"-",TRUNC(G8)) -> 2018-Fa-Gri-82-58-224 | B8: 2018 | C8: Fanatic | D8: Grip TE 82 | E8: 82 | F8: 58 | G8: 224 | J8: CF 2 × 9.5 cm, 2 × 14.5 cm | K8: Up to 5.8 m2
A9: =_xlfn.CONCAT(B9,"-",LEFT(C9,2),"-",LEFT(D9,3),"-",E9,"-",TRUNC(F9),"-",TRUNC(G9)) -> 2018-Fa-Gri-89-59-226 | B9: 2018 | C9: Fanatic | D9: Grip TE 89 | E9: 89 | F9: 59.5 | G9: 226 | J9: CF 2 × 10 cm, 2 × 14.5 cm | K9: Up to 6.2 m2
A10: =_xlfn.CONCAT(B10,"-",LEFT(C10,2),"-",LEFT(D10,3),"-",E10,"-",TRUNC(F10),"-",TRUNC(G10)) -> 2018-Fa-Gri-99-62-229 | B10: 2018 | C10: Fanatic | D10: Grip TE 99 | E10: 99 | F10: 62 | G10: 229 | H10: 2 × Slot Box, C. US Box | I10: MFC TF Black 2 × 12cm, 19 cm | J10: Up to 6.5 m2
A11: =_xlfn.CONCAT(B11,"-",LEFT(C11,2),"-",LEFT(D11,3),"-",E11,"-",TRUNC(F11),"-",TRUNC(G11)) -> 2018-Fa-Fre-85-57-225 | B11: 2018 | C11: Fanatic | D11: FreeWave STB TXTR 85 | E11: 85 | F11: 57.5 | G11: 225 | H11: TXTR / BXIC | I11: 2 × Slot Box,_x000D_Power Box | J11: MFC TF Black 2 × 12 cm, 18 cm | K11: Up to 6.0 m2
A12: =_xlfn.CONCAT(B12,"-",LEFT(C12,2),"-",LEFT(D12,3),"-",E12,"-",TRUNC(F12),"-",TRUNC(G12)) -> 2018-Fa-Fre-95-60-227 | B12: 2018 | C12: Fanatic | D12: FreeWave STB TXTR 95 | E12: 95 | F12: 60 | G12: 227 | J12: MFC TF Black 2 × 12 cm, 19 cm | K12: Up to 6.2 m2
A13: =_xlfn.CONCAT(B13,"-",LEFT(C13,2),"-",LEFT(D13,3),"-",E13,"-",TRUNC(F13),"-",TRUNC(G13)) -> 2018-Fa-Fre-105-62-229 | B13: 2018 | C13: Fanatic | D13: FreeWave STB TXTR 105 | E13: 105 | F13: 62.5 | G13: 229 | J13: MFC TF Black 2 × 12 cm, 20 cm | K13: Up to 6.8 m2
A14: =_xlfn.CONCAT(B14,"-",LEFT(C14,2),"-",LEFT(D14,3),"-",E14,"-",TRUNC(F14),"-",TRUNC(G14)) -> 2018-Fa-Fre-115-65-231 | B14: 2018 | C14: Fanatic | D14: FreeWave STB TXTR 115 | E14: 115 | F14: 65 | G14: 231 | J14: MFC 30 cm | K14: Up to 7.5 m2
A15: =_xlfn.CONCAT(B15,"-",LEFT(C15,2),"-",LEFT(D15,3),"-",E15,"-",TRUNC(F15),"-",TRUNC(G15)) -> 2018-Fa-Fre-85-57-225 | B15: 2018 | C15: Fanatic | D15: FreeWave STB TE 85 | E15: 85 | F15: 57.5 | G15: 225 | H15: BXIC | I15: 2 × Slot Box,_x000D_Power Box | J15: MFC TF Black 2 × 12 cm, 18 cm | K15: Up to 6.0 m2
A16: =_xlfn.CONCAT(B16,"-",LEFT(C16,2),"-",LEFT(D16,3),"-",E16,"-",TRUNC(F16),"-",TRUNC(G16)) -> 2018-Fa-Fre-95-60-227 | B16: 2018 | C16: Fanatic | D16: FreeWave STB TE 95 | E16: 95 | F16: 60 | G16: 227 | J16: MFC TF Black 2 × 12 cm, 19 cm | K16: Up to 6.2 m2
A17: =_xlfn.CONCAT(B17,"-",LEFT(C17,2),"-",LEFT(D17,3),"-",E17,"-",TRUNC(F17),"-",TRUNC(G17)) -> 2018-Fa-Fre-105-62-229 | B17: 2018 | C17: Fanatic | D17: FreeWave STB TE 105 | E17: 105 | F17: 62.5 | G17: 229 | J17: MFC TF Black 2 × 12 cm, 20 cm | K17: Up to 6.8 m2
A18: =_xlfn.CONCAT(B18,"-",LEFT(C18,2),"-",LEFT(D18,3),"-",E18,"-",TRUNC(F18),"-",TRUNC(G18)) -> 2018-Fa-Fre-115-65-231 | B18: 2018 | C18: Fanatic | D18: FreeWave STB TE 115 | E18: 115 | F18: 65 | G18: 231 | J18: MFC 30 cm | K18: Up to 7.5 m2
A19: =_xlfn.CONCAT(B19,"-",LEFT(C19,2),"-",LEFT(D19,3),"-",E19,"-",TRUNC(F19),"-",TRUNC(G19)) -> 2018-Fa-Fre-85-57-225 | B19: 2018 | C19: Fanatic | D19: FreeWave STB 85 | E19: 85 | F19: 57.5 | G19: 225 | H19: BXF | I19: 2 × Slot Box,_x000D_Power Box | J19: CF 26 cm | K19: Up to 6.0 m2
A20: =_xlfn.CONCAT(B20,"-",LEFT(C20,2),"-",LEFT(D20,3),"-",E20,"-",TRUNC(F20),"-",TRUNC(G20)) -> 2018-Fa-Fre-95-60-227 | B20: 2018 | C20: Fanatic | D20: FreeWave STB 95 | E20: 95 | F20: 60 | G20: 227 | J20: CF 28 cm | K20: Up to 6.2 m2
A21: =_xlfn.CONCAT(B21,"-",LEFT(C21,2),"-",LEFT(D21,3),"-",E21,"-",TRUNC(F21),"-",TRUNC(G21)) -> 2018-Fa-Fre-105-62-229 | B21: 2018 | C21: Fanatic | D21: FreeWave STB 105 | E21: 105 | F21: 62.5 | G21: 229 | J21: CF 30 cm | K21: Up to 6.8 m2
A22: =_xlfn.CONCAT(B22,"-",LEFT(C22,2),"-",LEFT(D22,3),"-",E22,"-",TRUNC(F22),"-",TRUNC(G22)) -> 2018-Fa-Ska-86-60-228 | B22: 2018 | C22: Fanatic | D22: Skate TE 86 | E22: 86 | F22: 60 | G22: 228 | H22: BXIC | I22: Power Box | J22: CF Composite Innegra 17.5 cm | K22: Up to 5.3 m2
A23: =_xlfn.CONCAT(B23,"-",LEFT(C23,2),"-",LEFT(D23,3),"-",E23,"-",TRUNC(F23),"-",TRUNC(G23)) -> 2018-Fa-Ska-93-62-225 | B23: 2018 | C23: Fanatic | D23: Skate TE 93 | E23: 93 | F23: 62 | G23: 225 | J23: CF Composite Innegra 18.5 cm | K23: Up to 5.9 m2
A24: =_xlfn.CONCAT(B24,"-",LEFT(C24,2),"-",LEFT(D24,3),"-",E24,"-",TRUNC(F24),"-",TRUNC(G24)) -> 2018-Fa-Ska-100-64-228 | B24: 2018 | C24: Fanatic | D24: Skate TE 100 | E24: 100 | F24: 64 | G24: 228 | J24: CF Composite Innegra 20 cm | K24: Up to 6.2 m2
A25: =_xlfn.CONCAT(B25,"-",LEFT(C25,2),"-",LEFT(D25,3),"-",E25,"-",TRUNC(F25),"-",TRUNC(G25)) -> 2018-Fa-Ska-108-66-226 | B25: 2018 | C25: Fanatic | D25: Skate TE 108 | E25: 108 | F25: 66.5 | G25: 226 | J25: CF Composite Innegra 22 cm | K25: Up to 6.7 m2
A26: =_xlfn.CONCAT(B26,"-",LEFT(C26,2),"-",LEFT(D26,3),"-",E26,"-",TRUNC(F26),"-",TRUNC(G26)) -> 2018-Fa-Gec-98-63-239 | B26: 2018 | C26: Fanatic | D26: Gecko LTD 98 | E26: 98 | F26: 63 | G26: 239 | H26: BXF | I26: Power Box | J26: CF Composite Black 34 cm | K26: Up to 7.5 m2
A27: =_xlfn.CONCAT(B27,"-",LEFT(C27,2),"-",LEFT(D27,3),"-",E27,"-",TRUNC(F27),"-",TRUNC(G27)) -> 2018-Fa-Gec-105-69-239 | B27: 2018 | C27: Fanatic | D27: Gecko LTD 105 | E27: 105 | F27: 69 | G27: 239 | J27: CF Composite Black 36 cm | K27: Up to 8.0 m2
A28: =_xlfn.CONCAT(B28,"-",LEFT(C28,2),"-",LEFT(D28,3),"-",E28,"-",TRUNC(F28),"-",TRUNC(G28)) -> 2018-Fa-Gec-112-73-239 | B28: 2018 | C28: Fanatic | D28: Gecko LTD 112 | E28: 112 | F28: 73 | G28: 239 | J28: CF Composite Black 38 cm | K28: Up to 8.5 m2
A29: =_xlfn.CONCAT(B29,"-",LEFT(C29,2),"-",LEFT(D29,3),"-",E29,"-",TRUNC(F29),"-",TRUNC(G29)) -> 2018-Fa-Gec-120-76-242 | B29: 2018 | C29: Fanatic | D29: Gecko LTD 120 | E29: 120 | F29: 76 | G29: 242 | J29: CF Composite Black 40 cm | K29: Up to 9.0 m2
A30: =_xlfn.CONCAT(B30,"-",LEFT(C30,2),"-",LEFT(D30,3),"-",E30,"-",TRUNC(F30),"-",TRUNC(G30)) -> 2018-Fa-Gec-133-78-246 | B30: 2018 | C30: Fanatic | D30: Gecko LTD 133 | E30: 133 | F30: 78 | G30: 246 | J30: CF Composite Black 42 cm | K30: Up to 9.5 m2
A31: =_xlfn.CONCAT(B31,"-",LEFT(C31,2),"-",LEFT(D31,3),"-",E31,"-",TRUNC(F31),"-",TRUNC(G31)) -> 2018-Fa-Gec-146-83-250 | B31: 2018 | C31: Fanatic | D31: Gecko LTD 146 | E31: 146 | F31: 83 | G31: 250 | J31: CF Composite Black 46 cm | K31: Up to 10 m2
A32: =_xlfn.CONCAT(B32,"-",LEFT(C32,2),"-",LEFT(D32,3),"-",E32,"-",TRUNC(F32),"-",TRUNC(G32)) -> 2018-Fa-Gec-120-76-242 | B32: 2018 | C32: Fanatic | D32: Gecko Foil Edition 120 | E32: 120 | F32: 76 | G32: 242 | H32: BXF | I32: FOIL Tuttle Box | J32: CF Composite Black 42 cm | K32: Up to 9.0 m2
A33: =_xlfn.CONCAT(B33,"-",LEFT(C33,2),"-",LEFT(D33,3),"-",E33,"-",TRUNC(F33),"-",TRUNC(G33)) -> 2018-Fa-Gec-133-78-246 | B33: 2018 | C33: Fanatic | D33: Gecko Foil Edition 133 | E33: 133 | F33: 78 | G33: 246 | J33: CF Composite Black 44 cm | K33: Up to 9.5 m2
A34: =_xlfn.CONCAT(B34,"-",LEFT(C34,2),"-",LEFT(D34,3),"-",E34,"-",TRUNC(F34),"-",TRUNC(G34)) -> 2018-Fa-Gec-112-73-239 | B34: 2018 | C34: Fanatic | D34: Gecko Eco 112 | E34: 112 | F34: 73 | G34: 239 | H34: CBC | I34: Power Box | J34: CF Composite Black 38 cm | K34: Up to 8.5 m2
A35: =_xlfn.CONCAT(B35,"-",LEFT(C35,2),"-",LEFT(D35,3),"-",E35,"-",TRUNC(F35),"-",TRUNC(G35)) -> 2018-Fa-Gec-98-63-239 | B35: 2018 | C35: Fanatic | D35: Gecko HRS 98 | E35: 98 | F35: 63 | G35: 239 | H35: HRS | I35: Power Box | J35: CF White 34 cm | K35: Up to 7.5 m2
A36: =_xlfn.CONCAT(B36,"-",LEFT(C36,2),"-",LEFT(D36,3),"-",E36,"-",TRUNC(F36),"-",TRUNC(G36)) -> 2018-Fa-Gec-105-69-239 | B36: 2018 | C36: Fanatic | D36: Gecko HRS 105 | E36: 105 | F36: 69 | G36: 239 | J36: CF White 36 cm | K36: Up to 8.0 m2
A37: =_xlfn.CONCAT(B37,"-",LEFT(C37,2),"-",LEFT(D37,3),"-",E37,"-",TRUNC(F37),"-",TRUNC(G37)) -> 2018-Fa-Gec-112-73-239 | B37: 2018 | C37: Fanatic | D37: Gecko HRS 112 | E37: 112 | F37: 73 | G37: 239 | J37: CF White 38 cm | K37: Up to 8.5 m2
A38: =_xlfn.CONCAT(B38,"-",LEFT(C38,2),"-",LEFT(D38,3),"-",E38,"-",TRUNC(F38),"-",TRUNC(G38)) -> 2018-Fa-Gec-120-76-242 | B38: 2018 | C38: Fanatic | D38: Gecko HRS 120 | E38: 120 | F38: 76 | G38: 242 | J38: CF White 40 cm | K38: Up to 9.0 m2
A39: =_xlfn.CONCAT(B39,"-",LEFT(C39,2),"-",LEFT(D39,3),"-",E39,"-",TRUNC(F39),"-",TRUNC(G39)) -> 2018-Fa-Gec-133-78-246 | B39: 2018 | C39: Fanatic | D39: Gecko HRS 133 | E39: 133 | F39: 78 | G39: 246 | J39: CF White 42 cm | K39: Up to 9.5 m2
A40: =_xlfn.CONCAT(B40,"-",LEFT(C40,2),"-",LEFT(D40,3),"-",E40,"-",TRUNC(F40),"-",TRUNC(G40)) -> 2018-Fa-Gec-146-83-250 | B40: 2018 | C40: Fanatic | D40: Gecko HRS 146 | E40: 146 | F40: 83 | G40: 250 | J40: CF White 46 cm | K40: Up to 10 m2
...

Sheet To Add After Review
A2: YEAR | B2: Brand | C2: MODELS | D2: VOLUME | E2: WIDTH | F2: LENGTH | G2: TECHNOLOGY | H2: FIN BOXES | I2: FINS | J2: REC. SAIL SIZES
C3: MODEL | D3: VOLUME | E3: WIDTH | F3: LENGTH | G3: BOARD TECHNOLOGIES | J3: REC. SAIL SIZES
A4: 2016 | B4: Fanatic | C4: Quad TE 69 NEW SHAPE | D4: 69 | E4: 53.5 | F4: 224 | G4: IC / LF | J4: 3.3 – 5.0 m2
A5: 2016 | B5: Fanatic | C5: Quad TE 75 NEW SHAPE | D5: 75 | E5: 55.5 | F5: 225 | G5: IC / LF | J5: 3.7 – 5.3 m2
A6: 2016 | B6: Fanatic | C6: Quad TE 81 NEW SHAPE | D6: 81 | E6: 57.5 | F6: 226 | G6: IC / LF | J6: 4.0 – 5.8 m2
A7: 2016 | B7: Fanatic | C7: Quad TE 90 NEW SHAPE | D7: 90 | E7: 59.5 | F7: 227 | G7: IC / LF | J7: 4.2 – 6.5 m2
A8: 2016 | B8: Fanatic | C8: Stubby TE 77 NEW SHAPE | D8: 77 | E8: 55 | F8: 212 | G8: IC / LF | J8: 3.3 – 5.3 m2
A9: 2016 | B9: Fanatic | C9: Stubby TE 88 NEW SHAPE | D9: 88 | E9: 57.5 | F9: 215 | G9: IC / LF | J9: 4.0 – 5.8 m2
A10: 2016 | B10: Fanatic | C10: TriWave TE 74 NEW SHAPE | D10: 74 | E10: 56 | F10: 222 | G10: IC / LF | J10: 3.5 – 5.3 m2
A11: 2016 | B11: Fanatic | C11: TriWave TE 82 NEW SHAPE | D11: 82 | E11: 58 | F11: 224 | G11: IC / LF | J11: 4.0 – 5.8 m2
A12: 2016 | B12: Fanatic | C12: TriWave TE 89 NEW SHAPE | D12: 89 | E12: 59.5 | F12: 227 | G12: IC / LF | J12: 4.2 – 6.2 m2
A13: 2016 | B13: Fanatic | C13: TriWave TE 99 NEW SHAPE | D13: 99 | E13: 62 | F13: 229 | G13: IC / LF | J13: 4.5 – 6.7 m2
A14: 2016 | B14: Fanatic | C14: FreeWave TE 76; FreeWave CWS 76 | D14: 76 | E14: 56 | F14: 232 | G14: IC / LF; CWS | J14: 3.7 – 6.0 m2
A15: 2016 | B15: Fanatic | C15: FreeWave TeXtreme® 86; FreeWave TE 86; FreeWave CWS 86 | D15: 86 | E15: 58.5 | F15: 233 | G15: TeXtreme® IC / LF; IC / LF; CWS | J15: 4.2 – 6.5 m2
... A54: 2016 | B54: Fanatic | C54: Ripper Air WS 187 NEW SHAPE | D54: 187 | E54: 73.7 | F54: 274.3 | G54: Double Layer Heavy Duty | J54: 1.0 – 6.5 m2

Sheet Temp
A1: 69 l | B1: 53.5 cm | C1: 224 cm | E1: =_xlfn.REGEXREPLACE(A1,"[^0-9.]","")+0 -> 69 | F1: =_xlfn.REGEXREPLACE(B1,"[^0-9.]","")+0 -> 53.5 | G1: =_xlfn.REGEXREPLACE(C1,"[^0-9.]","")+0 -> 224
A2: 75 l | B2: 55.5 cm | C2: 225 cm | E2: =_xlfn.REGEXREPLACE(A2,"[^0-9.]","")+0 -> 75 | F2: =_xlfn.REGEXREPLACE(B2,"[^0-9.]","")+0 -> 55.5 | G2: =_xlfn.REGEXREPLACE(C2,"[^0-9.]","")+0 -> 225
A3: 81 l | B3: 57.5 cm | C3: 226 cm | E3: =_xlfn.REGEXREPLACE(A3,"[^0-9.]","")+0 -> 81 | F3: =_xlfn.REGEXREPLACE(B3,"[^0-9.]","")+0 -> 57.5 | G3: =_xlfn.REGEXREPLACE(C3,"[^0-9.]","")+0 -> 226
A4: 90 l | B4: 59.5 cm | C4: 227 cm | E4: =_xlfn.REGEXREPLACE(A4,"[^0-9.]","")+0 -> 90 | F4: =_xlfn.REGEXREPLACE(B4,"[^0-9.]","")+0 -> 59.5 | G4: =_xlfn.REGEXREPLACE(C4,"[^0-9.]","")+0 -> 227
A5: 77 l | B5: 55 cm | C5: 212 cm | E5: =_xlfn.REGEXREPLACE(A5,"[^0-9.]","")+0 -> 77 | F5: =_xlfn.REGEXREPLACE(B5,"[^0-9.]","")+0 -> 55 | G5: =_xlfn.REGEXREPLACE(C5,"[^0-9.]","")+0 -> 212
A6: 88 l | B6: 57.5 cm | C6: 215 cm | E6: =_xlfn.REGEXREPLACE(A6,"[^0-9.]","")+0 -> 88 | F6: =_xlfn.REGEXREPLACE(B6,"[^0-9.]","")+0 -> 57.5 | G6: =_xlfn.REGEXREPLACE(C6,"[^0-9.]","")+0 -> 215
A7: 74 l | B7: 56 cm | C7: 222 cm | E7: =_xlfn.REGEXREPLACE(A7,"[^0-9.]","")+0 -> 74 | F7: =_xlfn.REGEXREPLACE(B7,"[^0-9.]","")+0 -> 56 | G7: =_xlfn.REGEXREPLACE(C7,"[^0-9.]","")+0 -> 222
A8: 82 l | B8: 58 cm | C8: 224 cm | E8: =_xlfn.REGEXREPLACE(A8,"[^0-9.]","")+0 -> 82 | F8: =_xlfn.REGEXREPLACE(B8,"[^0-9.]","")+0 -> 58 | G8: =_xlfn.REGEXREPLACE(C8,"[^0-9.]","")+0 -> 224
A9: 89 l | B9: 59.5 cm | C9: 227 cm | E9: =_xlfn.REGEXREPLACE(A9,"[^0-9.]","")+0 -> 89 | F9: =_xlfn.REGEXREPLACE(B9,"[^0-9.]","")+0 -> 59.5 | G9: =_xlfn.REGEXREPLACE(C9,"[^0-9.]","")+0 -> 227
A10: 99 l | B10: 62 cm | C10: 229 cm | E10: =_xlfn.REGEXREPLACE(A10,"[^0-9.]","")+0 -> 99 | F10: =_xlfn.REGEXREPLACE(B10,"[^0-9.]","")+0 -> 62 | G10: =_xlfn.REGEXREPLACE(C10,"[^0-9.]","")+0 -> 229
A11: 76 l | B11: 56 cm | C11: 232 cm | E11: =_xlfn.REGEXREPLACE(A11,"[^0-9.]","")+0 -> 76 | F11: =_xlfn.REGEXREPLACE(B11,"[^0-9.]","")+0 -> 56 | G11: =_xlfn.REGEXREPLACE(C11,"[^0-9.]","")+0 -> 232
A12: 86 l | B12: 58.5 cm | C12: 233 cm | E12: =_xlfn.REGEXREPLACE(A12,"[^0-9.]","")+0 -> 86 | F12: =_xlfn.REGEXREPLACE(B12,"[^0-9.]","")+0 -> 58.5 | G12: =_xlfn.REGEXREPLACE(C12,"[^0-9.]","")+0 -> 233
... A49: 120 l | B49: 69 cm | C49: 245 cm | E49: =_xlfn.REGEXREPLACE(A49,"[^0-9.]","")+0 -> 120 | F49: =_xlfn.REGEXREPLACE(B49,"[^0-9.]","")+0 -> 69 | G49: =_xlfn.REGEXREPLACE(C49,"[^0-9.]","")+0 -> 245
A50: 315 l | B50: 85.1 cm | C50: 300 | E50: =_xlfn.REGEXREPLACE(A50,"[^0-9.]","")+0 -> 315 | F50: =_xlfn.REGEXREPLACE(B50,"[^0-9.]","")+0 -> 85.1 | G50: =_xlfn.REGEXREPLACE(C50,"[^0-9.]","")+0 -> 300
A51: 187 l | B51: 73.7 cm | C51: 274.3 cm | E51: =_xlfn.REGEXREPLACE(A51,"[^0-9.]","")+0 -> 187 | F51: =_xlfn.REGEXREPLACE(B51,"[^0-9.]","")+0 -> 73.7 | G51: =_xlfn.REGEXREPLACE(C51,"[^0-9.]","")+0 -> 274.3
E52: =_xlfn.REGEXREPLACE(A52,"[^0-9.]","")+0 -> #VALUE! | F52: =_xlfn.REGEXREPLACE(B52,"[^0-9.]","")+0 -> #VALUE! | G52: =_xlfn.REGEXREPLACE(C52,"[^0-9.]","")+0 -> #VALUE!
E53: =_xlfn.REGEXREPLACE(A53,"[^0-9.]","")+0 -> #VALUE! | F53: =_xlfn.REGEXREPLACE(B53,"[^0-9.]","")+0 -> #VALUE! | G53: =_xlfn.REGEXREPLACE(C53,"[^0-9.]","")+0 -> #VALUE!
E54: =_xlfn.REGEXREPLACE(A54,"[^0-9.]","")+0 -> #VALUE! | F54: =_xlfn.REGEXREPLACE(B54,"[^0-9.]","")+0 -> #VALUE! | G54: =_xlfn.REGEXREPLACE(C54,"[^0-9.]","")+0 -> #VALUE!
E55: =_xlfn.REGEXREPLACE(A55,"[^0-9.]","")+0 -> #VALUE! | F55: =_xlfn.REGEXREPLACE(B55,"[^0-9.]","")+0 -> #VALUE! | G55: =_xlfn.REGEXREPLACE(C55,"[^0-9.]","")+0 -> #VALUE!
E56: =_xlfn.REGEXREPLACE(A56,"[^0-9.]","")+0 -> #VALUE! | F56: =_xlfn.REGEXREPLACE(B56,"[^0-9.]","")+0 -> #VALUE! | G56: =_xlfn.REGEXREPLACE(C56,"[^0-9.]","")+0 -> #VALUE!
E57: =_xlfn.REGEXREPLACE(A57,"[^0-9.]","")+0 -> #VALUE! | F57: =_xlfn.REGEXREPLACE(B57,"[^0-9.]","")+0 -> #VALUE! | G57: =_xlfn.REGEXREPLACE(C57,"[^0-9.]","")+0 -> #VALUE!
E58: =_xlfn.REGEXREPLACE(A58,"[^0-9.]","")+0 -> #VALUE! | F58: =_xlfn.REGEXREPLACE(B58,"[^0-9.]","")+0 -> #VALUE! | G58: =_xlfn.REGEXREPLACE(C58,"[^0-9.]","")+0 -> #VALUE!
E59: =_xlfn.REGEXREPLACE(A59,"[^0-9.]","")+0 -> #VALUE! | F59: =_xlfn.REGEXREPLACE(B59,"[^0-9.]","")+0 -> #VALUE! | G59: =_xlfn.REGEXREPLACE(C59,"[^0-9.]","")+0 -> #VALUE!
E60: =_xlfn.REGEXREPLACE(A60,"[^0-9.]","")+0 -> #VALUE! | F60: =_xlfn.REGEXREPLACE(B60,"[^0-9.]","")+0 -> #VALUE! | G60: =_xlfn.REGEXREPLACE(C60,"[^0-9.]","")+0 -> #VALUE!
E61: =_xlfn.REGEXREPLACE(A61,"[^0-9.]","")+0 -> #VALUE! | F61: =_xlfn.REGEXREPLACE(B61,"[^0-9.]","")+0 -> #VALUE! | G61: =_xlfn.REGEXREPLACE(C61,"[^0-9.]","")+0 -> #VALUE!
E62: =_xlfn.REGEXREPLACE(A62,"[^0-9.]","")+0 -> #VALUE! | F62: =_xlfn.REGEXREPLACE(B62,"[^0-9.]","")+0 -> #VALUE! | G62: =_xlfn.REGEXREPLACE(C62,"[^0-9.]","")+0 -> #VALUE!
E63: =_xlfn.REGEXREPLACE(A63,"[^0-9.]","")+0 -> #VALUE! | F63: =_xlfn.REGEXREPLACE(B63,"[^0-9.]","")+0 -> #VALUE! | G63: =_xlfn.REGEXREPLACE(C63,"[^0-9.]","")+0 -> #VALUE!
... E69: =_xlfn.REGEXREPLACE(A69,"[^0-9.]","")+0 -> #VALUE! | F69: =_xlfn.REGEXREPLACE(B69,"[^0-9.]","")+0 -> #VALUE! | G69: =_xlfn.REGEXREPLACE(C69,"[^0-9.]","")+0 -> #VALUE!

Sheet tabula-2016_Fanatic
A1: MODEL | B1: VOLUME | C1: WIDTH | D1: LENGTH | E1: THICKNESS | F1: BOARD TECHNOLOGIES | G1: REC. SAIL SIZES
A2: Quad TE 69 NEW SHAPE | B2: 69 l | C2: 53.5 cm | D2: 224 cm | E2: — | F2: IC / LF | G2: 3.3 – 5.0 m2
A3: Quad TE 75 NEW SHAPE | B3: 75 l | C3: 55.5 cm | D3: 225 cm | E3: — | F3: IC / LF | G3: 3.7 – 5.3 m2
A4: Quad TE 81 NEW SHAPE | B4: 81 l | C4: 57.5 cm | D4: 226 cm | E4: — | F4: IC / LF | G4: 4.0 – 5.8 m2
A5: Quad TE 90 NEW SHAPE | B5: 90 l | C5: 59.5 cm | D5: 227 cm | E5: — | F5: IC / LF | G5: 4.2 – 6.5 m2
A6: Stubby TE 77 NEW SHAPE | B6: 77 l | C6: 55 cm | D6: 212 cm | E6: — | F6: IC / LF | G6: 3.3 – 5.3 m2
A7: Stubby TE 88 NEW SHAPE | B7: 88 l | C7: 57.5 cm | D7: 215 cm | E7: — | F7: IC / LF | G7: 4.0 – 5.8 m2
A8: TriWave TE 74 NEW SHAPE | B8: 74 l | C8: 56 cm | D8: 222 cm | E8: — | F8: IC / LF | G8: 3.5 – 5.3 m2
A9: TriWave TE 82 NEW SHAPE | B9: 82 l | C9: 58 cm | D9: 224 cm | E9: — | F9: IC / LF | G9: 4.0 – 5.8 m2
A10: TriWave TE 89 NEW SHAPE | B10: 89 l | C10: 59.5 cm | D10: 227 cm | E10: — | F10: IC / LF | G10: 4.2 – 6.2 m2
A11: TriWave TE 99 NEW SHAPE | B11: 99 l | C11: 62 cm | D11: 229 cm | E11: — | F11: IC / LF | G11: 4.5 – 6.7 m2
A12: FreeWave TE 76; FreeWave CWS 76 | B12: 76 l | C12: 56 cm | D12: 232 cm | E12: — | F12: IC / LF; CWS | G12: 3.7 – 6.0 m2
... A52: Ripper Air WS 187 NEW SHAPE | B52: 187 l | C52: 29” / 73.7 cm | D52: 9’0” / 274.3 cm | E52: 4.5” / 11.5 cm | F52: Double Layer Heavy Duty | G52: 1.0 – 6.5 m2

Sheet Sheet1

Sheet Category
A1: Category
A2: Wave
A3: Freestyle
A4: Freewave
A5: Freeride
A6: Performance
A7: Slalom
A8: Foil

Sheet Brands
A1: Brands
A2: Fanatic
A3: Mistral
A4: F2

Sheet Year
A1: Year
A2: 2007
A3: 2008
A4: 2009
A5: 2010
A6: 2011
A7: 2012
A8: 2013
A9: 2014
A10: 2015
A11: 2016
A12: 2017
A13: 2018
... A18: 2023
