Workbook

Sheet Boards Catalogue
A1: ID | B1: YEAR | C1: Model Year | D1: Brand | E1: Model | F1: Vol. | G1: WIDTH | H1: LENGTH | I1: TECHNOLOGY | J1: FIN BOXES | K1: FINS | L1: REC. SAIL SIZES | M1: Weight | N1: Misc
A2: =_xlfn.CONCAT(B2,"-",LEFT(D2,2),"-",LEFT(E2,3),"-",F2,"-",TRUNC(G2),"-",TRUNC(H2)) -> 1992-Ti-260-88-55-260 | B2: =LEFT(C2,4) -> 1992 | C2: 1992 | D2: Tiga | E2: 260 ACR | F2: 88 | G2: 55 | H2: 260 | J2: Tiga Box
A3: =_xlfn.CONCAT(B3,"-",LEFT(D3,2),"-",LEFT(E3,3),"-",F3,"-",TRUNC(G3),"-",TRUNC(H3)) -> 2007-Fa-All-72-54-232 | B3: =LEFT(C3,4) -> 2007 | C3: 2007/2008 | D3: Fanatic | E3: AllWave 72 | F3: 72 | G3: 54 | H3: 232 | I3: GLASS DOUBLE SANDWICH | K3: FANATIC ALLWAVE 22 G10
A4: =_xlfn.CONCAT(B4,"-",LEFT(D4,2),"-",LEFT(E4,3),"-",F4,"-",TRUNC(G4),"-",TRUNC(H4)) -> 2007-Fa-All-82-57-233 | B4: =LEFT(C4,4) -> 2007 | C4: 2007/2008 | D4: Fanatic | E4: AllWave 82 | F4: 82 | G4: 57 | H4: 233 | I4: GLASS DOUBLE SANDWICH | K4: FANATIC ALLWAVE 23,5 G10
A5: =_xlfn.CONCAT(B5,"-",LEFT(D5,2),"-",LEFT(E5,3),"-",F5,"-",TRUNC(G5),"-",TRUNC(H5)) -> 2007-Fa-AW -92-60-235 | B5: =LEFT(C5,4) -> 2007 | C5: 2007/2008 | D5: Fanatic | E5: AW 92 | F5: 92 | G5: 60 | H5: 235 | I5: GLASS DOUBLE SANDWICH | K5: FANATIC ALLWAVE 25 G10
A6: =_xlfn.CONCAT(B6,"-",LEFT(D6,2),"-",LEFT(E6,3),"-",F6,"-",TRUNC(G6),"-",TRUNC(H6)) -> 2007-Fa-EAG-100-63-245 | B6: =LEFT(C6,4) -> 2007 | C6: 2007/2008 | D6: Fanatic | E6: EAGLE 100 | F6: 100 | G6: 63 | H6: 245 | I6: HYBRID SANDWICH | K6: FANATIC EAGLE 36 G10
A7: =_xlfn.CONCAT(B7,"-",LEFT(D7,2),"-",LEFT(E7,3),"-",F7,"-",TRUNC(G7),"-",TRUNC(H7)) -> 2007-Fa-EAG-113-66-246 | B7: =LEFT(C7,4) -> 2007 | C7: 2007/2008 | D7: Fanatic | E7: EAGLE 113 | F7: 113 | G7: 66 | H7: 246 | I7: HYBRID SANDWICH | K7: FANATIC EAGLE 39 G10
A8: =_xlfn.CONCAT(B8,"-",LEFT(D8,2),"-",LEFT(E8,3),"-",F8,"-",TRUNC(G8),"-",TRUNC(H8)) -> 2007-Fa-EAG-126-69-249 | B8: =LEFT(C8,4) -> 2007 | C8: 2007/2008 | D8: Fanatic | E8: EAGLE 126 | F8: 126 | G8: 69 | H8: 249 | I8: HYBRID SANDWICH | K8: FANATIC EAGLE 42 G10
A9: =_xlfn.CONCAT(B9,"-",LEFT(D9,2),"-",LEFT(E9,3),"-",F9,"-",TRUNC(G9),"-",TRUNC(H9)) -> 2007-Fa-FAL-145-85-245 | B9: =LEFT(C9,4) -> 2007 | C9: 2007/2008 | D9: Fanatic | E9: FALCON SL 145 | F9: 145 | G9: 85 | H9: 245 | I9: CARBON SANDWICH | K9: Fanatic Slalom 54 G10
A10: =_xlfn.CONCAT(B10,"-",LEFT(D10,2),"-",LEFT(E10,3),"-",F10,"-",TRUNC(G10),"-",TRUNC(H10)) -> 2007-Fa-FAL-68-48-242 | B10: =LEFT(C10,4) -> 2007 | C10: 2007/2008 | D10: Fanatic | E10: FALCON SPEED | F10: 68 | G10: 48 | H10: 242 | I10: CARBON SANDWICH | K10: FANATIC SPEED 28 G10
A11: =_xlfn.CONCAT(B11,"-",LEFT(D11,2),"-",LEFT(E11,3),"-",F11,"-",TRUNC(G11),"-",TRUNC(H11)) -> 2007-Fa-FW -104-63-241 | B11: =LEFT(C11,4) -> 2007 | C11: 2007/2008 | D11: Fanatic | E11: FW 104 | F11: 104 | G11: 63.5 | H11: 241 | I11: TECHNORA KEVLAR DOUBLE SANDWICH / LF | K11: FANATIC FREEWAVE 29 G10
A12: =_xlfn.CONCAT(B12,"-",LEFT(D12,2),"-",LEFT(E12,3),"-",F12,"-",TRUNC(G12),"-",TRUNC(H12)) -> 2007-Fa-Fee-77-56-237 | B12: =LEFT(C12,4) -> 2007 | C12: 2007/2008 | D12: Fanatic | E12: FeeWave 77 | F12: 77 | G12: 56 | H12: 237 | I12: TECHNORA KEVLAR DOUBLE SANDWICH / LF | K12: FANATIC FREEWAVE 23 G10
A13: =_xlfn.CONCAT(B13,"-",LEFT(D13,2),"-",LEFT(E13,3),"-",F13,"-",TRUNC(G13),"-",TRUNC(H13)) -> 2007-Fa-Fre-86-58-239 | B13: =LEFT(C13,4) -> 2007 | C13: 2007/2008 | D13: Fanatic | E13: FreeWave 86 | F13: 86 | G13: 58.5 | H13: 239 | I13: TECHNORA KEVLAR DOUBLE SANDWICH / LF | K13: FANATIC FREEWAVE 25 G10
A14: =_xlfn.CONCAT(B14,"-",LEFT(D14,2),"-",LEFT(E14,3),"-",F14,"-",TRUNC(G14),"-",TRUNC(H14)) -> 2007-Fa-Fre-95-61-241 | B14: =LEFT(C14,4) -> 2007 | C14: 2007/2008 | D14: Fanatic | E14: FreeWave 95 | F14: 95 | G14: 61 | H14: 241 | I14: TECHNORA KEVLAR DOUBLE SANDWICH / LF | K14: FANATIC FREEWAVE 27 G10
... A36: =_xlfn.CONCAT(B36,"-",LEFT(D36,2),"-",LEFT(E36,3),"-",F36,"-",TRUNC(G36),"-",TRUNC(H36)) -> 2007-Fa-VIP-220-85-285 | B36: =LEFT(C36,4) -> 2007 | C36: 2007/2008 | D36: Fanatic | E36: VIPER 85 | F36: 220 | G36: 85 | H36: 285 | I36: HIGH RESISTANCE SKIN – SOFTDECK | K36: FANATIC VIPER 34, DAGGERBOARD
A37: =_xlfn.CONCAT(B37,"-",LEFT(D37,2),"-",LEFT(E37,3),"-",F37,"-",TRUNC(G37),"-",TRUNC(H37)) -> 2007-Fa-FAL-79-55-245 | B37: =LEFT(C37,4) -> 2007 | C37: 2007/2008 | D37: Fanatic | E37: FALCON SL 79 | F37: 79 | G37: 55 | H37: 245 | I37: CARBON SANDWICH
A38: =_xlfn.CONCAT(B38,"-",LEFT(D38,2),"-",LEFT(E38,3),"-",F38,"-",TRUNC(G38),"-",TRUNC(H38)) -> 2007-Fa-FAL-89-61-244 | B38: =LEFT(C38,4) -> 2007 | C38: 2007/2008 | D38: Fanatic | E38: FALCON SL 89 | F38: 89 | G38: 61 | H38: 244 | I38: CARBON SANDWICH
A39: =_xlfn.CONCAT(B39,"-",LEFT(D39,2),"-",LEFT(E39,3),"-",F39,"-",TRUNC(G39),"-",TRUNC(H39)) -> 2007-Fa-FAL-104-67-245 | B39: =LEFT(C39,4) -> 2007 | C39: 2007/2008 | D39: Fanatic | E39: FALCON SL 104 | F39: 104 | G39: 67 | H39: 245 | I39: CARBON SANDWICH
A40: =_xlfn.CONCAT(B40,"-",LEFT(D40,2),"-",LEFT(E40,3),"-",F40,"-",TRUNC(G40),"-",TRUNC(H40)) -> 2007-Fa-FAL-124-76-245 | B40: =LEFT(C40,4) -> 2007 | C40: 2007/2008 | D40: Fanatic | E40: FALCON SL 124 | F40: 124 | G40: 76 | H40: 245 | I40: CARBON SANDWICH
A41: =_xlfn.CONCAT(B41,"-",LEFT(D41,2),"-",LEFT(E41,3),"-",F41,"-",TRUNC(G41),"-",TRUNC(H41)) -> 2007-Fa-Fal-89-61-244 | B41: =LEFT(C41,4) -> 2007 | C41: 2007 | D41: Fanatic | E41: Falcon 90 | F41: 89 | G41: 61 | H41: 244 | I41: CARBON SANDWICH
A42: =_xlfn.CONCAT(B42,"-",LEFT(D42,2),"-",LEFT(E42,3),"-",F42,"-",TRUNC(G42),"-",TRUNC(H42)) -> 2010-Fa-Fal-102-63-235 | B42: =LEFT(C42,4) -> 2010 | C42: 2010 | D42: Fanatic | E42: Falcon Slalom 102 | F42: 102 | G42: 63 | H42: 235 | I42: Biax Carbon Sandwich Light | J42: Tuttle Box | K42: None | L42: 5.5 – 8.5 M2
A43: =_xlfn.CONCAT(B43,"-",LEFT(D43,2),"-",LEFT(E43,3),"-",F43,"-",TRUNC(G43),"-",TRUNC(H43)) -> 2010-Fa-Fal-112-69-235 | B43: =LEFT(C43,4) -> 2010 | C43: 2010 | D43: Fanatic | E43: Falcon Slalom 112 | F43: 112 | G43: 69 | H43: 235 | I43: Biax Carbon Sandwich Light | J43: Tuttle Box | K43: None | L43: 6.0 – 9.0 M2
A44: =_xlfn.CONCAT(B44,"-",LEFT(D44,2),"-",LEFT(E44,3),"-",F44,"-",TRUNC(G44),"-",TRUNC(H44)) -> 2010-Fa-Fal-122-75-230 | B44: =LEFT(C44,4) -> 2010 | C44: 2010 | D44: Fanatic | E44: Falcon Slalom 122 | F44: 122 | G44: 75 | H44: 230 | I44: Biax Carbon Sandwich Light | J44: Tuttle Box | K44: None | L44: 6.5 – 9.5 M2
A45: =_xlfn.CONCAT(B45,"-",LEFT(D45,2),"-",LEFT(E45,3),"-",F45,"-",TRUNC(G45),"-",TRUNC(H45)) -> 2010-Fa-Fal-133-79-230 | B45: =LEFT(C45,4) -> 2010 | C45: 2010 | D45: Fanatic | E45: Falcon Slalom 133 | F45: 133 | G45: 79 | H45: 230 | I45: Biax Carbon Sandwich Light | J45: Deep Tuttle Box | K45: None | L45: 6.5 – 10 M2
A46: =_xlfn.CONCAT(B46,"-",LEFT(D46,2),"-",LEFT(E46,3),"-",F46,"-",TRUNC(G46),"-",TRUNC(H46)) -> 2010-Fa-Fal-145-85-230 | B46: =LEFT(C46,4) -> 2010 | C46: 2010 | D46: Fanatic | E46: Falcon Slalom 145 | F46: 145 | G46: 85 | H46: 230 | I46: Biax Carbon Sandwich Light | J46: Deep Tuttle Box | K46: None | L46: 7.0 – 10 M2 +
A47: =_xlfn.CONCAT(B47,"-",LEFT(D47,2),"-",LEFT(E47,3),"-",F47,"-",TRUNC(G47),"-",TRUNC(H47)) -> 2010-Fa-Fal-68-48-242 | B47: =LEFT(C47,4) -> 2010 | C47: 2010 | D47: Fanatic | E47: Falcon Speed | F47: 68 | G47: 48 | H47: 242 | I47: Carbon Sandwich Light | J47: Tuttle Box | K47: None | L47: 4.0 – 7.0 M2
A48: =_xlfn.CONCAT(B48,"-",LEFT(D48,2),"-",LEFT(E48,3),"-",F48,"-",TRUNC(G48),"-",TRUNC(H48)) -> 2010-Fa-Fal-86-58-240 | B48: =LEFT(C48,4) -> 2010 | C48: 2010 | D48: Fanatic | E48: Falcon Slalom 86 | F48: 86 | G48: 58 | H48: 240 | I48: Biax Carbon Sandwich Light | J48: Tuttle Box | K48: None | L48: 4.5 – 7.0 M2
A49: =_xlfn.CONCAT(B49,"-",LEFT(D49,2),"-",LEFT(E49,3),"-",F49,"-",TRUNC(G49),"-",TRUNC(H49)) -> 2010-Fa-Fre-105-63-242 | B49: =LEFT(C49,4) -> 2010 | C49: 2010 | D49: Fanatic | E49: Freewave 105 | F49: 105 | G49: 63.5 | H49: 242 | I49: Custom Wood Sandwich Light | J49: Power Box | K49: Fanatic Freewave 29 G10 | L49: 4.7 –7.0 M2
A50: =_xlfn.CONCAT(B50,"-",LEFT(D50,2),"-",LEFT(E50,3),"-",F50,"-",TRUNC(G50),"-",TRUNC(H50)) -> 2010-Fa-Fre-105-63-242 | B50: =LEFT(C50,4) -> 2010 | C50: 2010 | D50: Fanatic | E50: Freewave TE 105 | F50: 105 | G50: 63.5 | H50: 242 | I50: Carbon Kevlar Light TE | J50: Power Box | K50: Fanatic Freewave 29 G10 | L50: 4.7 – 7.0 M2
A51: =_xlfn.CONCAT(B51,"-",LEFT(D51,2),"-",LEFT(E51,3),"-",F51,"-",TRUNC(G51),"-",TRUNC(H51)) -> 2010-Fa-Fre-115-66-244 | B51: =LEFT(C51,4) -> 2010 | C51: 2010 | D51: Fanatic | E51: Freewave 115 | F51: 115 | G51: 66 | H51: 244 | I51: Custom Wood Sandwich Light | J51: Power Box | K51: Fanatic Freewave 29 G10 | L51: 5.0 – 7.3 M2
A52: =_xlfn.CONCAT(B52,"-",LEFT(D52,2),"-",LEFT(E52,3),"-",F52,"-",TRUNC(G52),"-",TRUNC(H52)) -> 2010-Fa-Fre-115-66-244 | B52: =LEFT(C52,4) -> 2010 | C52: 2010 | D52: Fanatic | E52: Freewave TE 115 | F52: 115 | G52: 66 | H52: 244 | I52: Carbon Kevlar Light TE | J52: Power Box | K52: Fanatic Freewave 29 G10 | L52: 5.0 – 7.3 M2
A53: =_xlfn.CONCAT(B53,"-",LEFT(D53,2),"-",LEFT(E53,3),"-",F53,"-",TRUNC(G53),"-",TRUNC(H53)) -> 2010-Fa-Fre-75-56-235 | B53: =LEFT(C53,4) -> 2010 | C53: 2010 | D53: Fanatic | E53: Freewave 75 | F53: 75 | G53: 56 | H53: 235 | I53: Custom Wood Sandwich Light | J53: Us Box | K53: Fanatic Freewave 23 G10 | L53: 3.7 – 6.0 M2
... A94: =_xlfn.CONCAT(B94,"-",LEFT(D94,2),"-",LEFT(E94,3),"-",F94,"-",TRUNC(G94),"-",TRUNC(H94)) -> 2010-Fa-Vip-220-85-285 | B94: =LEFT(C94,4) -> 2010 | C94: 2010 | D94: Fanatic | E94: Viper 85 | F94: 220 | G94: 85 | H94: 285 | I94: High Resistance Skin – Softdeck** | J94: Power Box | K94: Fanatic Viper 34 | L94: 2.0 – 10.0 M2
A95: =_xlfn.CONCAT(B95,"-",LEFT(D95,2),"-",LEFT(E95,3),"-",F95,"-",TRUNC(G95),"-",TRUNC(H95)) -> 2016-Fa-Fal-112-70-230 | B95: =LEFT(C95,4) -> 2016 | C95: 2016 | D95: Fanatic | E95: Falcon Slalom TE 112 | F95: 112 | G95: 70 | H95: 230 | I95: Full BCS / LF (Deck & Bottom); BGS / LF | L95: 6.0 – 8.6 m2
A96: =_xlfn.CONCAT(B96,"-",LEFT(D96,2),"-",LEFT(E96,3),"-",F96,"-",TRUNC(G96),"-",TRUNC(H96)) -> 2016-Fa-Fal-121-75-230 | B96: =LEFT(C96,4) -> 2016 | C96: 2016 | D96: Fanatic | E96: Falcon Slalom TE 121 | F96: 121 | G96: 75 | H96: 230 | I96: Full BCS / LF (Deck & Bottom); BGS / LF | L96: 6.5 – 9.2 m2
A97: =_xlfn.CONCAT(B97,"-",LEFT(D97,2),"-",LEFT(E97,3),"-",F97,"-",TRUNC(G97),"-",TRUNC(H97)) -> 2016-Fa-Fal-129-80-230 | B97: =LEFT(C97,4) -> 2016 | C97: 2016 | D97: Fanatic | E97: Falcon Slalom TE 129 | F97: 129 | G97: 80 | H97: 230 | I97: Full BCS / LF (Deck & Bottom) | L97: 6.8 – 9.5 m2
A98: =_xlfn.CONCAT(B98,"-",LEFT(D98,2),"-",LEFT(E98,3),"-",F98,"-",TRUNC(G98),"-",TRUNC(H98)) -> 2016-Fa-Fal-138-85-230 | B98: =LEFT(C98,4) -> 2016 | C98: 2016 | D98: Fanatic | E98: Falcon Slalom TE 138 | F98: 138 | G98: 85 | H98: 230 | I98: Full BCS / LF (Deck & Bottom) | L98: 7.0 – 10.0 m2
A99: =_xlfn.CONCAT(B99,"-",LEFT(D99,2),"-",LEFT(E99,3),"-",F99,"-",TRUNC(G99),"-",TRUNC(H99)) -> 2016-Fa-Fal-152-90-230 | B99: =LEFT(C99,4) -> 2016 | C99: 2016 | D99: Fanatic | E99: Falcon Slalom TE 152 | F99: 152 | G99: 90 | H99: 230 | I99: Full BCS / LF (Deck & Bottom) | L99: 7.5 – 11.0+ m2
A100: =_xlfn.CONCAT(B100,"-",LEFT(D100,2),"-",LEFT(E100,3),"-",F100,"-",TRUNC(G100),"-",TRUNC(H100)) -> 2016-Fa-Fal-172-100-230 | B100: =LEFT(C100,4) -> 2016 | C100: 2016 | D100: Fanatic | E100: Falcon Formula 172 | F100: 172 | G100: 100 | H100: 230 | I100: Full BCS / LF (Deck & Bottom) | L100: 8.0 – 12.5+ m2
A101: =_xlfn.CONCAT(B101,"-",LEFT(D101,2),"-",LEFT(E101,3),"-",F101,"-",TRUNC(G101),"-",TRUNC(H101)) -> 2016-Fa-Fal-54-44-230 | B101: =LEFT(C101,4) -> 2016 | C101: 2016 | D101: Fanatic | E101: Falcon Speed 44 Lüderitz | F101: 54 | G101: 44 | H101: 230 | I101: BCS / LF | L101: 4.0 – 6.5 m2
...

Sheet APPROVED SERIES PRODUCTION 
A1: ID | B1: Year | C1: MODEL YEAR | D1: BRAND | E1: MODEL | F1: Vol. | G1: Width | H1: Length | I1: Width_x000D_(mm) | J1: Length Straight_x000D_(mm) | K1: REGISTRATION DATE | L1: Weight_x000D_(Kg)
A2: =_xlfn.CONCAT(B2,"-",LEFT(D2,2),"-",LEFT(E2,3),"-",F2,"-",TRUNC(I2),"-",TRUNC(J2)) -> 2014-99-SL -89-578-2434 | B2: =LEFT(C2,4) -> 2014 | C2: 2014 | D2: 99 International | E2: SL 89 | F2: 89 | G2: =TRUNC(I2/10) -> 57 | H2: =TRUNC(J2/10) -> 243 | I2: 578 | J2: 2434 | K2: 2014 | L2: 6.5
A3: =_xlfn.CONCAT(B3,"-",LEFT(D3,2),"-",LEFT(E3,3),"-",F3,"-",TRUNC(I3),"-",TRUNC(J3)) -> 2014-99-SL -89-578-2434 | B3: =LEFT(C3,4) -> 2014 | C3: 2014 | D3: 99 International | E3: SL 89 NANO | F3: 89 | G3: =TRUNC(I3/10) -> 57 | H3: =TRUNC(J3/10) -> 243 | I3: 578 | J3: 2434 | K3: 2014 | L3: 5.9
A4: =_xlfn.CONCAT(B4,"-",LEFT(D4,2),"-",LEFT(E4,3),"-",F4,"-",TRUNC(I4),"-",TRUNC(J4)) -> 2014-99-SL -109-689-2352 | B4: =LEFT(C4,4) -> 2014 | C4: 2014 | D4: 99 International | E4: SL 109 | F4: 109 | G4: =TRUNC(I4/10) -> 68 | H4: =TRUNC(J4/10) -> 235 | I4: 689 | J4: 2352 | K4: 2014 | L4: 6.9
A5: =_xlfn.CONCAT(B5,"-",LEFT(D5,2),"-",LEFT(E5,3),"-",F5,"-",TRUNC(I5),"-",TRUNC(J5)) -> 2014-99-SL -109-689-2352 | B5: =LEFT(C5,4) -> 2014 | C5: 2014 | D5: 99 International | E5: SL 109 NANO | F5: 109 | G5: =TRUNC(I5/10) -> 68 | H5: =TRUNC(J5/10) -> 235 | I5: 689 | J5: 2352 | K5: 2014 | L5: 6.4
A6: =_xlfn.CONCAT(B6,"-",LEFT(D6,2),"-",LEFT(E6,3),"-",F6,"-",TRUNC(I6),"-",TRUNC(J6)) -> 2014-99-SL -119-765-2320 | B6: =LEFT(C6,4) -> 2014 | C6: 2014 | D6: 99 International | E6: SL 119 NANO | F6: 119 | G6: =TRUNC(I6/10) -> 76 | H6: =TRUNC(J6/10) -> 232 | I6: 765 | J6: 2320 | K6: 2014 | L6: 6.8
A7: =_xlfn.CONCAT(B7,"-",LEFT(D7,2),"-",LEFT(E7,3),"-",F7,"-",TRUNC(I7),"-",TRUNC(J7)) -> 2014-99-SL -129-850-2283 | B7: =LEFT(C7,4) -> 2014 | C7: 2014 | D7: 99 International | E7: SL 129 | F7: 129 | G7: =TRUNC(I7/10) -> 85 | H7: =TRUNC(J7/10) -> 228 | I7: 850 | J7: 2283 | K7: 2014 | L7: 7.5
A8: =_xlfn.CONCAT(B8,"-",LEFT(D8,2),"-",LEFT(E8,3),"-",F8,"-",TRUNC(I8),"-",TRUNC(J8)) -> 2014-99-SL -129-850-2283 | B8: =LEFT(C8,4) -> 2014 | C8: 2014 | D8: 99 International | E8: SL 129 NANO | F8: 129 | G8: =TRUNC(I8/10) -> 85 | H8: =TRUNC(J8/10) -> 228 | I8: 850 | J8: 2283 | K8: 2014 | L8: 7.3
A9: =_xlfn.CONCAT(B9,"-",LEFT(D9,2),"-",LEFT(E9,3),"-",F9,"-",TRUNC(I9),"-",TRUNC(J9)) -> 2015-99-WC -100-619-2332 | B9: =LEFT(C9,4) -> 2015 | C9: 2015 | D9: 99 International | E9: WC SL 95 | F9: 100 | G9: =TRUNC(I9/10) -> 61 | H9: =TRUNC(J9/10) -> 233 | I9: 619 | J9: 2332 | K9: 3/6/15 | L9: 5.9
A10: =_xlfn.CONCAT(B10,"-",LEFT(D10,2),"-",LEFT(E10,3),"-",F10,"-",TRUNC(I10),"-",TRUNC(J10)) -> 2015-99-WC -123.5-714-2330 | B10: =LEFT(C10,4) -> 2015 | C10: 2015 | D10: 99 International | E10: WC SL 115 | F10: 123.5 | G10: =TRUNC(I10/10) -> 71 | H10: =TRUNC(J10/10) -> 233 | I10: 714 | J10: 2330 | K10: 3/6/15 | L10: 6.3
A11: =_xlfn.CONCAT(B11,"-",LEFT(D11,2),"-",LEFT(E11,3),"-",F11,"-",TRUNC(I11),"-",TRUNC(J11)) -> 2015-99-WC -134.7-794-2265 | B11: =LEFT(C11,4) -> 2015 | C11: 2015 | D11: 99 International | E11: WC SL 125 | F11: 134.7 | G11: =TRUNC(I11/10) -> 79 | H11: =TRUNC(J11/10) -> 226 | I11: 794 | J11: 2265 | K11: 3/6/15 | L11: 6.3
A12: =_xlfn.CONCAT(B12,"-",LEFT(D12,2),"-",LEFT(E12,3),"-",F12,"-",TRUNC(I12),"-",TRUNC(J12)) -> 2015-99-WC -146.8-847-2265 | B12: =LEFT(C12,4) -> 2015 | C12: 2015 | D12: 99 International | E12: WC SL 135 | F12: 146.8 | G12: =TRUNC(I12/10) -> 84 | H12: =TRUNC(J12/10) -> 226 | I12: 847 | J12: 2265 | K12: 3/6/15 | L12: 7.3
A13: =_xlfn.CONCAT(B13,"-",LEFT(D13,2),"-",LEFT(E13,3),"-",F13,"-",TRUNC(I13),"-",TRUNC(J13)) -> 2016-99-WCS-90.7-579-2348 | B13: =LEFT(C13,4) -> 2016 | C13: 2016 | D13: 99 International | E13: WCSL 89 | F13: 90.7 | G13: =TRUNC(I13/10) -> 57 | H13: =TRUNC(J13/10) -> 234 | I13: 579 | J13: 2348 | K13: 12/04/2016 | L13: 5.8
... A29: =_xlfn.CONCAT(B29,"-",LEFT(D29,2),"-",LEFT(E29,3),"-",F29,"-",TRUNC(I29),"-",TRUNC(J29)) -> 2018-99-WCS-148.9-847-2285 | B29: =LEFT(C29,4) -> 2018 | C29: 2018 | D29: 99 International | E29: WCSL 139 | F29: 148.9 | G29: =TRUNC(I29/10) -> 84 | H29: =TRUNC(J29/10) -> 228 | I29: 847 | J29: 2285 | K29: 13/04/2018 | L29: 7.5
A30: =_xlfn.CONCAT(B30,"-",LEFT(D30,2),"-",LEFT(E30,3),"-",F30,"-",TRUNC(I30),"-",TRUNC(J30)) -> 2009-AB-Spe-63-470-2240 | B30: =LEFT(C30,4) -> 2009 | C30: 2009 | D30: AB+ | E30: Speed 46 | F30: 63 | G30: =TRUNC(I30/10) -> 47 | H30: =TRUNC(J30/10) -> 224 | I30: 470 | J30: 2240 | K30: 2008 | L30: 4.6
A31: =_xlfn.CONCAT(B31,"-",LEFT(D31,2),"-",LEFT(E31,3),"-",F31,"-",TRUNC(I31),"-",TRUNC(J31)) -> 2009-AB-Sla-78-540-2360 | B31: =LEFT(C31,4) -> 2009 | C31: 2009 | D31: AB+ | E31: Slalom 54 | F31: 78 | G31: =TRUNC(I31/10) -> 54 | H31: =TRUNC(J31/10) -> 236 | I31: 540 | J31: 2360 | K31: 2008 | L31: 5.4
A32: =_xlfn.CONCAT(B32,"-",LEFT(D32,2),"-",LEFT(E32,3),"-",F32,"-",TRUNC(I32),"-",TRUNC(J32)) -> 2009-AB-Sla-95-592-2370 | B32: =LEFT(C32,4) -> 2009 | C32: 2009 | D32: AB+ | E32: Slalom 59 | F32: 95 | G32: =TRUNC(I32/10) -> 59 | H32: =TRUNC(J32/10) -> 237 | I32: 592 | J32: 2370 | K32: 2008 | L32: 5.8
A33: =_xlfn.CONCAT(B33,"-",LEFT(D33,2),"-",LEFT(E33,3),"-",F33,"-",TRUNC(I33),"-",TRUNC(J33)) -> 2009-AB-Sla-110-666-2350 | B33: =LEFT(C33,4) -> 2009 | C33: 2009 | D33: AB+ | E33: Slalom 67 | F33: 110 | G33: =TRUNC(I33/10) -> 66 | H33: =TRUNC(J33/10) -> 235 | I33: 666 | J33: 2350 | K33: 2008 | L33: 6.4
A34: =_xlfn.CONCAT(B34,"-",LEFT(D34,2),"-",LEFT(E34,3),"-",F34,"-",TRUNC(I34),"-",TRUNC(J34)) -> 2009-AB-Sla-123-746-2350 | B34: =LEFT(C34,4) -> 2009 | C34: 2009 | D34: AB+ | E34: Slalom 76 | F34: 123 | G34: =TRUNC(I34/10) -> 74 | H34: =TRUNC(J34/10) -> 235 | I34: 746 | J34: 2350 | K34: 2008 | L34: 6.8
A35: =_xlfn.CONCAT(B35,"-",LEFT(D35,2),"-",LEFT(E35,3),"-",F35,"-",TRUNC(I35),"-",TRUNC(J35)) -> 1999-AH-DIA-168-720-2730 | B35: =LEFT(C35,4) -> 1999 | C35: 1999 | D35: AHD | E35: DIAMOND RACE 72 | F35: 168 | G35: =TRUNC(I35/10) -> 72 | H35: =TRUNC(J35/10) -> 273 | I35: 720 | J35: 2730 | K35: 99 | L35: 7.6
A36: =_xlfn.CONCAT(B36,"-",LEFT(D36,2),"-",LEFT(E36,3),"-",F36,"-",TRUNC(I36),"-",TRUNC(J36)) -> 2000-AH-DIA-169-790-2660 | B36: =LEFT(C36,4) -> 2000 | C36: 2000 | D36: AHD | E36: DIAMOND RACE 78 | F36: 169 | G36: =TRUNC(I36/10) -> 79 | H36: =TRUNC(J36/10) -> 266 | I36: 790 | J36: 2660 | K36: 00 | L36: 8.1
A37: =_xlfn.CONCAT(B37,"-",LEFT(D37,2),"-",LEFT(E37,3),"-",F37,"-",TRUNC(I37),"-",TRUNC(J37)) -> 2003-AH-GT -88-590-2470 | B37: =LEFT(C37,4) -> 2003 | C37: 2003 | D37: AHD | E37: GT SPECIAL 59 | F37: 88 | G37: =TRUNC(I37/10) -> 59 | H37: =TRUNC(J37/10) -> 247 | I37: 590 | J37: 2470 | K37: 03 | L37: 6.1
A38: =_xlfn.CONCAT(B38,"-",LEFT(D38,2),"-",LEFT(E38,3),"-",F38,"-",TRUNC(I38),"-",TRUNC(J38)) -> 2004-AH-GT -78-538-2423 | B38: =LEFT(C38,4) -> 2004 | C38: 2004 | D38: AHD | E38: GT SPECIAL 54 | F38: 78 | G38: =TRUNC(I38/10) -> 53 | H38: =TRUNC(J38/10) -> 242 | I38: 538 | J38: 2423 | K38: 04 | L38: 5.6
A39: =_xlfn.CONCAT(B39,"-",LEFT(D39,2),"-",LEFT(E39,3),"-",F39,"-",TRUNC(I39),"-",TRUNC(J39)) -> 2004-AH-GT -120-735-2578 | B39: =LEFT(C39,4) -> 2004 | C39: 2004 | D39: AHD | E39: GT SPECIAL 73 | F39: 120 | G39: =TRUNC(I39/10) -> 73 | H39: =TRUNC(J39/10) -> 257 | I39: 735 | J39: 2578 | K39: 04 | L39: 7.3
A40: =_xlfn.CONCAT(B40,"-",LEFT(D40,2),"-",LEFT(E40,3),"-",F40,"-",TRUNC(I40),"-",TRUNC(J40)) -> 2002-AH-DIA-124-744-2598 | B40: =LEFT(C40,4) -> 2002 | C40: 2002 | D40: AHD | E40: DIAMOND GT 75 | F40: 124 | G40: =TRUNC(I40/10) -> 74 | H40: =TRUNC(J40/10) -> 259 | I40: 744 | J40: 2598 | K40: 02 | L40: 7.3
A41: =_xlfn.CONCAT(B41,"-",LEFT(D41,2),"-",LEFT(E41,3),"-",F41,"-",TRUNC(I41),"-",TRUNC(J41)) -> 2002-AH-DIA-144-841-2600 | B41: =LEFT(C41,4) -> 2002 | C41: 2002 | D41: AHD | E41: DIAMOND GT 85 | F41: 144 | G41: =TRUNC(I41/10) -> 84 | H41: =TRUNC(J41/10) -> 260 | I41: 841 | J41: 2600 | K41: 02 | L41: 8.1
A42: =_xlfn.CONCAT(B42,"-",LEFT(D42,2),"-",LEFT(E42,3),"-",F42,"-",TRUNC(I42),"-",TRUNC(J42)) -> 2005-AH-GT -110-655-2480 | B42: =LEFT(C42,4) -> 2005 | C42: 2005 | D42: AHD | E42: GT SPECIAL 110 | F42: 110 | G42: =TRUNC(I42/10) -> 65 | H42: =TRUNC(J42/10) -> 248 | I42: 655 | J42: 2480 | K42: 04 | L42: 6.3
A43: =_xlfn.CONCAT(B43,"-",LEFT(D43,2),"-",LEFT(E43,3),"-",F43,"-",TRUNC(I43),"-",TRUNC(J43)) -> 2006-AH-TRA-67-500-2339 | B43: =LEFT(C43,4) -> 2006 | C43: 2006 | D43: AHD | E43: TRACER 68 | F43: 67 | G43: =TRUNC(I43/10) -> 50 | H43: =TRUNC(J43/10) -> 233 | I43: 500 | J43: 2339 | K43: 06 | L43: 5.4
A44: =_xlfn.CONCAT(B44,"-",LEFT(D44,2),"-",LEFT(E44,3),"-",F44,"-",TRUNC(I44),"-",TRUNC(J44)) -> 2006-AH-TRA-76-548-2336 | B44: =LEFT(C44,4) -> 2006 | C44: 2006 | D44: AHD | E44: TRACER 79 | F44: 76 | G44: =TRUNC(I44/10) -> 54 | H44: =TRUNC(J44/10) -> 233 | I44: 548 | J44: 2336 | K44: 06 | L44: 5.7
A45: =_xlfn.CONCAT(B45,"-",LEFT(D45,2),"-",LEFT(E45,3),"-",F45,"-",TRUNC(I45),"-",TRUNC(J45)) -> 2006-AH-TRA-82-601-2362 | B45: =LEFT(C45,4) -> 2006 | C45: 2006 | D45: AHD | E45: TRACER 90 | F45: 82 | G45: =TRUNC(I45/10) -> 60 | H45: =TRUNC(J45/10) -> 236 | I45: 601 | J45: 2362 | K45: 06 | L45: 6
A46: =_xlfn.CONCAT(B46,"-",LEFT(D46,2),"-",LEFT(E46,3),"-",F46,"-",TRUNC(I46),"-",TRUNC(J46)) -> 2006-AH-TRA-113-709-2493 | B46: =LEFT(C46,4) -> 2006 | C46: 2006 | D46: AHD | E46: TRACER 113 | F46: 113 | G46: =TRUNC(I46/10) -> 70 | H46: =TRUNC(J46/10) -> 249 | I46: 709 | J46: 2493 | K46: 06 | L46: 7
... A61: =_xlfn.CONCAT(B61,"-",LEFT(D61,2),"-",LEFT(E61,3),"-",F61,"-",TRUNC(I61),"-",TRUNC(J61)) -> 2017-AH-SL3-128-815-2290 | B61: =LEFT(C61,4) -> 2017 | C61: 2017 | D61: AHD | E61: SL3 128 | F61: 128 | G61: =TRUNC(I61/10) -> 81 | H61: =TRUNC(J61/10) -> 229 | I61: 815 | J61: 2290 | K61: 10/7/17 | L61: 7
A62: =_xlfn.CONCAT(B62,"-",LEFT(D62,2),"-",LEFT(E62,3),"-",F62,"-",TRUNC(I62),"-",TRUNC(J62)) -> 1999-AH-DIA-83-540-2590 | B62: =LEFT(C62,4) -> 1999 | C62: 1999 | D62: AHD | E62: DIAMOND SLALOM 54 | F62: 83 | G62: =TRUNC(I62/10) -> 54 | H62: =TRUNC(J62/10) -> 259 | I62: 540 | J62: 2590 | K62: 1999 | L62: 6.2
A63: =_xlfn.CONCAT(B63,"-",LEFT(D63,2),"-",LEFT(E63,3),"-",F63,"-",TRUNC(I63),"-",TRUNC(J63)) -> 1999-AH-DIA-95-590-2640 | B63: =LEFT(C63,4) -> 1999 | C63: 1999 | D63: AHD | E63: DIAMOND SLALOM 58 | F63: 95 | G63: =TRUNC(I63/10) -> 59 | H63: =TRUNC(J63/10) -> 264 | I63: 590 | J63: 2640 | K63: 1999 | L63: 6.4
A64: =_xlfn.CONCAT(B64,"-",LEFT(D64,2),"-",LEFT(E64,3),"-",F64,"-",TRUNC(I64),"-",TRUNC(J64)) -> 1999-AH-DIA-145-670-2740 | B64: =LEFT(C64,4) -> 1999 | C64: 1999 | D64: AHD | E64: DIAMOND RACE 67 | F64: 145 | G64: =TRUNC(I64/10) -> 67 | H64: =TRUNC(J64/10) -> 274 | I64: 670 | J64: 2740 | K64: 1999 | L64: 7.2
A65: =_xlfn.CONCAT(B65,"-",LEFT(D65,2),"-",LEFT(E65,3),"-",F65,"-",TRUNC(I65),"-",TRUNC(J65)) -> 2010-AN-Mag-99-617-2382 | B65: =LEFT(C65,4) -> 2010 | C65: 2010 | D65: ANGULO | E65: Magnum 62 | F65: 99 | G65: =TRUNC(I65/10) -> 61 | H65: =TRUNC(J65/10) -> 238 | I65: 617 | J65: 2382 | K65: 09 | L65: 5.9
A66: =_xlfn.CONCAT(B66,"-",LEFT(D66,2),"-",LEFT(E66,3),"-",F66,"-",TRUNC(I66),"-",TRUNC(J66)) -> 2010-AN-Mag-130-728-2426 | B66: =LEFT(C66,4) -> 2010 | C66: 2010 | D66: ANGULO | E66: Magnum72 | F66: 130 | G66: =TRUNC(I66/10) -> 72 | H66: =TRUNC(J66/10) -> 242 | I66: 728 | J66: 2426 | K66: 09 | L66: 6.6
A67: =_xlfn.CONCAT(B67,"-",LEFT(D67,2),"-",LEFT(E67,3),"-",F67,"-",TRUNC(I67),"-",TRUNC(J67)) -> 2010-AN-Mag-152-837-2436 | B67: =LEFT(C67,4) -> 2010 | C67: 2010 | D67: ANGULO | E67: Magnum 82 | F67: 152 | G67: =TRUNC(I67/10) -> 83 | H67: =TRUNC(J67/10) -> 243 | I67: 837 | J67: 2436 | K67: 10 | L67: 7.1
A68: =_xlfn.CONCAT(B68,"-",LEFT(D68,2),"-",LEFT(E68,3),"-",F68,"-",TRUNC(I68),"-",TRUNC(J68)) -> 2011-AN-Mag-98-590-2380 | B68: =LEFT(C68,4) -> 2011 | C68: 2011 | D68: ANGULO | E68: Magnum 60 | F68: 98 | G68: =TRUNC(I68/10) -> 59 | H68: =TRUNC(J68/10) -> 238 | I68: 590 | J68: 2380 | K68: 11 | L68: 6.12
A69: =_xlfn.CONCAT(B69,"-",LEFT(D69,2),"-",LEFT(E69,3),"-",F69,"-",TRUNC(I69),"-",TRUNC(J69)) -> 2011-AN-Mag-116-700-2400 | B69: =LEFT(C69,4) -> 2011 | C69: 2011 | D69: ANGULO | E69: Magnum 71 | F69: 116 | G69: =TRUNC(I69/10) -> 70 | H69: =TRUNC(J69/10) -> 240 | I69: 700 | J69: 2400 | K69: 11 | L69: 6.62
...

Sheet GPS-Boards-Validation
A1: ID | B1: Brand | C1: Type | D1: Size | E1: Volume | F1: Year | G1: Class | H1: Sessions | I1: Temp Notes | K1: ID2 | L1: Vol | M1: Width | N1: Length | P1: XMATCH | Q1: XLookUp "-1"
A2: 10455 | B2: Fanatic | C2: Blast 100 LTD | D2: 62 x 231 cm | E2: 100 l | F2: 2018 | G2: Slalom Medium | H2: Fanatic Blast 100 LTD | K2: =_xlfn.CONCAT(F2,"-",LEFT(B2,2),"-",LEFT(C2,3),"-",L2,"-",M2,"-",N2) -> 2018-Fa-Bla-100-62-231 | L2: =_xlfn.REGEXREPLACE(E2,"[^0-9.]","")+0 -> 100 | M2: =LEFT(D2, FIND(" x", D2)-1) -> 62 | N2: =MID(D2, FIND("x ", D2)+2, FIND(" cm", D2)-FIND("x ", D2)-2) -> 231 | P2: =_xlfn.IFNA(_xlfn.XMATCH(K2,'Boards Catalogue'!A:A),-1) -> 147 | Q2: =_xlfn.XLOOKUP(K2,'Boards Catalogue'!A:A,'Boards Catalogue'!A:A,,-1) -> 2018-Fa-Bla-100-62-231
A3: 13502 | B3: Fanatic | C3: Blast 115 | D3: 66 x 232 cm | E3: 115 l | F3: 2018 | G3: Slalom Medium | H3: Fanatic Blast 115 | K3: =_xlfn.CONCAT(F3,"-",LEFT(B3,2),"-",LEFT(C3,3),"-",L3,"-",M3,"-",N3) -> 2018-Fa-Bla-115-66-232 | L3: =_xlfn.REGEXREPLACE(E3,"[^0-9.]","")+0 -> 115 | M3: =LEFT(D3, FIND(" x", D3)-1) -> 66 | N3: =MID(D3, FIND("x ", D3)+2, FIND(" cm", D3)-FIND("x ", D3)-2) -> 232 | P3: =_xlfn.IFNA(_xlfn.XMATCH(K3,'Boards Catalogue'!A:A),-1) -> 149 | Q3: =_xlfn.XLOOKUP(K3,'Boards Catalogue'!A:A,'Boards Catalogue'!A:A,,-1) -> 2018-Fa-Bla-115-66-232
A4: 9740 | B4: Fanatic | C4: Blast 115 LTD | D4: 66 x 232 cm | E4: 115 l | F4: 2018 | G4: Slalom Medium | H4: Fanatic Blast 115 LTD | K4: =_xlfn.CONCAT(F4,"-",LEFT(B4,2),"-",LEFT(C4,3),"-",L4,"-",M4,"-",N4) -> 2018-Fa-Bla-115-66-232 | L4: =_xlfn.REGEXREPLACE(E4,"[^0-9.]","")+0 -> 115 | M4: =LEFT(D4, FIND(" x", D4)-1) -> 66 | N4: =MID(D4, FIND("x ", D4)+2, FIND(" cm", D4)-FIND("x ", D4)-2) -> 232 | P4: =_xlfn.IFNA(_xlfn.XMATCH(K4,'Boards Catalogue'!A:A),-1) -> 149 | Q4: =_xlfn.XLOOKUP(K4,'Boards Catalogue'!A:A,'Boards Catalogue'!A:A,,-1) -> 2018-Fa-Bla-115-66-232
A5: 10388 | B5: Fanatic | C5: Blast 130 LTD | D5: 70 x 233 cm | E5: 130 l | F5: 2018 | G5: Slalom Large | H5: Fanatic Blast 130 LTD | K5: =_xlfn.CONCAT(F5,"-",LEFT(B5,2),"-",LEFT(C5,3),"-",L5,"-",M5,"-",N5) -> 2018-Fa-Bla-130-70-233 | L5: =_xlfn.REGEXREPLACE(E5,"[^0-9.]","")+0 -> 130 | M5: =LEFT(D5, FIND(" x", D5)-1) -> 70 | N5: =MID(D5, FIND("x ", D5)+2, FIND(" cm", D5)-FIND("x ", D5)-2) -> 233 | P5: =_xlfn.IFNA(_xlfn.XMATCH(K5,'Boards Catalogue'!A:A),-1) -> 151 | Q5: =_xlfn.XLOOKUP(K5,'Boards Catalogue'!A:A,'Boards Catalogue'!A:A,,-1) -> 2018-Fa-Bla-130-70-233
A6: 12165 | B6: Fanatic | C6: Blast 130 LTD | D6: 70 x 233 cm | E6: 130 l | F6: 2018 | G6: Slalom Large | H6: Fanatic Blast 130 LTD | K6: =_xlfn.CONCAT(F6,"-",LEFT(B6,2),"-",LEFT(C6,3),"-",L6,"-",M6,"-",N6) -> 2018-Fa-Bla-130-70-233 | L6: =_xlfn.REGEXREPLACE(E6,"[^0-9.]","")+0 -> 130 | M6: =LEFT(D6, FIND(" x", D6)-1) -> 70 | N6: =MID(D6, FIND("x ", D6)+2, FIND(" cm", D6)-FIND("x ", D6)-2) -> 233 | P6: =_xlfn.IFNA(_xlfn.XMATCH(K6,'Boards Catalogue'!A:A),-1) -> 151 | Q6: =_xlfn.XLOOKUP(K6,'Boards Catalogue'!A:A,'Boards Catalogue'!A:A,,-1) -> 2018-Fa-Bla-130-70-233
A7: 11191 | B7: Fanatic | C7: Blast 145 LTD | D7: 77 x 235 cm | E7: 145 l | F7: 2018 | G7: Slalom Medium | H7: Fanatic Blast 145 LTD | K7: =_xlfn.CONCAT(F7,"-",LEFT(B7,2),"-",LEFT(C7,3),"-",L7,"-",M7,"-",N7) -> 2018-Fa-Bla-145-77-235 | L7: =_xlfn.REGEXREPLACE(E7,"[^0-9.]","")+0 -> 145 | M7: =LEFT(D7, FIND(" x", D7)-1) -> 77 | N7: =MID(D7, FIND("x ", D7)+2, FIND(" cm", D7)-FIND("x ", D7)-2) -> 235 | P7: =_xlfn.IFNA(_xlfn.XMATCH(K7,'Boards Catalogue'!A:A),-1) -> 153 | Q7: =_xlfn.XLOOKUP(K7,'Boards Catalogue'!A:A,'Boards Catalogue'!A:A,,-1) -> 2018-Fa-Bla-145-77-235
A8: 10662 | B8: Fanatic | C8: Falcon 114 TE | D8: 71 x 230 cm | E8: 114 l | F8: 2018 | G8: Slalom Medium | H8: Fanatic Falcon 114 TE | K8: =_xlfn.CONCAT(F8,"-",LEFT(B8,2),"-",LEFT(C8,3),"-",L8,"-",M8,"-",N8) -> 2018-Fa-Fal-114-71-230 | L8: =_xlfn.REGEXREPLACE(E8,"[^0-9.]","")+0 -> 114 | M8: =LEFT(D8, FIND(" x", D8)-1) -> 71 | N8: =MID(D8, FIND("x ", D8)+2, FIND(" cm", D8)-FIND("x ", D8)-2) -> 230 | P8: =_xlfn.IFNA(_xlfn.XMATCH(K8,'Boards Catalogue'!A:A),-1) -> 155 | Q8: =_xlfn.XLOOKUP(K8,'Boards Catalogue'!A:A,'Boards Catalogue'!A:A,,-1) -> 2018-Fa-Fal-114-71-230
A9: 10391 | B9: Fanatic | C9: Falcon 129 | D9: 80 x 230 cm | E9: 129 l | F9: 2018 | G9: Slalom Large | H9: Fanatic Falcon 129 | K9: =_xlfn.CONCAT(F9,"-",LEFT(B9,2),"-",LEFT(C9,3),"-",L9,"-",M9,"-",N9) -> 2018-Fa-Fal-129-80-230 | L9: =_xlfn.REGEXREPLACE(E9,"[^0-9.]","")+0 -> 129 | M9: =LEFT(D9, FIND(" x", D9)-1) -> 80 | N9: =MID(D9, FIND("x ", D9)+2, FIND(" cm", D9)-FIND("x ", D9)-2) -> 230 | P9: =_xlfn.IFNA(_xlfn.XMATCH(K9,'Boards Catalogue'!A:A),-1) -> 157 | Q9: =_xlfn.XLOOKUP(K9,'Boards Catalogue'!A:A,'Boards Catalogue'!A:A,,-1) -> 2018-Fa-Fal-129-80-230
A10: 10650 | B10: Fanatic | C10: Falcon 89 | D10: 60 x 235 cm | E10: 89 l | F10: 2018 | G10: Speed/Slalom Small | H10: Fanatic Falcon 89 | K10: =_xlfn.CONCAT(F10,"-",LEFT(B10,2),"-",LEFT(C10,3),"-",L10,"-",M10,"-",N10) -> 2018-Fa-Fal-89-60-235 | L10: =_xlfn.REGEXREPLACE(E10,"[^0-9.]","")+0 -> 89 | M10: =LEFT(D10, FIND(" x", D10)-1) -> 60 | N10: =MID(D10, FIND("x ", D10)+2, FIND(" cm", D10)-FIND("x ", D10)-2) -> 235 | P10: =_xlfn.IFNA(_xlfn.XMATCH(K10,'Boards Catalogue'!A:A),-1) -> 164 | Q10: =_xlfn.XLOOKUP(K10,'Boards Catalogue'!A:A,'Boards Catalogue'!A:A,,-1) -> 2018-Fa-Fal-89-60-235
A11: 10419 | B11: Fanatic | C11: Falcon Lightwind | D11: 90 x 230 cm | E11: 159 l | F11: 2018 | G11: Slalom Xtra Large | H11: Fanatic Falcon Lightwind | K11: =_xlfn.CONCAT(F11,"-",LEFT(B11,2),"-",LEFT(C11,3),"-",L11,"-",M11,"-",N11) -> 2018-Fa-Fal-159-90-230 | L11: =_xlfn.REGEXREPLACE(E11,"[^0-9.]","")+0 -> 159 | M11: =LEFT(D11, FIND(" x", D11)-1) -> 90 | N11: =MID(D11, FIND("x ", D11)+2, FIND(" cm", D11)-FIND("x ", D11)-2) -> 230 | P11: =_xlfn.IFNA(_xlfn.XMATCH(K11,'Boards Catalogue'!A:A),-1) -> 159 | Q11: =_xlfn.XLOOKUP(K11,'Boards Catalogue'!A:A,'Boards Catalogue'!A:A,,-1) -> 2018-Fa-Fal-159-90-230
A12: 10683 | B12: Fanatic | C12: Falcon Speed 40 | D12: 40 x 228 cm | E12: 55 l | F12: 2018 | G12: Speedboard | H12: Fanatic Falcon Speed 40 | K12: =_xlfn.CONCAT(F12,"-",LEFT(B12,2),"-",LEFT(C12,3),"-",L12,"-",M12,"-",N12) -> 2018-Fa-Fal-55-40-228 | L12: =_xlfn.REGEXREPLACE(E12,"[^0-9.]","")+0 -> 55 | M12: =LEFT(D12, FIND(" x", D12)-1) -> 40 | N12: =MID(D12, FIND("x ", D12)+2, FIND(" cm", D12)-FIND("x ", D12)-2) -> 228 | P12: =_xlfn.IFNA(_xlfn.XMATCH(K12,'Boards Catalogue'!A:A),-1) -> -1 | Q12: =_xlfn.XLOOKUP(K12,'Boards Catalogue'!A:A,'Boards Catalogue'!A:A,,-1) -> 2018-Fa-Fal-54-44-230
A13: 10290 | B13: Fanatic | C13: Falcon Speed 52.5 | D13: 525 x 235 cm | E13: 70 l | F13: 2018 | G13: Speed/Slalom Small | H13: Fanatic Falcon Speed 52.5 | K13: =_xlfn.CONCAT(F13,"-",LEFT(B13,2),"-",LEFT(C13,3),"-",L13,"-",M13,"-",N13) -> 2018-Fa-Fal-70-525-235 | L13: =_xlfn.REGEXREPLACE(E13,"[^0-9.]","")+0 -> 70 | M13: =LEFT(D13, FIND(" x", D13)-1) -> 525 | N13: =MID(D13, FIND("x ", D13)+2, FIND(" cm", D13)-FIND("x ", D13)-2) -> 235 | P13: =_xlfn.IFNA(_xlfn.XMATCH(K13,'Boards Catalogue'!A:A),-1) -> -1 | Q13: =_xlfn.XLOOKUP(K13,'Boards Catalogue'!A:A,'Boards Catalogue'!A:A,,-1) -> 2018-Fa-Fal-70-52-230
... A22: 11871 | B22: Fanatic | C22: Gecko | D22: 78 x 246 cm | E22: 133 l | F22: 2018 | G22: Wave / Freestyle | H22: Fanatic Gecko | K22: =_xlfn.CONCAT(F22,"-",LEFT(B22,2),"-",LEFT(C22,3),"-",L22,"-",M22,"-",N22) -> 2018-Fa-Gec-133-78-246 | L22: =_xlfn.REGEXREPLACE(E22,"[^0-9.]","")+0 -> 133 | M22: =LEFT(D22, FIND(" x", D22)-1) -> 78 | N22: =MID(D22, FIND("x ", D22)+2, FIND(" cm", D22)-FIND("x ", D22)-2) -> 246 | P22: =_xlfn.IFNA(_xlfn.XMATCH(K22,'Boards Catalogue'!A:A),-1) -> 185 | Q22: =_xlfn.XLOOKUP(K22,'Boards Catalogue'!A:A,'Boards Catalogue'!A:A,,-1) -> 2018-Fa-Gec-133-78-246
A23: 11049 | B23: Fanatic | C23: Gecko 120 | D23: 76 x 242 cm | E23: 120 l | F23: 2018 | H23: Fanatic Gecko 120 | K23: =_xlfn.CONCAT(F23,"-",LEFT(B23,2),"-",LEFT(C23,3),"-",L23,"-",M23,"-",N23) -> 2018-Fa-Gec-120-76-242 | L23: =_xlfn.REGEXREPLACE(E23,"[^0-9.]","")+0 -> 120 | M23: =LEFT(D23, FIND(" x", D23)-1) -> 76 | N23: =MID(D23, FIND("x ", D23)+2, FIND(" cm", D23)-FIND("x ", D23)-2) -> 242 | P23: =_xlfn.IFNA(_xlfn.XMATCH(K23,'Boards Catalogue'!A:A),-1) -> 182 | Q23: =_xlfn.XLOOKUP(K23,'Boards Catalogue'!A:A,'Boards Catalogue'!A:A,,-1) -> 2018-Fa-Gec-120-76-242
A24: 10203 | B24: Fanatic | C24: Gecko Foil Edition | D24: 76 x 245 cm | E24: 120 l | F24: 2018 | G24: Slalom Large | H24: Fanatic Gecko Foil Edition | K24: =_xlfn.CONCAT(F24,"-",LEFT(B24,2),"-",LEFT(C24,3),"-",L24,"-",M24,"-",N24) -> 2018-Fa-Gec-120-76-245 | L24: =_xlfn.REGEXREPLACE(E24,"[^0-9.]","")+0 -> 120 | M24: =LEFT(D24, FIND(" x", D24)-1) -> 76 | N24: =MID(D24, FIND("x ", D24)+2, FIND(" cm", D24)-FIND("x ", D24)-2) -> 245 | P24: =_xlfn.IFNA(_xlfn.XMATCH(K24,'Boards Catalogue'!A:A),-1) -> -1 | Q24: =_xlfn.XLOOKUP(K24,'Boards Catalogue'!A:A,'Boards Catalogue'!A:A,,-1) -> 2018-Fa-Gec-120-76-242
A25: 10545 | B25: Fanatic | C25: Grip 82 | D25: 58 x 224 cm | E25: 82 l | F25: 2018 | G25: Wave / Freestyle | H25: Fanatic Grip 82 | K25: =_xlfn.CONCAT(F25,"-",LEFT(B25,2),"-",LEFT(C25,3),"-",L25,"-",M25,"-",N25) -> 2018-Fa-Gri-82-58-224 | L25: =_xlfn.REGEXREPLACE(E25,"[^0-9.]","")+0 -> 82 | M25: =LEFT(D25, FIND(" x", D25)-1) -> 58 | N25: =MID(D25, FIND("x ", D25)+2, FIND(" cm", D25)-FIND("x ", D25)-2) -> 224 | P25: =_xlfn.IFNA(_xlfn.XMATCH(K25,'Boards Catalogue'!A:A),-1) -> 196 | Q25: =_xlfn.XLOOKUP(K25,'Boards Catalogue'!A:A,'Boards Catalogue'!A:A,,-1) -> 2018-Fa-Gri-82-58-224
A26: 11188 | B26: Fanatic | C26: Grip 99 | D26: 62 x 229 cm | E26: 99 l | F26: 2018 | G26: Slalom Xtra Large | H26: Fanatic Grip 99 | K26: =_xlfn.CONCAT(F26,"-",LEFT(B26,2),"-",LEFT(C26,3),"-",L26,"-",M26,"-",N26) -> 2018-Fa-Gri-99-62-229 | L26: =_xlfn.REGEXREPLACE(E26,"[^0-9.]","")+0 -> 99 | M26: =LEFT(D26, FIND(" x", D26)-1) -> 62 | N26: =MID(D26, FIND("x ", D26)+2, FIND(" cm", D26)-FIND("x ", D26)-2) -> 229 | P26: =_xlfn.IFNA(_xlfn.XMATCH(K26,'Boards Catalogue'!A:A),-1) -> 198 | Q26: =_xlfn.XLOOKUP(K26,'Boards Catalogue'!A:A,'Boards Catalogue'!A:A,,-1) -> 2018-Fa-Gri-99-62-229
A27: 10563 | B27: Fanatic | C27: Jag 125 | D27: 75 x 235 cm | E27: 125 l | F27: 2018 | G27: Slalom Large | H27: Fanatic Jag 125 | K27: =_xlfn.CONCAT(F27,"-",LEFT(B27,2),"-",LEFT(C27,3),"-",L27,"-",M27,"-",N27) -> 2018-Fa-Jag-125-75-235 | L27: =_xlfn.REGEXREPLACE(E27,"[^0-9.]","")+0 -> 125 | M27: =LEFT(D27, FIND(" x", D27)-1) -> 75 | N27: =MID(D27, FIND("x ", D27)+2, FIND(" cm", D27)-FIND("x ", D27)-2) -> 235 | P27: =_xlfn.IFNA(_xlfn.XMATCH(K27,'Boards Catalogue'!A:A),-1) -> -1 | Q27: =_xlfn.XLOOKUP(K27,'Boards Catalogue'!A:A,'Boards Catalogue'!A:A,,-1) -> 2018-Fa-Gri-99-62-229
A28: 10291 | B28: Fanatic | C28: Lüderitz Speed 44 | D28: 44 x 230 cm | E28: 50 l | F28: 2018 | G28: Speedboard | H28: Fanatic Lüderitz Speed 44 | K28: =_xlfn.CONCAT(F28,"-",LEFT(B28,2),"-",LEFT(C28,3),"-",L28,"-",M28,"-",N28) -> 2018-Fa-Lüd-50-44-230 | L28: =_xlfn.REGEXREPLACE(E28,"[^0-9.]","")+0 -> 50 | M28: =LEFT(D28, FIND(" x", D28)-1) -> 44 | N28: =MID(D28, FIND("x ", D28)+2, FIND(" cm", D28)-FIND("x ", D28)-2) -> 230 | P28: =_xlfn.IFNA(_xlfn.XMATCH(K28,'Boards Catalogue'!A:A),-1) -> -1 | Q28: =_xlfn.XLOOKUP(K28,'Boards Catalogue'!A:A,'Boards Catalogue'!A:A,,-1) -> 2018-Fa-Gri-99-62-229
A29: 740 | B29: Fanatic | C29: Shark | D29: 70 x 295 cm | E29: 125 l | F29: 2018 | G29: Slalom Xtra Large | H29: Fanatic Shark | K29: =_xlfn.CONCAT(F29,"-",LEFT(B29,2),"-",LEFT(C29,3),"-",L29,"-",M29,"-",N29) -> 2018-Fa-Sha-125-70-295 | L29: =_xlfn.REGEXREPLACE(E29,"[^0-9.]","")+0 -> 125 | M29: =LEFT(D29, FIND(" x", D29)-1) -> 70 | N29: =MID(D29, FIND("x ", D29)+2, FIND(" cm", D29)-FIND("x ", D29)-2) -> 295 | P29: =_xlfn.IFNA(_xlfn.XMATCH(K29,'Boards Catalogue'!A:A),-1) -> -1 | Q29: =_xlfn.XLOOKUP(K29,'Boards Catalogue'!A:A,'Boards Catalogue'!A:A,,-1) -> 2018-Fa-Rip-187-73-274
A30: 10240 | B30: Fanatic | C30: Slalom TE 136 | D30: 85 x 235 cm | E30: 136 l | F30: 2018 | G30: Slalom Large | H30: Fanatic Slalom TE 136 | K30: =_xlfn.CONCAT(F30,"-",LEFT(B30,2),"-",LEFT(C30,3),"-",L30,"-",M30,"-",N30) -> 2018-Fa-Sla-136-85-235 | L30: =_xlfn.REGEXREPLACE(E30,"[^0-9.]","")+0 -> 136 | M30: =LEFT(D30, FIND(" x", D30)-1) -> 85 | N30: =MID(D30, FIND("x ", D30)+2, FIND(" cm", D30)-FIND("x ", D30)-2) -> 235 | P30: =_xlfn.IFNA(_xlfn.XMATCH(K30,'Boards Catalogue'!A:A),-1) -> -1 | Q30: =_xlfn.XLOOKUP(K30,'Boards Catalogue'!A:A,'Boards Catalogue'!A:A,,-1) -> 2018-Fa-Ska-93-62-225
A31: 10237 | B31: Fanatic | C31: Slalom TE 98 | D31: 63 x 235 cm | E31: 98 l | F31: 2018 | G31: Slalom Medium | H31: Fanatic Slalom TE 98 | K31: =_xlfn.CONCAT(F31,"-",LEFT(B31,2),"-",LEFT(C31,3),"-",L31,"-",M31,"-",N31) -> 2018-Fa-Sla-98-63-235 | L31: =_xlfn.REGEXREPLACE(E31,"[^0-9.]","")+0 -> 98 | M31: =LEFT(D31, FIND(" x", D31)-1) -> 63 | N31: =MID(D31, FIND("x ", D31)+2, FIND(" cm", D31)-FIND("x ", D31)-2) -> 235 | P31: =_xlfn.IFNA(_xlfn.XMATCH(K31,'Boards Catalogue'!A:A),-1) -> -1 | Q31: =_xlfn.XLOOKUP(K31,'Boards Catalogue'!A:A,'Boards Catalogue'!A:A,,-1) -> 2018-Fa-Ska-93-62-225
A32: 10219 | B32: Fanatic | C32: Stubby TE 99 | D32: 60 x 218 cm | E32: 99 l | F32: 2018 | G32: Wave / Freestyle | H32: Fanatic Stubby TE 99 | K32: =_xlfn.CONCAT(F32,"-",LEFT(B32,2),"-",LEFT(C32,3),"-",L32,"-",M32,"-",N32) -> 2018-Fa-Stu-99-60-218 | L32: =_xlfn.REGEXREPLACE(E32,"[^0-9.]","")+0 -> 99 | M32: =LEFT(D32, FIND(" x", D32)-1) -> 60 | N32: =MID(D32, FIND("x ", D32)+2, FIND(" cm", D32)-FIND("x ", D32)-2) -> 218 | P32: =_xlfn.IFNA(_xlfn.XMATCH(K32,'Boards Catalogue'!A:A),-1) -> 208 | Q32: =_xlfn.XLOOKUP(K32,'Boards Catalogue'!A:A,'Boards Catalogue'!A:A,,-1) -> 2018-Fa-Stu-99-60-218
A33: 12906 | B33: Fanatic | C33: Viper | D33: 85 x 285 cm | E33: 220 l | F33: 2018 | G33: Slalom Xtra Large | H33: Fanatic Viper | K33: =_xlfn.CONCAT(F33,"-",LEFT(B33,2),"-",LEFT(C33,3),"-",L33,"-",M33,"-",N33) -> 2018-Fa-Vip-220-85-285 | L33: =_xlfn.REGEXREPLACE(E33,"[^0-9.]","")+0 -> 220 | M33: =LEFT(D33, FIND(" x", D33)-1) -> 85 | N33: =MID(D33, FIND("x ", D33)+2, FIND(" cm", D33)-FIND("x ", D33)-2) -> 285 | P33: =_xlfn.IFNA(_xlfn.XMATCH(K33,'Boards Catalogue'!A:A),-1) -> 212 | Q33: =_xlfn.XLOOKUP(K33,'Boards Catalogue'!A:A,'Boards Catalogue'!A:A,,-1) -> 2018-Fa-Vip-220-85-285
A34: 13285 | B34: Fanatic | C34: Wave | D34: 64 x 232 cm | E34: 103 l | F34: 2018 | G34: Wave / Freestyle | H34: Fanatic Wave | K34: =_xlfn.CONCAT(F34,"-",LEFT(B34,2),"-",LEFT(C34,3),"-",L34,"-",M34,"-",N34) -> 2018-Fa-Wav-103-64-232 | L34: =_xlfn.REGEXREPLACE(E34,"[^0-9.]","")+0 -> 103 | M34: =LEFT(D34, FIND(" x", D34)-1) -> 64 | N34: =MID(D34, FIND("x ", D34)+2, FIND(" cm", D34)-FIND("x ", D34)-2) -> 232 | P34: =_xlfn.IFNA(_xlfn.XMATCH(K34,'Boards Catalogue'!A:A),-1) -> -1 | Q34: =_xlfn.XLOOKUP(K34,'Boards Catalogue'!A:A,'Boards Catalogue'!A:A,,-1) -> 2018-Fa-Vip-355-85-335

Sheet Temp-Berra-ToAddAfterReview
A2: YEAR | B2: Brand | C2: MODELS | D2: VOLUME | E2: WIDTH | F2: LENGTH | G2: TECHNOLOGY | H2: FIN BOXES | I2: FINS | J2: REC. SAIL SIZES | K2: Weight

Sheet Temp-Berra-unit-remove
A1: YEAR | B1: Brand | C1: MODELS | D1: VOLUME | E1: WIDTH | F1: LENGTH | G1: TECHNOLOGY | H1: FIN BOXES | I1: FINS | J1: REC. SAIL SIZES
A2: 2020 | B2: Fanatic | C2: Grip XS | D2: 60 | E2: 52 | F2: 218 | G2: Biax Fibre / Full PVC Sandw. LF | H2: 4 × Slot Box | I2: CF 2 × 9 cm, 2 × 14 cm | J2: Up to 4.7 m2 | M2: =_xlfn.REGEXREPLACE(D2,"[^0-9.]","")+0 -> 60 | N2: =_xlfn.REGEXREPLACE(E2,"[^0-9.]","")+0 -> 52 | O2: =_xlfn.REGEXREPLACE(F2,"[^0-9.]","")+0 -> 218 | Q2: 60 | R2: 52 | S2: 218
A3: 2020 | B3: Fanatic | C3: Grip TE | D3: 68 | E3: 54 | F3: 220 | G3: Biax Innegra Carbon LF | H3: 4 × Slot Box | I3: CF 2 × 9 cm, 2 × 14 cm | J3: Up to 5.0 m2 | M3: =_xlfn.REGEXREPLACE(D3,"[^0-9.]","")+0 -> 68 | N3: =_xlfn.REGEXREPLACE(E3,"[^0-9.]","")+0 -> 54 | O3: =_xlfn.REGEXREPLACE(F3,"[^0-9.]","")+0 -> 220 | Q3: 68 | R3: 54 | S3: 220
A4: 2020 | B4: Fanatic | C4: Grip TE | D4: 75 | E4: 56 | F4: 222 | G4: Biax Innegra Carbon LF | H4: 5 × Slot Box | J4: Up to 5.3 m2 | M4: =_xlfn.REGEXREPLACE(D4,"[^0-9.]","")+0 -> 75 | N4: =_xlfn.REGEXREPLACE(E4,"[^0-9.]","")+0 -> 56 | O4: =_xlfn.REGEXREPLACE(F4,"[^0-9.]","")+0 -> 222 | Q4: 75 | R4: 56 | S4: 222
A5: 2020 | B5: Fanatic | C5: Grip TE | D5: 82 | E5: 58 | F5: 224 | G5: Biax Innegra Carbon LF | H5: 5 × Slot Box | I5: CF 2 × 9.5 cm, 2 × 14.5 cm | J5: Up to 5.8 m2 | M5: =_xlfn.REGEXREPLACE(D5,"[^0-9.]","")+0 -> 82 | N5: =_xlfn.REGEXREPLACE(E5,"[^0-9.]","")+0 -> 58 | O5: =_xlfn.REGEXREPLACE(F5,"[^0-9.]","")+0 -> 224 | Q5: 82 | R5: 58 | S5: 224
A6: 2020 | B6: Fanatic | C6: Grip TE | D6: 86 | E6: 58.5 | F6: 225 | G6: Biax Innegra Carbon LF | H6: 5 × Slot Box | J6: Up to 6.0 m2 | M6: =_xlfn.REGEXREPLACE(D6,"[^0-9.]","")+0 -> 86 | N6: =_xlfn.REGEXREPLACE(E6,"[^0-9.]","")+0 -> 58.5 | O6: =_xlfn.REGEXREPLACE(F6,"[^0-9.]","")+0 -> 225 | Q6: 86 | R6: 58.5 | S6: 225
A7: 2020 | B7: Fanatic | C7: Grip TE | D7: 92 | E7: 59.5 | F7: 226 | G7: Biax Innegra Carbon LF | H7: 5 × Slot Box | I7: CF 2 × 10 cm, 2 × 14.5 cm | J7: Up to 6.2 m2 | M7: =_xlfn.REGEXREPLACE(D7,"[^0-9.]","")+0 -> 92 | N7: =_xlfn.REGEXREPLACE(E7,"[^0-9.]","")+0 -> 59.5 | O7: =_xlfn.REGEXREPLACE(F7,"[^0-9.]","")+0 -> 226 | Q7: 92 | R7: 59.5 | S7: 226
A8: 2020 | B8: Fanatic | C8: Grip TE | D8: 102 | E8: 61 | F8: 228 | G8: Biax Innegra Carbon LF | H8: 5 × Slot Box | I8: MFC TF Black 2 × 12 cm, 19 cm | J8: Up to 6.5 m2 | M8: =_xlfn.REGEXREPLACE(D8,"[^0-9.]","")+0 -> 102 | N8: =_xlfn.REGEXREPLACE(E8,"[^0-9.]","")+0 -> 61 | O8: =_xlfn.REGEXREPLACE(F8,"[^0-9.]","")+0 -> 228 | Q8: 102 | R8: 61 | S8: 228
A9: 2020 | B9: Fanatic | C9: Stubby TE | D9: 76 | E9: 55 | F9: 212 | G9: Biax Innegra Carbon LF | H9: 2 × Slot Box, Center US Box | I9: CF 2 × 12 cm, 17 cm | J9: Up to 5.3 m2 | M9: =_xlfn.REGEXREPLACE(D9,"[^0-9.]","")+0 -> 76 | N9: =_xlfn.REGEXREPLACE(E9,"[^0-9.]","")+0 -> 55 | O9: =_xlfn.REGEXREPLACE(F9,"[^0-9.]","")+0 -> 212 | Q9: 76 | R9: 55 | S9: 212
A10: 2020 | B10: Fanatic | C10: Stubby TE | D10: 82 | E10: 56 | F10: 214 | G10: Biax Innegra Carbon LF | H10: 2 × Slot Box, Center US Box | I10: CF 2 × 12 cm, 17 cm | J10: Up to 5.8 m2 | M10: =_xlfn.REGEXREPLACE(D10,"[^0-9.]","")+0 -> 82 | N10: =_xlfn.REGEXREPLACE(E10,"[^0-9.]","")+0 -> 56 | O10: =_xlfn.REGEXREPLACE(F10,"[^0-9.]","")+0 -> 214 | Q10: 82 | R10: 56 | S10: 214
A11: 2020 | B11: Fanatic | C11: Stubby TE | D11: 89 | E11: 57.5 | F11: 215 | G11: Biax Innegra Carbon LF | H11: 2 × Slot Box, Center US Box | I11: CF 2 × 12 cm, 18 cm | J11: Up to 6.2 m2 | M11: =_xlfn.REGEXREPLACE(D11,"[^0-9.]","")+0 -> 89 | N11: =_xlfn.REGEXREPLACE(E11,"[^0-9.]","")+0 -> 57.5 | O11: =_xlfn.REGEXREPLACE(F11,"[^0-9.]","")+0 -> 215 | Q11: 89 | R11: 57.5 | S11: 215
A12: 2020 | B12: Fanatic | C12: Stubby TE | D12: 99 | E12: 60 | F12: 218 | G12: Biax Innegra Carbon LF | H12: 2 × Slot Box, Center US Box | I12: CF 2 × 12 cm, 18 cm | J12: Up to 6.5 m2 | M12: =_xlfn.REGEXREPLACE(D12,"[^0-9.]","")+0 -> 99 | N12: =_xlfn.REGEXREPLACE(E12,"[^0-9.]","")+0 -> 60 | O12: =_xlfn.REGEXREPLACE(F12,"[^0-9.]","")+0 -> 218 | Q12: 99 | R12: 60 | S12: 218
A13: 2020 | B13: Fanatic | C13: FreeWave TXTR | D13: 85 | E13: 58.5 | F13: 229 | G13: TeXtreme® / Biax Innegra | H13: Power Box, 2 × Slot Box | I13: MFC TF Black 2 × 12 cm, 19 cm | J13: Up to 6.0 m2 | M13: =_xlfn.REGEXREPLACE(D13,"[^0-9.]","")+0 -> 85 | N13: =_xlfn.REGEXREPLACE(E13,"[^0-9.]","")+0 -> 58.5 | O13: =_xlfn.REGEXREPLACE(F13,"[^0-9.]","")+0 -> 229 | Q13: 85 | R13: 58.5 | S13: 229
A14: 2020 | B14: Fanatic | C14: FreeWave TXTR | D14: 95 | E14: 61 | F14: 230 | G14: TeXtreme® / Biax Innegra | H14: Power Box, 2 × Slot Box | I14: MFC TF Black 2 × 12 cm, 20 cm | J14: Up to 6.2 m2 | M14: =_xlfn.REGEXREPLACE(D14,"[^0-9.]","")+0 -> 95 | N14: =_xlfn.REGEXREPLACE(E14,"[^0-9.]","")+0 -> 61 | O14: =_xlfn.REGEXREPLACE(F14,"[^0-9.]","")+0 -> 230 | Q14: 95 | R14: 61 | S14: 230
A15: 2020 | B15: Fanatic | C15: FreeWave TXTR | D15: 105 | E15: 63 | F15: 231 | G15: Carbon LF | H15: Power Box, 2 × Slot Box | I15: MFC TF Black 2 × 12 cm, 21 cm | J15: Up to 6.8 m2 | M15: =_xlfn.REGEXREPLACE(D15,"[^0-9.]","")+0 -> 105 | N15: =_xlfn.REGEXREPLACE(E15,"[^0-9.]","")+0 -> 63 | O15: =_xlfn.REGEXREPLACE(F15,"[^0-9.]","")+0 -> 231 | Q15: 105 | R15: 63 | S15: 231
A16: 2020 | B16: Fanatic | C16: FreeWave TXTR | D16: 115 | E16: 65 | F16: 232 | H16: Power Box, 2 × Slot Box | I16: MFC 30 cm G10 | J16: Up to 7.5 m2 | M16: =_xlfn.REGEXREPLACE(D16,"[^0-9.]","")+0 -> 115 | N16: =_xlfn.REGEXREPLACE(E16,"[^0-9.]","")+0 -> 65 | O16: =_xlfn.REGEXREPLACE(F16,"[^0-9.]","")+0 -> 232 | Q16: 115 | R16: 65 | S16: 232
A17: 2020 | B17: Fanatic | C17: Freewave TE | D17: 75 | E17: 56 | F17: 228 | G17: Biax Innegra Carbon LF | H17: Power Box, 2 × Slot Box | I17: MFC TF Black 2 × 12 cm, 18 cm | J17: Up to 5.8 m2 | M17: =_xlfn.REGEXREPLACE(D17,"[^0-9.]","")+0 -> 75 | N17: =_xlfn.REGEXREPLACE(E17,"[^0-9.]","")+0 -> 56 | O17: =_xlfn.REGEXREPLACE(F17,"[^0-9.]","")+0 -> 228 | Q17: 75 | R17: 56 | S17: 228
A18: 2020 | B18: Fanatic | C18: Freewave TE | D18: 85 | E18: 58.5 | F18: 229 | G18: Biax Innegra Carbon LF | H18: Power Box, 2 × Slot Box | I18: MFC TF Black 2 × 12 cm, 19 cm | J18: Up to 6.0 m2 | M18: =_xlfn.REGEXREPLACE(D18,"[^0-9.]","")+0 -> 85 | N18: =_xlfn.REGEXREPLACE(E18,"[^0-9.]","")+0 -> 58.5 | O18: =_xlfn.REGEXREPLACE(F18,"[^0-9.]","")+0 -> 229 | Q18: 85 | R18: 58.5 | S18: 229
A19: 2020 | B19: Fanatic | C19: Freewave TE | D19: 95 | E19: 61 | F19: 230 | G19: Biax Innegra Carbon LF | H19: Power Box, 2 × Slot Box | I19: MFC TF Black 2 × 12 cm, 20 cm | J19: Up to 6.2 m2 | M19: =_xlfn.REGEXREPLACE(D19,"[^0-9.]","")+0 -> 95 | N19: =_xlfn.REGEXREPLACE(E19,"[^0-9.]","")+0 -> 61 | O19: =_xlfn.REGEXREPLACE(F19,"[^0-9.]","")+0 -> 230 | Q19: 95 | R19: 61 | S19: 230
A20: 2020 | B20: Fanatic | C20: Freewave TE | D20: 105 | E20: 63 | F20: 231 | G20: Biax Innegra Carbon LF | H20: Power Box, 2 × Slot Box | I20: MFC TF Black 2 × 12 cm, 21 cm | J20: Up to 6.8 m2 | M20: =_xlfn.REGEXREPLACE(D20,"[^0-9.]","")+0 -> 105 | N20: =_xlfn.REGEXREPLACE(E20,"[^0-9.]","")+0 -> 63 | O20: =_xlfn.REGEXREPLACE(F20,"[^0-9.]","")+0 -> 231 | Q20: 105 | R20: 63 | S20: 231
A21: 2020 | B21: Fanatic | C21: Freewave TE | D21: 115 | E21: 65 | F21: 232 | G21: Biax Innegra Carbon LF | H21: Power Box, 2 × Slot Box | I21: MFC 30 cm G10 | J21: Up to 7.5 m2 | M21: =_xlfn.REGEXREPLACE(D21,"[^0-9.]","")+0 -> 115 | N21: =_xlfn.REGEXREPLACE(E21,"[^0-9.]","")+0 -> 65 | O21: =_xlfn.REGEXREPLACE(F21,"[^0-9.]","")+0 -> 232 | Q21: 115 | R21: 65 | S21: 232
A22: 2020 | B22: Fanatic | C22: Freewave | D22: 75 | E22: 56 | F22: 228 | G22: Biax Fibre / Full PVC Sandwich LF | H22: Power Box, 2 × Slot Box | I22: CF G10 24 cm | J22: Up to 5.8 m2 | M22: =_xlfn.REGEXREPLACE(D22,"[^0-9.]","")+0 -> 75 | N22: =_xlfn.REGEXREPLACE(E22,"[^0-9.]","")+0 -> 56 | O22: =_xlfn.REGEXREPLACE(F22,"[^0-9.]","")+0 -> 228 | Q22: 75 | R22: 56 | S22: 228
A23: 2020 | B23: Fanatic | C23: Freewave | D23: 85 | E23: 58.5 | F23: 229 | G23: Biax Fibre / Full PVC Sandwich LF | H23: Power Box, 2 × Slot Box | I23: CF G10 26 cm | J23: Up to 6.0 m2 | M23: =_xlfn.REGEXREPLACE(D23,"[^0-9.]","")+0 -> 85 | N23: =_xlfn.REGEXREPLACE(E23,"[^0-9.]","")+0 -> 58.5 | O23: =_xlfn.REGEXREPLACE(F23,"[^0-9.]","")+0 -> 229 | Q23: 85 | R23: 58.5 | S23: 229
A24: 2020 | B24: Fanatic | C24: Freewave | D24: 95 | E24: 61 | F24: 230 | G24: Biax Fibre / Full PVC Sandwich LF | H24: Power Box, 2 × Slot Box | I24: CF G10 28 cm | J24: Up to 6.2 m2 | M24: =_xlfn.REGEXREPLACE(D24,"[^0-9.]","")+0 -> 95 | N24: =_xlfn.REGEXREPLACE(E24,"[^0-9.]","")+0 -> 61 | O24: =_xlfn.REGEXREPLACE(F24,"[^0-9.]","")+0 -> 230 | Q24: 95 | R24: 61 | S24: 230
A25: 2020 | B25: Fanatic | C25: Freewave | D25: 105 | E25: 63 | F25: 231 | G25: Biax Fibre / Full PVC Sandwich LF | H25: Power Box, 2 × Slot Box | I25: CF G10 30 cm | J25: Up to 6.8 m2 | M25: =_xlfn.REGEXREPLACE(D25,"[^0-9.]","")+0 -> 105 | N25: =_xlfn.REGEXREPLACE(E25,"[^0-9.]","")+0 -> 63 | O25: =_xlfn.REGEXREPLACE(F25,"[^0-9.]","")+0 -> 231 | Q25: 105 | R25: 63 | S25: 231
A26: 2020 | B26: Fanatic | C26: Skate TE | D26: 85 | E26: 60 | F26: 225 | G26: Biax Innegra Carbon LF | H26: Power Box | I26: CF Composite Innegra Carbon 17.5 cm | J26: Up to 5.3 m2 | M26: =_xlfn.REGEXREPLACE(D26,"[^0-9.]","")+0 -> 85 | N26: =_xlfn.REGEXREPLACE(E26,"[^0-9.]","")+0 -> 60 | O26: =_xlfn.REGEXREPLACE(F26,"[^0-9.]","")+0 -> 225 | Q26: 85 | R26: 60 | S26: 225
A27: 2020 | B27: Fanatic | C27: Skate TE | D27: 92 | E27: 62 | F27: 220 | G27: Biax Innegra Carbon LF | H27: Power Box | I27: CF Composite Innegra Carbon 18.5 cm | J27: Up to 5.9 m2 | M27: =_xlfn.REGEXREPLACE(D27,"[^0-9.]","")+0 -> 92 | N27: =_xlfn.REGEXREPLACE(E27,"[^0-9.]","")+0 -> 62 | O27: =_xlfn.REGEXREPLACE(F27,"[^0-9.]","")+0 -> 220 | Q27: 92 | R27: 62 | S27: 220
A28: 2020 | B28: Fanatic | C28: Skate TE | D28: 99 | E28: 65 | F28: 225 | G28: Biax Innegra Carbon LF | H28: Power Box | I28: CF Composite Innegra Carbon 20 cm | J28: Up to 6.2 m2 | M28: =_xlfn.REGEXREPLACE(D28,"[^0-9.]","")+0 -> 99 | N28: =_xlfn.REGEXREPLACE(E28,"[^0-9.]","")+0 -> 65 | O28: =_xlfn.REGEXREPLACE(F28,"[^0-9.]","")+0 -> 225 | Q28: 99 | R28: 65 | S28: 225
... A31: 2020 | B31: Fanatic | C31: Blast LTD | D31: 115 | E31: 66 | F31: 232 | G31: Biax Fibre / Full PVC Sandwich LF | H31: Foil Tuttle Box | I31: CF Composite Black 38 cm | J31: Up to 8.4 m2 | M31: =_xlfn.REGEXREPLACE(D31,"[^0-9.]","")+0 -> 115 | N31: =_xlfn.REGEXREPLACE(E31,"[^0-9.]","")+0 -> 66 | O31: =_xlfn.REGEXREPLACE(F31,"[^0-9.]","")+0 -> 232 | Q31: 115 | R31: 66 | S31: 232
A32: 2020 | B32: Fanatic | C32: Blast LTD | D32: 130 | E32: 70 | F32: 233 | G32: Biax Fibre / Full PVC Sandwich LF | I32: CF Composite Black 42 cm | J32: Up to 9.0 m2 | M32: =_xlfn.REGEXREPLACE(D32,"[^0-9.]","")+0 -> 130 | N32: =_xlfn.REGEXREPLACE(E32,"[^0-9.]","")+0 -> 70 | O32: =_xlfn.REGEXREPLACE(F32,"[^0-9.]","")+0 -> 233 | Q32: 130 | R32: 70 | S32: 233
A33: 2020 | B33: Fanatic | C33: Blast LTD | D33: 145 | E33: 77 | F33: 235 | G33: Biax Fibre / Full PVC Sandwich LF | I33: CF Composite Black 44 cm | J33: Up to 10.0 m2 | M33: =_xlfn.REGEXREPLACE(D33,"[^0-9.]","")+0 -> 145 | N33: =_xlfn.REGEXREPLACE(E33,"[^0-9.]","")+0 -> 77 | O33: =_xlfn.REGEXREPLACE(F33,"[^0-9.]","")+0 -> 235 | Q33: 145 | R33: 77 | S33: 235
A34: 2020 | B34: Fanatic | C34: Blast HRS | D34: 100 | E34: 62 | F34: 231 | G34: High Resistance Skin | H34: Foil Tuttle Box | I34: CF Composite White 34 cm | J34: Up to 7.8 m2 | M34: =_xlfn.REGEXREPLACE(D34,"[^0-9.]","")+0 -> 100 | N34: =_xlfn.REGEXREPLACE(E34,"[^0-9.]","")+0 -> 62 | O34: =_xlfn.REGEXREPLACE(F34,"[^0-9.]","")+0 -> 231 | Q34: 100 | R34: 62 | S34: 231
A35: 2020 | B35: Fanatic | C35: Blast HRS | D35: 115 | E35: 66 | F35: 232 | G35: High Resistance Skin | H35: Foil Tuttle Box | I35: CF Composite White 38 cm | J35: Up to 8.4 m2 | M35: =_xlfn.REGEXREPLACE(D35,"[^0-9.]","")+0 -> 115 | N35: =_xlfn.REGEXREPLACE(E35,"[^0-9.]","")+0 -> 66 | O35: =_xlfn.REGEXREPLACE(F35,"[^0-9.]","")+0 -> 232 | Q35: 115 | R35: 66 | S35: 232
A36: 2020 | B36: Fanatic | C36: Blast HRS | D36: 130 | E36: 70 | F36: 233 | G36: High Resistance Skin | H36: Foil Tuttle Box | I36: CF Composite White 42 cm | J36: Up to 9.0 m2 | M36: =_xlfn.REGEXREPLACE(D36,"[^0-9.]","")+0 -> 130 | N36: =_xlfn.REGEXREPLACE(E36,"[^0-9.]","")+0 -> 70 | O36: =_xlfn.REGEXREPLACE(F36,"[^0-9.]","")+0 -> 233 | Q36: 130 | R36: 70 | S36: 233
A37: 2020 | B37: Fanatic | C37: Blast HRS | D37: 145 | E37: 77 | F37: 235 | G37: High Resistance Skin | H37: Foil Tuttle Box | I37: CF Composite White 44 cm | J37: Up to 10.0 m2 | M37: =_xlfn.REGEXREPLACE(D37,"[^0-9.]","")+0 -> 145 | N37: =_xlfn.REGEXREPLACE(E37,"[^0-9.]","")+0 -> 77 | O37: =_xlfn.REGEXREPLACE(F37,"[^0-9.]","")+0 -> 235 | Q37: 145 | R37: 77 | S37: 235
A38: 2020 | B38: Fanatic | C38: Gecko LTD | D38: 100 | E38: 66 | F38: 239 | G38: Biax Fibre / Full PVC Sandwich LF | H38: Power Box | I38: CF Composite Black 36 cm | J38: Up to 8.0 m2 | M38: =_xlfn.REGEXREPLACE(D38,"[^0-9.]","")+0 -> 100 | N38: =_xlfn.REGEXREPLACE(E38,"[^0-9.]","")+0 -> 66 | O38: =_xlfn.REGEXREPLACE(F38,"[^0-9.]","")+0 -> 239 | Q38: 100 | R38: 66 | S38: 239
A39: 2020 | B39: Fanatic | C39: Gecko LTD | D39: 110 | E39: 72 | F39: 239 | G39: Biax Fibre / Full PVC Sandwich LF | H39: Power Box | I39: CF Composite Black 38 cm | J39: Up to 8.5 m2 | M39: =_xlfn.REGEXREPLACE(D39,"[^0-9.]","")+0 -> 110 | N39: =_xlfn.REGEXREPLACE(E39,"[^0-9.]","")+0 -> 72 | O39: =_xlfn.REGEXREPLACE(F39,"[^0-9.]","")+0 -> 239 | Q39: 110 | R39: 72 | S39: 239
A40: 2020 | B40: Fanatic | C40: Gecko LTD | D40: 122 | E40: 77 | F40: 242 | G40: Biax Fibre / Full PVC Sandwich LF | H40: Power Box | I40: CF Composite Black 40 cm | J40: Up to 9.0 m2 | M40: =_xlfn.REGEXREPLACE(D40,"[^0-9.]","")+0 -> 122 | N40: =_xlfn.REGEXREPLACE(E40,"[^0-9.]","")+0 -> 77 | O40: =_xlfn.REGEXREPLACE(F40,"[^0-9.]","")+0 -> 242 | Q40: 122 | R40: 77 | S40: 242
A41: 2020 | B41: Fanatic | C41: Gecko LTD | D41: 135 | E41: 79 | F41: 246 | G41: Biax Fibre / Full PVC Sandwich LF | H41: Power Box | I41: CF Composite Black 42 cm | J41: Up to 9.5 m2 | M41: =_xlfn.REGEXREPLACE(D41,"[^0-9.]","")+0 -> 135 | N41: =_xlfn.REGEXREPLACE(E41,"[^0-9.]","")+0 -> 79 | O41: =_xlfn.REGEXREPLACE(F41,"[^0-9.]","")+0 -> 246 | Q41: 135 | R41: 79 | S41: 246
A42: 2020 | B42: Fanatic | C42: Gecko LTD | D42: 148 | E42: 83 | F42: 250 | G42: Biax Fibre / Full PVC Sandwich LF | H42: Power Box | I42: CF Composite Black 46 cm | J42: Up to 10 m2 | M42: =_xlfn.REGEXREPLACE(D42,"[^0-9.]","")+0 -> 148 | N42: =_xlfn.REGEXREPLACE(E42,"[^0-9.]","")+0 -> 83 | O42: =_xlfn.REGEXREPLACE(F42,"[^0-9.]","")+0 -> 250 | Q42: 148 | R42: 83 | S42: 250
...
