Workbook
Name _Poängställning_01: "$#REF!.$A$302"
Name _poängställning_rekord: "$#REF!.$A$249"
Name Abborre_01: "$#REF!.$J$3"
Name Abborre_Rekord: "$#REF!.$B$1"
Name Ål_01: "$#REF!.$J$257"
Name Ål_rekord: "$#REF!.$B$217"
Name Asp_01: "$#REF!.$J$16"
Name Asp_rekord: "$#REF!.$B$9"
Name Björkna_01: "$#REF!.$J$29"
Name Björkna_rekord: "$#REF!.$B$17"
Name Brax_01: "$#REF!.$J$41"
Name Brax_rekord: "$#REF!.$B$25"
Name Faren_01: "$#REF!.$J$54"
Name Faren_rekord: "$#REF!.$B$33"
Name Färna_01: "$#REF!.$J$67"
Name Färna_rekord: "$#REF!.$B$41"
Name Gädda_01: "$#REF!.$J$79"
Name Gädda_rekord: "$#REF!.$B$57"
Name Gös_01: "$#REF!.$J$92"
Name Gös_rekord: "$#REF!.$B$65"
Name Gräskarp_rekord: "$#REF!.$B$49"
Name Harr_rekord: "$#REF!.$B$73"
Name Havsöring_rekord: "$#REF!.$B$81"
Name Id_01: "$#REF!.$J$105"
Name Id_rekord: "$#REF!.$B$89"
Name Insjö.lax_rekord: "$#REF!.$B$105"
Name Insjö.öring_rekord: "$#REF!.$B$97"
Name Karp_01: "$#REF!.$J$117"
Name Karp_rekord: "$#REF!.$B$113"
Name Lake_01: "$#REF!.$J$130"
Name Lake_rekord: "$#REF!.$B$121"
Name Lax_01: "$#REF!.$J$143"
Name Lax_rekord: "$#REF!.$B$129"
Name Mal_rekord: "$#REF!.$B$137"
Name Mört_01: "$#REF!.$J$155"
Name Mört_rekord: "$#REF!.$B$145"
Name Öring_01: "$#REF!.$J$269"
Name Röding_01: "$#REF!.$J$181"
Name Röding_rekord: "$#REF!.$B$169"
Name rPoints: #REF!
Name rPts: #REF!,#REF!,#REF!,#REF!,#REF!,#REF!,#REF!,#REF!,#REF!,#REF!,#REF!,#REF!,#REF!,#REF!,#REF!
Name Ruda_01: "$#REF!.$J$168"
Name Ruda_rekord: "$#REF!.$B$161"
Name Sarv_01: "$#REF!.$J$193"
Name Sarv_rekord: "$#REF!.$B$177"
Name Sik_01: "$#REF!.$J$206"
Name Sik_rekord: "$#REF!.$B$185"
Name Stäm_01: "$#REF!.$J$219"
Name Stäm_rekord: "$#REF!.$B$193"
Name Sutare_01: "$#REF!.$J$231"
Name Sutare_rekord: "$#REF!.$B$201"
Name Vimma_01: "$#REF!.$J$244"
Name Vimma_rekord: "$#REF!.$B$209"

Sheet Guide
A1: Step
A2: 1 | B2: Got to "Result of the day" | C2: e.g | D2: https://www.gps-speedsurfing.com/default.aspx?mnu=forum&forum=2&val=230014
A19: 2 | B19: mark data then Ctrl+ C
A41: 3 | B41: Go ot Resuts of the day tab and paste ("match destination format") copied date to the end of the table
A51: 4 | B51: Remove header row and add date in column B
A52: # | C52: Naam | D52: Avg | E52: Run | F52: 2 sec | G52: 500 | H52: Alpha
A53: 1 | B53: 45817 | C53: Peter Modéer | D53: 34.68 | E53: 35.17 | F53: 36.6 | G53: 33.52 | H53: 20.75
A54: 2 | B54: 45817 | C54: Anders Bjorkqvist | D54: 34.47 | E54: 35.26 | F54: 36.87 | G54: 30.38 | H54: 0
A55: 3 | B55: 45817 | C55: Kim Born | D55: 33.73 | E55: 34.46 | F55: 35.13 | G55: 28.18 | H55: 0
A56: 4 | B56: 45817 | C56: Jonas Bergström | D56: 33.62 | E56: 33.83 | F56: 34.74 | G56: 31.19 | H56: 0
A57: 5 | B57: 45817 | C57: Erik Larsson | D57: 32.88 | E57: 34.09 | F57: 34.8 | G57: 33.72 | H57: 0
A58: 6 | B58: 45817 | C58: Daniel E.A. Gustafsson | D58: 32.64 | E58: 33.52 | F58: 34.42 | G58: 29.72 | H58: 0
A59: 7 | B59: 45817 | C59: Per Högberg | D59: 32.07 | E59: 33.15 | F59: 34.3 | G59: 27.16 | H59: 16.62
A60: 8 | B60: 45817 | C60: Daniel Tobiasson | D60: 31.96 | E60: 33.65 | F60: 35.36 | G60: 25 | H60: 0
A61: 9 | B61: 45817 | C61: Rickard Fossum | D61: 30.72 | E61: 31.36 | F61: 33.41 | G61: 29.11 | H61: 20.22
A63: 5 | B63: Go to Resultat tab and add more rows above "Radical Ronald" if needed.
A85: 6 | B85: Add date in 1st row
A97: 7 | B97: Open Total tab and add date in 3rd row
A112: 8 | B112: Sort by Rank in Column A

Sheet Totalt
B1: King of the Fjord 2025 (5x10s)
D2: 1 | F2: 2 | H2: 3 | J2: 4 | L2: 5 | N2: 6 | P2: 7 | R2: 8 | T2: 9 | V2: 10 | X2: 11 | Z2: 12 | AB2: 13 | AD2: 14 | AF2: 15
A3: Rank | B3: Namn | C3: Score | D3: 45802 | F3: 45815 | H3: 45817 | J3: 45837
D4: Poäng | E4: Average | F4: Poäng | G4: Average | H4: Poäng | I4: Average | J4: Poäng | K4: Average | L4: Poäng | M4: Average | N4: Poäng | O4: Average | P4: Poäng | Q4: Average | R4: Poäng | S4: Average | T4: Poäng | U4: Average | V4: Poäng | W4: Average | X4: Poäng | Y4: Average | Z4: Poäng | AA4: Average | AB4: Poäng | AC4: Average | AD4: Poäng | AE4: Average | AF4: Poäng | AG4: Average
A5: =_xlfn.XLOOKUP($B5,Resultat!$D:$D,Resultat!$Z:$Z,-1,0) -> 1 | B5: Marcus Richardson | C5: =_xlfn.XLOOKUP($B5,Resultat!$D:$D,Resultat!$AA:$AA,-1,0) -> 1 | D5: =OFFSET(_xlfn.XLOOKUP($B5,Resultat!$D:$D,Resultat!$AL:$AL,-1,0),0,D$2-1) -> 1 | E5: =OFFSET(_xlfn.XLOOKUP($B5,Resultat!$D:$D,Resultat!$E:$E,-1,0),0,D$2-1) -> 34.75 | F5: =OFFSET(_xlfn.XLOOKUP($B5,Resultat!$D:$D,Resultat!$AL:$AL,-1,0),0,F$2-1) -> 0 | G5: =OFFSET(_xlfn.XLOOKUP($B5,Resultat!$D:$D,Resultat!$E:$E,-1,0),0,F$2-1) -> 0 | H5: =OFFSET(_xlfn.XLOOKUP($B5,Resultat!$D:$D,Resultat!$AL:$AL,-1,0),0,H$2-1) -> 0 | I5: =OFFSET(_xlfn.XLOOKUP($B5,Resultat!$D:$D,Resultat!$E:$E,-1,0),0,H$2-1) -> 0 | J5: =OFFSET(_xlfn.XLOOKUP($B5,Resultat!$D:$D,Resultat!$AL:$AL,-1,0),0,J$2-1) -> 0 | K5: =OFFSET(_xlfn.XLOOKUP($B5,Resultat!$D:$D,Resultat!$E:$E,-1,0),0,J$2-1) -> 0 | L5: =OFFSET(_xlfn.XLOOKUP($B5,Resultat!$D:$D,Resultat!$AL:$AL,-1,0),0,L$2-1) -> 0 | M5: =OFFSET(_xlfn.XLOOKUP($B5,Resultat!$D:$D,Resultat!$E:$E,-1,0),0,L$2-1) -> 0 | N5: =OFFSET(_xlfn.XLOOKUP($B5,Resultat!$D:$D,Resultat!$AL:$AL,-1,0),0,N$2-1) -> 0 | O5: =OFFSET(_xlfn.XLOOKUP($B5,Resultat!$D:$D,Resultat!$E:$E,-1,0),0,N$2-1) -> 0 | P5: =OFFSET(_xlfn.XLOOKUP($B5,Resultat!$D:$D,Resultat!$AL:$AL,-1,0),0,P$2-1) -> 0 | Q5: =OFFSET(_xlfn.XLOOKUP($B5,Resultat!$D:$D,Resultat!$E:$E,-1,0),0,P$2-1) -> 0 | R5: =OFFSET(_xlfn.XLOOKUP($B5,Resultat!$D:$D,Resultat!$AL:$AL,-1,0),0,R$2-1) -> 0 | S5: =OFFSET(_xlfn.XLOOKUP($B5,Resultat!$D:$D,Resultat!$E:$E,-1,0),0,R$2-1) -> 0 | T5: =OFFSET(_xlfn.XLOOKUP($B5,Resultat!$D:$D,Resultat!$AL:$AL,-1,0),0,T$2-1) -> 0 | U5: =OFFSET(_xlfn.XLOOKUP($B5,Resultat!$D:$D,Resultat!$E:$E,-1,0),0,T$2-1) -> 0 | V5: =OFFSET(_xlfn.XLOOKUP($B5,Resultat!$D:$D,Resultat!$AL:$AL,-1,0),0,V$2-1) -> 0 | W5: =OFFSET(_xlfn.XLOOKUP($B5,Resultat!$D:$D,Resultat!$E:$E,-1,0),0,V$2-1) -> 0 | X5: =OFFSET(_xlfn.XLOOKUP($B5,Resultat!$D:$D,Resultat!$AL:$AL,-1,0),0,X$2-1) -> 0 | Y5: =OFFSET(_xlfn.XLOOKUP($B5,Resultat!$D:$D,Resultat!$E:$E,-1,0),0,X$2-1) -> 0 | Z5: =OFFSET(_xlfn.XLOOKUP($B5,Resultat!$D:$D,Resultat!$AL:$AL,-1,0),0,Z$2-1) -> 0 | AA5: =OFFSET(_xlfn.XLOOKUP($B5,Resultat!$D:$D,Resultat!$E:$E,-1,0),0,Z$2-1) -> 0 | AB5: =OFFSET(_xlfn.XLOOKUP($B5,Resultat!$D:$D,Resultat!$AL:$AL,-1,0),0,AB$2-1) -> 0 | AC5: =OFFSET(_xlfn.XLOOKUP($B5,Resultat!$D:$D,Resultat!$E:$E,-1,0),0,AB$2-1) -> 0 | AD5: =OFFSET(_xlfn.XLOOKUP($B5,Resultat!$D:$D,Resultat!$AL:$AL,-1,0),0,AD$2-1) -> 0 | AE5: =OFFSET(_xlfn.XLOOKUP($B5,Resultat!$D:$D,Resultat!$E:$E,-1,0),0,AD$2-1) -> 0 | AF5: =OFFSET(_xlfn.XLOOKUP($B5,Resultat!$D:$D,Resultat!$AL:$AL,-1,0),0,AF$2-1) -> 0 | AG5: =OFFSET(_xlfn.XLOOKUP($B5,Resultat!$D:$D,Resultat!$E:$E,-1,0),0,AF$2-1) -> 0
A6: =_xlfn.XLOOKUP($B6,Resultat!$D:$D,Resultat!$Z:$Z,-1,0) -> 2 | B6: Jonas Bergström | C6: =_xlfn.XLOOKUP($B6,Resultat!$D:$D,Resultat!$AA:$AA,-1,0) -> 2 | D6: =OFFSET(_xlfn.XLOOKUP($B6,Resultat!$D:$D,Resultat!$AL:$AL,-1,0),0,D$2-1) -> 2 | E6: =OFFSET(_xlfn.XLOOKUP($B6,Resultat!$D:$D,Resultat!$E:$E,-1,0),0,D$2-1) -> 31.2 | F6: =OFFSET(_xlfn.XLOOKUP($B6,Resultat!$D:$D,Resultat!$AL:$AL,-1,0),0,F$2-1) -> 0 | G6: =OFFSET(_xlfn.XLOOKUP($B6,Resultat!$D:$D,Resultat!$E:$E,-1,0),0,F$2-1) -> 0 | H6: =OFFSET(_xlfn.XLOOKUP($B6,Resultat!$D:$D,Resultat!$AL:$AL,-1,0),0,H$2-1) -> 0 | I6: =OFFSET(_xlfn.XLOOKUP($B6,Resultat!$D:$D,Resultat!$E:$E,-1,0),0,H$2-1) -> 0 | J6: =OFFSET(_xlfn.XLOOKUP($B6,Resultat!$D:$D,Resultat!$AL:$AL,-1,0),0,J$2-1) -> 0 | K6: =OFFSET(_xlfn.XLOOKUP($B6,Resultat!$D:$D,Resultat!$E:$E,-1,0),0,J$2-1) -> 0 | L6: =OFFSET(_xlfn.XLOOKUP($B6,Resultat!$D:$D,Resultat!$AL:$AL,-1,0),0,L$2-1) -> 0 | M6: =OFFSET(_xlfn.XLOOKUP($B6,Resultat!$D:$D,Resultat!$E:$E,-1,0),0,L$2-1) -> 0 | N6: =OFFSET(_xlfn.XLOOKUP($B6,Resultat!$D:$D,Resultat!$AL:$AL,-1,0),0,N$2-1) -> 0 | O6: =OFFSET(_xlfn.XLOOKUP($B6,Resultat!$D:$D,Resultat!$E:$E,-1,0),0,N$2-1) -> 0 | P6: =OFFSET(_xlfn.XLOOKUP($B6,Resultat!$D:$D,Resultat!$AL:$AL,-1,0),0,P$2-1) -> 0 | Q6: =OFFSET(_xlfn.XLOOKUP($B6,Resultat!$D:$D,Resultat!$E:$E,-1,0),0,P$2-1) -> 0 | R6: =OFFSET(_xlfn.XLOOKUP($B6,Resultat!$D:$D,Resultat!$AL:$AL,-1,0),0,R$2-1) -> 0 | S6: =OFFSET(_xlfn.XLOOKUP($B6,Resultat!$D:$D,Resultat!$E:$E,-1,0),0,R$2-1) -> 0 | T6: =OFFSET(_xlfn.XLOOKUP($B6,Resultat!$D:$D,Resultat!$AL:$AL,-1,0),0,T$2-1) -> 0 | U6: =OFFSET(_xlfn.XLOOKUP($B6,Resultat!$D:$D,Resultat!$E:$E,-1,0),0,T$2-1) -> 0 | V6: =OFFSET(_xlfn.XLOOKUP($B6,Resultat!$D:$D,Resultat!$AL:$AL,-1,0),0,V$2-1) -> 0 | W6: =OFFSET(_xlfn.XLOOKUP($B6,Resultat!$D:$D,Resultat!$E:$E,-1,0),0,V$2-1) -> 0 | X6: =OFFSET(_xlfn.XLOOKUP($B6,Resultat!$D:$D,Resultat!$AL:$AL,-1,0),0,X$2-1) -> 0 | Y6: =OFFSET(_xlfn.XLOOKUP($B6,Resultat!$D:$D,Resultat!$E:$E,-1,0),0,X$2-1) -> 0 | Z6: =OFFSET(_xlfn.XLOOKUP($B6,Resultat!$D:$D,Resultat!$AL:$AL,-1,0),0,Z$2-1) -> 0 | AA6: =OFFSET(_xlfn.XLOOKUP($B6,Resultat!$D:$D,Resultat!$E:$E,-1,0),0,Z$2-1) -> 0 | AB6: =OFFSET(_xlfn.XLOOKUP($B6,Resultat!$D:$D,Resultat!$AL:$AL,-1,0),0,AB$2-1) -> 0 | AC6: =OFFSET(_xlfn.XLOOKUP($B6,Resultat!$D:$D,Resultat!$E:$E,-1,0),0,AB$2-1) -> 0 | AD6: =OFFSET(_xlfn.XLOOKUP($B6,Resultat!$D:$D,Resultat!$AL:$AL,-1,0),0,AD$2-1) -> 0 | AE6: =OFFSET(_xlfn.XLOOKUP($B6,Resultat!$D:$D,Resultat!$E:$E,-1,0),0,AD$2-1) -> 0 | AF6: =OFFSET(_xlfn.XLOOKUP($B6,Resultat!$D:$D,Resultat!$AL:$AL,-1,0),0,AF$2-1) -> 0 | AG6: =OFFSET(_xlfn.XLOOKUP($B6,Resultat!$D:$D,Resultat!$E:$E,-1,0),0,AF$2-1) -> 0
A7: =_xlfn.XLOOKUP($B7,Resultat!$D:$D,Resultat!$Z:$Z,-1,0) -> 3 | B7: Per Högberg | C7: =_xlfn.XLOOKUP($B7,Resultat!$D:$D,Resultat!$AA:$AA,-1,0) -> 3 | D7: =OFFSET(_xlfn.XLOOKUP($B7,Resultat!$D:$D,Resultat!$AL:$AL,-1,0),0,D$2-1) -> 3 | E7: =OFFSET(_xlfn.XLOOKUP($B7,Resultat!$D:$D,Resultat!$E:$E,-1,0),0,D$2-1) -> 31.1 | F7: =OFFSET(_xlfn.XLOOKUP($B7,Resultat!$D:$D,Resultat!$AL:$AL,-1,0),0,F$2-1) -> 0 | G7: =OFFSET(_xlfn.XLOOKUP($B7,Resultat!$D:$D,Resultat!$E:$E,-1,0),0,F$2-1) -> 0 | H7: =OFFSET(_xlfn.XLOOKUP($B7,Resultat!$D:$D,Resultat!$AL:$AL,-1,0),0,H$2-1) -> 0 | I7: =OFFSET(_xlfn.XLOOKUP($B7,Resultat!$D:$D,Resultat!$E:$E,-1,0),0,H$2-1) -> 0 | J7: =OFFSET(_xlfn.XLOOKUP($B7,Resultat!$D:$D,Resultat!$AL:$AL,-1,0),0,J$2-1) -> 0 | K7: =OFFSET(_xlfn.XLOOKUP($B7,Resultat!$D:$D,Resultat!$E:$E,-1,0),0,J$2-1) -> 0 | L7: =OFFSET(_xlfn.XLOOKUP($B7,Resultat!$D:$D,Resultat!$AL:$AL,-1,0),0,L$2-1) -> 0 | M7: =OFFSET(_xlfn.XLOOKUP($B7,Resultat!$D:$D,Resultat!$E:$E,-1,0),0,L$2-1) -> 0 | N7: =OFFSET(_xlfn.XLOOKUP($B7,Resultat!$D:$D,Resultat!$AL:$AL,-1,0),0,N$2-1) -> 0 | O7: =OFFSET(_xlfn.XLOOKUP($B7,Resultat!$D:$D,Resultat!$E:$E,-1,0),0,N$2-1) -> 0 | P7: =OFFSET(_xlfn.XLOOKUP($B7,Resultat!$D:$D,Resultat!$AL:$AL,-1,0),0,P$2-1) -> 0 | Q7: =OFFSET(_xlfn.XLOOKUP($B7,Resultat!$D:$D,Resultat!$E:$E,-1,0),0,P$2-1) -> 0 | R7: =OFFSET(_xlfn.XLOOKUP($B7,Resultat!$D:$D,Resultat!$AL:$AL,-1,0),0,R$2-1) -> 0 | S7: =OFFSET(_xlfn.XLOOKUP($B7,Resultat!$D:$D,Resultat!$E:$E,-1,0),0,R$2-1) -> 0 | T7: =OFFSET(_xlfn.XLOOKUP($B7,Resultat!$D:$D,Resultat!$AL:$AL,-1,0),0,T$2-1) -> 0 | U7: =OFFSET(_xlfn.XLOOKUP($B7,Resultat!$D:$D,Resultat!$E:$E,-1,0),0,T$2-1) -> 0 | V7: =OFFSET(_xlfn.XLOOKUP($B7,Resultat!$D:$D,Resultat!$AL:$AL,-1,0),0,V$2-1) -> 0 | W7: =OFFSET(_xlfn.XLOOKUP($B7,Resultat!$D:$D,Resultat!$E:$E,-1,0),0,V$2-1) -> 0 | X7: =OFFSET(_xlfn.XLOOKUP($B7,Resultat!$D:$D,Resultat!$AL:$AL,-1,0),0,X$2-1) -> 0 | Y7: =OFFSET(_xlfn.XLOOKUP($B7,Resultat!$D:$D,Resultat!$E:$E,-1,0),0,X$2-1) -> 0 | Z7: =OFFSET(_xlfn.XLOOKUP($B7,Resultat!$D:$D,Resultat!$AL:$AL,-1,0),0,Z$2-1) -> 0 | AA7: =OFFSET(_xlfn.XLOOKUP($B7,Resultat!$D:$D,Resultat!$E:$E,-1,0),0,Z$2-1) -> 0 | AB7: =OFFSET(_xlfn.XLOOKUP($B7,Resultat!$D:$D,Resultat!$AL:$AL,-1,0),0,AB$2-1) -> 0 | AC7: =OFFSET(_xlfn.XLOOKUP($B7,Resultat!$D:$D,Resultat!$E:$E,-1,0),0,AB$2-1) -> 0 | AD7: =OFFSET(_xlfn.XLOOKUP($B7,Resultat!$D:$D,Resultat!$AL:$AL,-1,0),0,AD$2-1) -> 0 | AE7: =OFFSET(_xlfn.XLOOKUP($B7,Resultat!$D:$D,Resultat!$E:$E,-1,0),0,AD$2-1) -> 0 | AF7: =OFFSET(_xlfn.XLOOKUP($B7,Resultat!$D:$D,Resultat!$AL:$AL,-1,0),0,AF$2-1) -> 0 | AG7: =OFFSET(_xlfn.XLOOKUP($B7,Resultat!$D:$D,Resultat!$E:$E,-1,0),0,AF$2-1) -> 0
A8: =_xlfn.XLOOKUP($B8,Resultat!$D:$D,Resultat!$Z:$Z,-1,0) -> 4 | B8: Joko Mrnjavac | C8: =_xlfn.XLOOKUP($B8,Resultat!$D:$D,Resultat!$AA:$AA,-1,0) -> 4 | D8: =OFFSET(_xlfn.XLOOKUP($B8,Resultat!$D:$D,Resultat!$AL:$AL,-1,0),0,D$2-1) -> 4 | E8: =OFFSET(_xlfn.XLOOKUP($B8,Resultat!$D:$D,Resultat!$E:$E,-1,0),0,D$2-1) -> 31.01 | F8: =OFFSET(_xlfn.XLOOKUP($B8,Resultat!$D:$D,Resultat!$AL:$AL,-1,0),0,F$2-1) -> 0 | G8: =OFFSET(_xlfn.XLOOKUP($B8,Resultat!$D:$D,Resultat!$E:$E,-1,0),0,F$2-1) -> 0 | H8: =OFFSET(_xlfn.XLOOKUP($B8,Resultat!$D:$D,Resultat!$AL:$AL,-1,0),0,H$2-1) -> 0 | I8: =OFFSET(_xlfn.XLOOKUP($B8,Resultat!$D:$D,Resultat!$E:$E,-1,0),0,H$2-1) -> 0 | J8: =OFFSET(_xlfn.XLOOKUP($B8,Resultat!$D:$D,Resultat!$AL:$AL,-1,0),0,J$2-1) -> 0 | K8: =OFFSET(_xlfn.XLOOKUP($B8,Resultat!$D:$D,Resultat!$E:$E,-1,0),0,J$2-1) -> 0 | L8: =OFFSET(_xlfn.XLOOKUP($B8,Resultat!$D:$D,Resultat!$AL:$AL,-1,0),0,L$2-1) -> 0 | M8: =OFFSET(_xlfn.XLOOKUP($B8,Resultat!$D:$D,Resultat!$E:$E,-1,0),0,L$2-1) -> 0 | N8: =OFFSET(_xlfn.XLOOKUP($B8,Resultat!$D:$D,Resultat!$AL:$AL,-1,0),0,N$2-1) -> 0 | O8: =OFFSET(_xlfn.XLOOKUP($B8,Resultat!$D:$D,Resultat!$E:$E,-1,0),0,N$2-1) -> 0 | P8: =OFFSET(_xlfn.XLOOKUP($B8,Resultat!$D:$D,Resultat!$AL:$AL,-1,0),0,P$2-1) -> 0 | Q8: =OFFSET(_xlfn.XLOOKUP($B8,Resultat!$D:$D,Resultat!$E:$E,-1,0),0,P$2-1) -> 0 | R8: =OFFSET(_xlfn.XLOOKUP($B8,Resultat!$D:$D,Resultat!$AL:$AL,-1,0),0,R$2-1) -> 0 | S8: =OFFSET(_xlfn.XLOOKUP($B8,Resultat!$D:$D,Resultat!$E:$E,-1,0),0,R$2-1) -> 0 | T8: =OFFSET(_xlfn.XLOOKUP($B8,Resultat!$D:$D,Resultat!$AL:$AL,-1,0),0,T$2-1) -> 0 | U8: =OFFSET(_xlfn.XLOOKUP($B8,Resultat!$D:$D,Resultat!$E:$E,-1,0),0,T$2-1) -> 0 | V8: =OFFSET(_xlfn.XLOOKUP($B8,Resultat!$D:$D,Resultat!$AL:$AL,-1,0),0,V$2-1) -> 0 | W8: =OFFSET(_xlfn.XLOOKUP($B8,Resultat!$D:$D,Resultat!$E:$E,-1,0),0,V$2-1) -> 0 | X8: =OFFSET(_xlfn.XLOOKUP($B8,Resultat!$D:$D,Resultat!$AL:$AL,-1,0),0,X$2-1) -> 0 | Y8: =OFFSET(_xlfn.XLOOKUP($B8,Resultat!$D:$D,Resultat!$E:$E,-1,0),0,X$2-1) -> 0 | Z8: =OFFSET(_xlfn.XLOOKUP($B8,Resultat!$D:$D,Resultat!$AL:$AL,-1,0),0,Z$2-1) -> 0 | AA8: =OFFSET(_xlfn.XLOOKUP($B8,Resultat!$D:$D,Resultat!$E:$E,-1,0),0,Z$2-1) -> 0 | AB8: =OFFSET(_xlfn.XLOOKUP($B8,Resultat!$D:$D,Resultat!$AL:$AL,-1,0),0,AB$2-1) -> 0 | AC8: =OFFSET(_xlfn.XLOOKUP($B8,Resultat!$D:$D,Resultat!$E:$E,-1,0),0,AB$2-1) -> 0 | AD8: =OFFSET(_xlfn.XLOOKUP($B8,Resultat!$D:$D,Resultat!$AL:$AL,-1,0),0,AD$2-1) -> 0 | AE8: =OFFSET(_xlfn.XLOOKUP($B8,Resultat!$D:$D,Resultat!$E:$E,-1,0),0,AD$2-1) -> 0 | AF8: =OFFSET(_xlfn.XLOOKUP($B8,Resultat!$D:$D,Resultat!$AL:$AL,-1,0),0,AF$2-1) -> 0 | AG8: =OFFSET(_xlfn.XLOOKUP($B8,Resultat!$D:$D,Resultat!$E:$E,-1,0),0,AF$2-1) -> 0
A9: =_xlfn.XLOOKUP($B9,Resultat!$D:$D,Resultat!$Z:$Z,-1,0) -> 5 | B9: Rickard Fossum | C9: =_xlfn.XLOOKUP($B9,Resultat!$D:$D,Resultat!$AA:$AA,-1,0) -> 5 | D9: =OFFSET(_xlfn.XLOOKUP($B9,Resultat!$D:$D,Resultat!$AL:$AL,-1,0),0,D$2-1) -> 5 | E9: =OFFSET(_xlfn.XLOOKUP($B9,Resultat!$D:$D,Resultat!$E:$E,-1,0),0,D$2-1) -> 30.05 | F9: =OFFSET(_xlfn.XLOOKUP($B9,Resultat!$D:$D,Resultat!$AL:$AL,-1,0),0,F$2-1) -> 0 | G9: =OFFSET(_xlfn.XLOOKUP($B9,Resultat!$D:$D,Resultat!$E:$E,-1,0),0,F$2-1) -> 0 | H9: =OFFSET(_xlfn.XLOOKUP($B9,Resultat!$D:$D,Resultat!$AL:$AL,-1,0),0,H$2-1) -> 0 | I9: =OFFSET(_xlfn.XLOOKUP($B9,Resultat!$D:$D,Resultat!$E:$E,-1,0),0,H$2-1) -> 0 | J9: =OFFSET(_xlfn.XLOOKUP($B9,Resultat!$D:$D,Resultat!$AL:$AL,-1,0),0,J$2-1) -> 0 | K9: =OFFSET(_xlfn.XLOOKUP($B9,Resultat!$D:$D,Resultat!$E:$E,-1,0),0,J$2-1) -> 0 | L9: =OFFSET(_xlfn.XLOOKUP($B9,Resultat!$D:$D,Resultat!$AL:$AL,-1,0),0,L$2-1) -> 0 | M9: =OFFSET(_xlfn.XLOOKUP($B9,Resultat!$D:$D,Resultat!$E:$E,-1,0),0,L$2-1) -> 0 | N9: =OFFSET(_xlfn.XLOOKUP($B9,Resultat!$D:$D,Resultat!$AL:$AL,-1,0),0,N$2-1) -> 0 | O9: =OFFSET(_xlfn.XLOOKUP($B9,Resultat!$D:$D,Resultat!$E:$E,-1,0),0,N$2-1) -> 0 | P9: =OFFSET(_xlfn.XLOOKUP($B9,Resultat!$D:$D,Resultat!$AL:$AL,-1,0),0,P$2-1) -> 0 | Q9: =OFFSET(_xlfn.XLOOKUP($B9,Resultat!$D:$D,Resultat!$E:$E,-1,0),0,P$2-1) -> 0 | R9: =OFFSET(_xlfn.XLOOKUP($B9,Resultat!$D:$D,Resultat!$AL:$AL,-1,0),0,R$2-1) -> 0 | S9: =OFFSET(_xlfn.XLOOKUP($B9,Resultat!$D:$D,Resultat!$E:$E,-1,0),0,R$2-1) -> 0 | T9: =OFFSET(_xlfn.XLOOKUP($B9,Resultat!$D:$D,Resultat!$AL:$AL,-1,0),0,T$2-1) -> 0 | U9: =OFFSET(_xlfn.XLOOKUP($B9,Resultat!$D:$D,Resultat!$E:$E,-1,0),0,T$2-1) -> 0 | V9: =OFFSET(_xlfn.XLOOKUP($B9,Resultat!$D:$D,Resultat!$AL:$AL,-1,0),0,V$2-1) -> 0 | W9: =OFFSET(_xlfn.XLOOKUP($B9,Resultat!$D:$D,Resultat!$E:$E,-1,0),0,V$2-1) -> 0 | X9: =OFFSET(_xlfn.XLOOKUP($B9,Resultat!$D:$D,Resultat!$AL:$AL,-1,0),0,X$2-1) -> 0 | Y9: =OFFSET(_xlfn.XLOOKUP($B9,Resultat!$D:$D,Resultat!$E:$E,-1,0),0,X$2-1) -> 0 | Z9: =OFFSET(_xlfn.XLOOKUP($B9,Resultat!$D:$D,Resultat!$AL:$AL,-1,0),0,Z$2-1) -> 0 | AA9: =OFFSET(_xlfn.XLOOKUP($B9,Resultat!$D:$D,Resultat!$E:$E,-1,0),0,Z$2-1) -> 0 | AB9: =OFFSET(_xlfn.XLOOKUP($B9,Resultat!$D:$D,Resultat!$AL:$AL,-1,0),0,AB$2-1) -> 0 | AC9: =OFFSET(_xlfn.XLOOKUP($B9,Resultat!$D:$D,Resultat!$E:$E,-1,0),0,AB$2-1) -> 0 | AD9: =OFFSET(_xlfn.XLOOKUP($B9,Resultat!$D:$D,Resultat!$AL:$AL,-1,0),0,AD$2-1) -> 0 | AE9: =OFFSET(_xlfn.XLOOKUP($B9,Resultat!$D:$D,Resultat!$E:$E,-1,0),0,AD$2-1) -> 0 | AF9: =OFFSET(_xlfn.XLOOKUP($B9,Resultat!$D:$D,Resultat!$AL:$AL,-1,0),0,AF$2-1) -> 0 | AG9: =OFFSET(_xlfn.XLOOKUP($B9,Resultat!$D:$D,Resultat!$E:$E,-1,0),0,AF$2-1) -> 0
A10: =_xlfn.XLOOKUP($B10,Resultat!$D:$D,Resultat!$Z:$Z,-1,0) -> 6 | B10: Morgan Ruudh | C10: =_xlfn.XLOOKUP($B10,Resultat!$D:$D,Resultat!$AA:$AA,-1,0) -> 6 | D10: =OFFSET(_xlfn.XLOOKUP($B10,Resultat!$D:$D,Resultat!$AL:$AL,-1,0),0,D$2-1) -> 6 | E10: =OFFSET(_xlfn.XLOOKUP($B10,Resultat!$D:$D,Resultat!$E:$E,-1,0),0,D$2-1) -> 29.71 | F10: =OFFSET(_xlfn.XLOOKUP($B10,Resultat!$D:$D,Resultat!$AL:$AL,-1,0),0,F$2-1) -> 0 | G10: =OFFSET(_xlfn.XLOOKUP($B10,Resultat!$D:$D,Resultat!$E:$E,-1,0),0,F$2-1) -> 0 | H10: =OFFSET(_xlfn.XLOOKUP($B10,Resultat!$D:$D,Resultat!$AL:$AL,-1,0),0,H$2-1) -> 0 | I10: =OFFSET(_xlfn.XLOOKUP($B10,Resultat!$D:$D,Resultat!$E:$E,-1,0),0,H$2-1) -> 0 | J10: =OFFSET(_xlfn.XLOOKUP($B10,Resultat!$D:$D,Resultat!$AL:$AL,-1,0),0,J$2-1) -> 0 | K10: =OFFSET(_xlfn.XLOOKUP($B10,Resultat!$D:$D,Resultat!$E:$E,-1,0),0,J$2-1) -> 0 | L10: =OFFSET(_xlfn.XLOOKUP($B10,Resultat!$D:$D,Resultat!$AL:$AL,-1,0),0,L$2-1) -> 0 | M10: =OFFSET(_xlfn.XLOOKUP($B10,Resultat!$D:$D,Resultat!$E:$E,-1,0),0,L$2-1) -> 0 | N10: =OFFSET(_xlfn.XLOOKUP($B10,Resultat!$D:$D,Resultat!$AL:$AL,-1,0),0,N$2-1) -> 0 | O10: =OFFSET(_xlfn.XLOOKUP($B10,Resultat!$D:$D,Resultat!$E:$E,-1,0),0,N$2-1) -> 0 | P10: =OFFSET(_xlfn.XLOOKUP($B10,Resultat!$D:$D,Resultat!$AL:$AL,-1,0),0,P$2-1) -> 0 | Q10: =OFFSET(_xlfn.XLOOKUP($B10,Resultat!$D:$D,Resultat!$E:$E,-1,0),0,P$2-1) -> 0 | R10: =OFFSET(_xlfn.XLOOKUP($B10,Resultat!$D:$D,Resultat!$AL:$AL,-1,0),0,R$2-1) -> 0 | S10: =OFFSET(_xlfn.XLOOKUP($B10,Resultat!$D:$D,Resultat!$E:$E,-1,0),0,R$2-1) -> 0 | T10: =OFFSET(_xlfn.XLOOKUP($B10,Resultat!$D:$D,Resultat!$AL:$AL,-1,0),0,T$2-1) -> 0 | U10: =OFFSET(_xlfn.XLOOKUP($B10,Resultat!$D:$D,Resultat!$E:$E,-1,0),0,T$2-1) -> 0 | V10: =OFFSET(_xlfn.XLOOKUP($B10,Resultat!$D:$D,Resultat!$AL:$AL,-1,0),0,V$2-1) -> 0 | W10: =OFFSET(_xlfn.XLOOKUP($B10,Resultat!$D:$D,Resultat!$E:$E,-1,0),0,V$2-1) -> 0 | X10: =OFFSET(_xlfn.XLOOKUP($B10,Resultat!$D:$D,Resultat!$AL:$AL,-1,0),0,X$2-1) -> 0 | Y10: =OFFSET(_xlfn.XLOOKUP($B10,Resultat!$D:$D,Resultat!$E:$E,-1,0),0,X$2-1) -> 0 | Z10: =OFFSET(_xlfn.XLOOKUP($B10,Resultat!$D:$D,Resultat!$AL:$AL,-1,0),0,Z$2-1) -> 0 | AA10: =OFFSET(_xlfn.XLOOKUP($B10,Resultat!$D:$D,Resultat!$E:$E,-1,0),0,Z$2-1) -> 0 | AB10: =OFFSET(_xlfn.XLOOKUP($B10,Resultat!$D:$D,Resultat!$AL:$AL,-1,0),0,AB$2-1) -> 0 | AC10: =OFFSET(_xlfn.XLOOKUP($B10,Resultat!$D:$D,Resultat!$E:$E,-1,0),0,AB$2-1) -> 0 | AD10: =OFFSET(_xlfn.XLOOKUP($B10,Resultat!$D:$D,Resultat!$AL:$AL,-1,0),0,AD$2-1) -> 0 | AE10: =OFFSET(_xlfn.XLOOKUP($B10,Resultat!$D:$D,Resultat!$E:$E,-1,0),0,AD$2-1) -> 0 | AF10: =OFFSET(_xlfn.XLOOKUP($B10,Resultat!$D:$D,Resultat!$AL:$AL,-1,0),0,AF$2-1) -> 0 | AG10: =OFFSET(_xlfn.XLOOKUP($B10,Resultat!$D:$D,Resultat!$E:$E,-1,0),0,AF$2-1) -> 0
A11: =_xlfn.XLOOKUP($B11,Resultat!$D:$D,Resultat!$Z:$Z,-1,0) -> 7 | B11: Jesper Kropp Axelsson | C11: =_xlfn.XLOOKUP($B11,Resultat!$D:$D,Resultat!$AA:$AA,-1,0) -> 7 | D11: =OFFSET(_xlfn.XLOOKUP($B11,Resultat!$D:$D,Resultat!$AL:$AL,-1,0),0,D$2-1) -> 7 | E11: =OFFSET(_xlfn.XLOOKUP($B11,Resultat!$D:$D,Resultat!$E:$E,-1,0),0,D$2-1) -> 29.7 | F11: =OFFSET(_xlfn.XLOOKUP($B11,Resultat!$D:$D,Resultat!$AL:$AL,-1,0),0,F$2-1) -> 0 | G11: =OFFSET(_xlfn.XLOOKUP($B11,Resultat!$D:$D,Resultat!$E:$E,-1,0),0,F$2-1) -> 0 | H11: =OFFSET(_xlfn.XLOOKUP($B11,Resultat!$D:$D,Resultat!$AL:$AL,-1,0),0,H$2-1) -> 0 | I11: =OFFSET(_xlfn.XLOOKUP($B11,Resultat!$D:$D,Resultat!$E:$E,-1,0),0,H$2-1) -> 0 | J11: =OFFSET(_xlfn.XLOOKUP($B11,Resultat!$D:$D,Resultat!$AL:$AL,-1,0),0,J$2-1) -> 0 | K11: =OFFSET(_xlfn.XLOOKUP($B11,Resultat!$D:$D,Resultat!$E:$E,-1,0),0,J$2-1) -> 0 | L11: =OFFSET(_xlfn.XLOOKUP($B11,Resultat!$D:$D,Resultat!$AL:$AL,-1,0),0,L$2-1) -> 0 | M11: =OFFSET(_xlfn.XLOOKUP($B11,Resultat!$D:$D,Resultat!$E:$E,-1,0),0,L$2-1) -> 0 | N11: =OFFSET(_xlfn.XLOOKUP($B11,Resultat!$D:$D,Resultat!$AL:$AL,-1,0),0,N$2-1) -> 0 | O11: =OFFSET(_xlfn.XLOOKUP($B11,Resultat!$D:$D,Resultat!$E:$E,-1,0),0,N$2-1) -> 0 | P11: =OFFSET(_xlfn.XLOOKUP($B11,Resultat!$D:$D,Resultat!$AL:$AL,-1,0),0,P$2-1) -> 0 | Q11: =OFFSET(_xlfn.XLOOKUP($B11,Resultat!$D:$D,Resultat!$E:$E,-1,0),0,P$2-1) -> 0 | R11: =OFFSET(_xlfn.XLOOKUP($B11,Resultat!$D:$D,Resultat!$AL:$AL,-1,0),0,R$2-1) -> 0 | S11: =OFFSET(_xlfn.XLOOKUP($B11,Resultat!$D:$D,Resultat!$E:$E,-1,0),0,R$2-1) -> 0 | T11: =OFFSET(_xlfn.XLOOKUP($B11,Resultat!$D:$D,Resultat!$AL:$AL,-1,0),0,T$2-1) -> 0 | U11: =OFFSET(_xlfn.XLOOKUP($B11,Resultat!$D:$D,Resultat!$E:$E,-1,0),0,T$2-1) -> 0 | V11: =OFFSET(_xlfn.XLOOKUP($B11,Resultat!$D:$D,Resultat!$AL:$AL,-1,0),0,V$2-1) -> 0 | W11: =OFFSET(_xlfn.XLOOKUP($B11,Resultat!$D:$D,Resultat!$E:$E,-1,0),0,V$2-1) -> 0 | X11: =OFFSET(_xlfn.XLOOKUP($B11,Resultat!$D:$D,Resultat!$AL:$AL,-1,0),0,X$2-1) -> 0 | Y11: =OFFSET(_xlfn.XLOOKUP($B11,Resultat!$D:$D,Resultat!$E:$E,-1,0),0,X$2-1) -> 0 | Z11: =OFFSET(_xlfn.XLOOKUP($B11,Resultat!$D:$D,Resultat!$AL:$AL,-1,0),0,Z$2-1) -> 0 | AA11: =OFFSET(_xlfn.XLOOKUP($B11,Resultat!$D:$D,Resultat!$E:$E,-1,0),0,Z$2-1) -> 0 | AB11: =OFFSET(_xlfn.XLOOKUP($B11,Resultat!$D:$D,Resultat!$AL:$AL,-1,0),0,AB$2-1) -> 0 | AC11: =OFFSET(_xlfn.XLOOKUP($B11,Resultat!$D:$D,Resultat!$E:$E,-1,0),0,AB$2-1) -> 0 | AD11: =OFFSET(_xlfn.XLOOKUP($B11,Resultat!$D:$D,Resultat!$AL:$AL,-1,0),0,AD$2-1) -> 0 | AE11: =OFFSET(_xlfn.XLOOKUP($B11,Resultat!$D:$D,Resultat!$E:$E,-1,0),0,AD$2-1) -> 0 | AF11: =OFFSET(_xlfn.XLOOKUP($B11,Resultat!$D:$D,Resultat!$AL:$AL,-1,0),0,AF$2-1) -> 0 | AG11: =OFFSET(_xlfn.XLOOKUP($B11,Resultat!$D:$D,Resultat!$E:$E,-1,0),0,AF$2-1) -> 0
A12: =_xlfn.XLOOKUP($B12,Resultat!$D:$D,Resultat!$Z:$Z,-1,0) -> 8 | B12: Mats Moren | C12: =_xlfn.XLOOKUP($B12,Resultat!$D:$D,Resultat!$AA:$AA,-1,0) -> 8 | D12: =OFFSET(_xlfn.XLOOKUP($B12,Resultat!$D:$D,Resultat!$AL:$AL,-1,0),0,D$2-1) -> 8 | E12: =OFFSET(_xlfn.XLOOKUP($B12,Resultat!$D:$D,Resultat!$E:$E,-1,0),0,D$2-1) -> 29.41 | F12: =OFFSET(_xlfn.XLOOKUP($B12,Resultat!$D:$D,Resultat!$AL:$AL,-1,0),0,F$2-1) -> 0 | G12: =OFFSET(_xlfn.XLOOKUP($B12,Resultat!$D:$D,Resultat!$E:$E,-1,0),0,F$2-1) -> 0 | H12: =OFFSET(_xlfn.XLOOKUP($B12,Resultat!$D:$D,Resultat!$AL:$AL,-1,0),0,H$2-1) -> 0 | I12: =OFFSET(_xlfn.XLOOKUP($B12,Resultat!$D:$D,Resultat!$E:$E,-1,0),0,H$2-1) -> 0 | J12: =OFFSET(_xlfn.XLOOKUP($B12,Resultat!$D:$D,Resultat!$AL:$AL,-1,0),0,J$2-1) -> 0 | K12: =OFFSET(_xlfn.XLOOKUP($B12,Resultat!$D:$D,Resultat!$E:$E,-1,0),0,J$2-1) -> 0 | L12: =OFFSET(_xlfn.XLOOKUP($B12,Resultat!$D:$D,Resultat!$AL:$AL,-1,0),0,L$2-1) -> 0 | M12: =OFFSET(_xlfn.XLOOKUP($B12,Resultat!$D:$D,Resultat!$E:$E,-1,0),0,L$2-1) -> 0 | N12: =OFFSET(_xlfn.XLOOKUP($B12,Resultat!$D:$D,Resultat!$AL:$AL,-1,0),0,N$2-1) -> 0 | O12: =OFFSET(_xlfn.XLOOKUP($B12,Resultat!$D:$D,Resultat!$E:$E,-1,0),0,N$2-1) -> 0 | P12: =OFFSET(_xlfn.XLOOKUP($B12,Resultat!$D:$D,Resultat!$AL:$AL,-1,0),0,P$2-1) -> 0 | Q12: =OFFSET(_xlfn.XLOOKUP($B12,Resultat!$D:$D,Resultat!$E:$E,-1,0),0,P$2-1) -> 0 | R12: =OFFSET(_xlfn.XLOOKUP($B12,Resultat!$D:$D,Resultat!$AL:$AL,-1,0),0,R$2-1) -> 0 | S12: =OFFSET(_xlfn.XLOOKUP($B12,Resultat!$D:$D,Resultat!$E:$E,-1,0),0,R$2-1) -> 0 | T12: =OFFSET(_xlfn.XLOOKUP($B12,Resultat!$D:$D,Resultat!$AL:$AL,-1,0),0,T$2-1) -> 0 | U12: =OFFSET(_xlfn.XLOOKUP($B12,Resultat!$D:$D,Resultat!$E:$E,-1,0),0,T$2-1) -> 0 | V12: =OFFSET(_xlfn.XLOOKUP($B12,Resultat!$D:$D,Resultat!$AL:$AL,-1,0),0,V$2-1) -> 0 | W12: =OFFSET(_xlfn.XLOOKUP($B12,Resultat!$D:$D,Resultat!$E:$E,-1,0),0,V$2-1) -> 0 | X12: =OFFSET(_xlfn.XLOOKUP($B12,Resultat!$D:$D,Resultat!$AL:$AL,-1,0),0,X$2-1) -> 0 | Y12: =OFFSET(_xlfn.XLOOKUP($B12,Resultat!$D:$D,Resultat!$E:$E,-1,0),0,X$2-1) -> 0 | Z12: =OFFSET(_xlfn.XLOOKUP($B12,Resultat!$D:$D,Resultat!$AL:$AL,-1,0),0,Z$2-1) -> 0 | AA12: =OFFSET(_xlfn.XLOOKUP($B12,Resultat!$D:$D,Resultat!$E:$E,-1,0),0,Z$2-1) -> 0 | AB12: =OFFSET(_xlfn.XLOOKUP($B12,Resultat!$D:$D,Resultat!$AL:$AL,-1,0),0,AB$2-1) -> 0 | AC12: =OFFSET(_xlfn.XLOOKUP($B12,Resultat!$D:$D,Resultat!$E:$E,-1,0),0,AB$2-1) -> 0 | AD12: =OFFSET(_xlfn.XLOOKUP($B12,Resultat!$D:$D,Resultat!$AL:$AL,-1,0),0,AD$2-1) -> 0 | AE12: =OFFSET(_xlfn.XLOOKUP($B12,Resultat!$D:$D,Resultat!$E:$E,-1,0),0,AD$2-1) -> 0 | AF12: =OFFSET(_xlfn.XLOOKUP($B12,Resultat!$D:$D,Resultat!$AL:$AL,-1,0),0,AF$2-1) -> 0 | AG12: =OFFSET(_xlfn.XLOOKUP($B12,Resultat!$D:$D,Resultat!$E:$E,-1,0),0,AF$2-1) -> 0
A13: =_xlfn.XLOOKUP($B13,Resultat!$D:$D,Resultat!$Z:$Z,-1,0) -> 9 | B13: François Pettorelli | C13: =_xlfn.XLOOKUP($B13,Resultat!$D:$D,Resultat!$AA:$AA,-1,0) -> 9 | D13: =OFFSET(_xlfn.XLOOKUP($B13,Resultat!$D:$D,Resultat!$AL:$AL,-1,0),0,D$2-1) -> 9 | E13: =OFFSET(_xlfn.XLOOKUP($B13,Resultat!$D:$D,Resultat!$E:$E,-1,0),0,D$2-1) -> 29.12 | F13: =OFFSET(_xlfn.XLOOKUP($B13,Resultat!$D:$D,Resultat!$AL:$AL,-1,0),0,F$2-1) -> 0 | G13: =OFFSET(_xlfn.XLOOKUP($B13,Resultat!$D:$D,Resultat!$E:$E,-1,0),0,F$2-1) -> 0 | H13: =OFFSET(_xlfn.XLOOKUP($B13,Resultat!$D:$D,Resultat!$AL:$AL,-1,0),0,H$2-1) -> 0 | I13: =OFFSET(_xlfn.XLOOKUP($B13,Resultat!$D:$D,Resultat!$E:$E,-1,0),0,H$2-1) -> 0 | J13: =OFFSET(_xlfn.XLOOKUP($B13,Resultat!$D:$D,Resultat!$AL:$AL,-1,0),0,J$2-1) -> 0 | K13: =OFFSET(_xlfn.XLOOKUP($B13,Resultat!$D:$D,Resultat!$E:$E,-1,0),0,J$2-1) -> 0 | L13: =OFFSET(_xlfn.XLOOKUP($B13,Resultat!$D:$D,Resultat!$AL:$AL,-1,0),0,L$2-1) -> 0 | M13: =OFFSET(_xlfn.XLOOKUP($B13,Resultat!$D:$D,Resultat!$E:$E,-1,0),0,L$2-1) -> 0 | N13: =OFFSET(_xlfn.XLOOKUP($B13,Resultat!$D:$D,Resultat!$AL:$AL,-1,0),0,N$2-1) -> 0 | O13: =OFFSET(_xlfn.XLOOKUP($B13,Resultat!$D:$D,Resultat!$E:$E,-1,0),0,N$2-1) -> 0 | P13: =OFFSET(_xlfn.XLOOKUP($B13,Resultat!$D:$D,Resultat!$AL:$AL,-1,0),0,P$2-1) -> 0 | Q13: =OFFSET(_xlfn.XLOOKUP($B13,Resultat!$D:$D,Resultat!$E:$E,-1,0),0,P$2-1) -> 0 | R13: =OFFSET(_xlfn.XLOOKUP($B13,Resultat!$D:$D,Resultat!$AL:$AL,-1,0),0,R$2-1) -> 0 | S13: =OFFSET(_xlfn.XLOOKUP($B13,Resultat!$D:$D,Resultat!$E:$E,-1,0),0,R$2-1) -> 0 | T13: =OFFSET(_xlfn.XLOOKUP($B13,Resultat!$D:$D,Resultat!$AL:$AL,-1,0),0,T$2-1) -> 0 | U13: =OFFSET(_xlfn.XLOOKUP($B13,Resultat!$D:$D,Resultat!$E:$E,-1,0),0,T$2-1) -> 0 | V13: =OFFSET(_xlfn.XLOOKUP($B13,Resultat!$D:$D,Resultat!$AL:$AL,-1,0),0,V$2-1) -> 0 | W13: =OFFSET(_xlfn.XLOOKUP($B13,Resultat!$D:$D,Resultat!$E:$E,-1,0),0,V$2-1) -> 0 | X13: =OFFSET(_xlfn.XLOOKUP($B13,Resultat!$D:$D,Resultat!$AL:$AL,-1,0),0,X$2-1) -> 0 | Y13: =OFFSET(_xlfn.XLOOKUP($B13,Resultat!$D:$D,Resultat!$E:$E,-1,0),0,X$2-1) -> 0 | Z13: =OFFSET(_xlfn.XLOOKUP($B13,Resultat!$D:$D,Resultat!$AL:$AL,-1,0),0,Z$2-1) -> 0 | AA13: =OFFSET(_xlfn.XLOOKUP($B13,Resultat!$D:$D,Resultat!$E:$E,-1,0),0,Z$2-1) -> 0 | AB13: =OFFSET(_xlfn.XLOOKUP($B13,Resultat!$D:$D,Resultat!$AL:$AL,-1,0),0,AB$2-1) -> 0 | AC13: =OFFSET(_xlfn.XLOOKUP($B13,Resultat!$D:$D,Resultat!$E:$E,-1,0),0,AB$2-1) -> 0 | AD13: =OFFSET(_xlfn.XLOOKUP($B13,Resultat!$D:$D,Resultat!$AL:$AL,-1,0),0,AD$2-1) -> 0 | AE13: =OFFSET(_xlfn.XLOOKUP($B13,Resultat!$D:$D,Resultat!$E:$E,-1,0),0,AD$2-1) -> 0 | AF13: =OFFSET(_xlfn.XLOOKUP($B13,Resultat!$D:$D,Resultat!$AL:$AL,-1,0),0,AF$2-1) -> 0 | AG13: =OFFSET(_xlfn.XLOOKUP($B13,Resultat!$D:$D,Resultat!$E:$E,-1,0),0,AF$2-1) -> 0
A14: =_xlfn.XLOOKUP($B14,Resultat!$D:$D,Resultat!$Z:$Z,-1,0) -> 10 | B14: Arne Samuelsson | C14: =_xlfn.XLOOKUP($B14,Resultat!$D:$D,Resultat!$AA:$AA,-1,0) -> 10 | D14: =OFFSET(_xlfn.XLOOKUP($B14,Resultat!$D:$D,Resultat!$AL:$AL,-1,0),0,D$2-1) -> 10 | E14: =OFFSET(_xlfn.XLOOKUP($B14,Resultat!$D:$D,Resultat!$E:$E,-1,0),0,D$2-1) -> 28.9 | F14: =OFFSET(_xlfn.XLOOKUP($B14,Resultat!$D:$D,Resultat!$AL:$AL,-1,0),0,F$2-1) -> 0 | G14: =OFFSET(_xlfn.XLOOKUP($B14,Resultat!$D:$D,Resultat!$E:$E,-1,0),0,F$2-1) -> 0 | H14: =OFFSET(_xlfn.XLOOKUP($B14,Resultat!$D:$D,Resultat!$AL:$AL,-1,0),0,H$2-1) -> 0 | I14: =OFFSET(_xlfn.XLOOKUP($B14,Resultat!$D:$D,Resultat!$E:$E,-1,0),0,H$2-1) -> 0 | J14: =OFFSET(_xlfn.XLOOKUP($B14,Resultat!$D:$D,Resultat!$AL:$AL,-1,0),0,J$2-1) -> 0 | K14: =OFFSET(_xlfn.XLOOKUP($B14,Resultat!$D:$D,Resultat!$E:$E,-1,0),0,J$2-1) -> 0 | L14: =OFFSET(_xlfn.XLOOKUP($B14,Resultat!$D:$D,Resultat!$AL:$AL,-1,0),0,L$2-1) -> 0 | M14: =OFFSET(_xlfn.XLOOKUP($B14,Resultat!$D:$D,Resultat!$E:$E,-1,0),0,L$2-1) -> 0 | N14: =OFFSET(_xlfn.XLOOKUP($B14,Resultat!$D:$D,Resultat!$AL:$AL,-1,0),0,N$2-1) -> 0 | O14: =OFFSET(_xlfn.XLOOKUP($B14,Resultat!$D:$D,Resultat!$E:$E,-1,0),0,N$2-1) -> 0 | P14: =OFFSET(_xlfn.XLOOKUP($B14,Resultat!$D:$D,Resultat!$AL:$AL,-1,0),0,P$2-1) -> 0 | Q14: =OFFSET(_xlfn.XLOOKUP($B14,Resultat!$D:$D,Resultat!$E:$E,-1,0),0,P$2-1) -> 0 | R14: =OFFSET(_xlfn.XLOOKUP($B14,Resultat!$D:$D,Resultat!$AL:$AL,-1,0),0,R$2-1) -> 0 | S14: =OFFSET(_xlfn.XLOOKUP($B14,Resultat!$D:$D,Resultat!$E:$E,-1,0),0,R$2-1) -> 0 | T14: =OFFSET(_xlfn.XLOOKUP($B14,Resultat!$D:$D,Resultat!$AL:$AL,-1,0),0,T$2-1) -> 0 | U14: =OFFSET(_xlfn.XLOOKUP($B14,Resultat!$D:$D,Resultat!$E:$E,-1,0),0,T$2-1) -> 0 | V14: =OFFSET(_xlfn.XLOOKUP($B14,Resultat!$D:$D,Resultat!$AL:$AL,-1,0),0,V$2-1) -> 0 | W14: =OFFSET(_xlfn.XLOOKUP($B14,Resultat!$D:$D,Resultat!$E:$E,-1,0),0,V$2-1) -> 0 | X14: =OFFSET(_xlfn.XLOOKUP($B14,Resultat!$D:$D,Resultat!$AL:$AL,-1,0),0,X$2-1) -> 0 | Y14: =OFFSET(_xlfn.XLOOKUP($B14,Resultat!$D:$D,Resultat!$E:$E,-1,0),0,X$2-1) -> 0 | Z14: =OFFSET(_xlfn.XLOOKUP($B14,Resultat!$D:$D,Resultat!$AL:$AL,-1,0),0,Z$2-1) -> 0 | AA14: =OFFSET(_xlfn.XLOOKUP($B14,Resultat!$D:$D,Resultat!$E:$E,-1,0),0,Z$2-1) -> 0 | AB14: =OFFSET(_xlfn.XLOOKUP($B14,Resultat!$D:$D,Resultat!$AL:$AL,-1,0),0,AB$2-1) -> 0 | AC14: =OFFSET(_xlfn.XLOOKUP($B14,Resultat!$D:$D,Resultat!$E:$E,-1,0),0,AB$2-1) -> 0 | AD14: =OFFSET(_xlfn.XLOOKUP($B14,Resultat!$D:$D,Resultat!$AL:$AL,-1,0),0,AD$2-1) -> 0 | AE14: =OFFSET(_xlfn.XLOOKUP($B14,Resultat!$D:$D,Resultat!$E:$E,-1,0),0,AD$2-1) -> 0 | AF14: =OFFSET(_xlfn.XLOOKUP($B14,Resultat!$D:$D,Resultat!$AL:$AL,-1,0),0,AF$2-1) -> 0 | AG14: =OFFSET(_xlfn.XLOOKUP($B14,Resultat!$D:$D,Resultat!$E:$E,-1,0),0,AF$2-1) -> 0
A15: =_xlfn.XLOOKUP($B15,Resultat!$D:$D,Resultat!$Z:$Z,-1,0) -> 11 | B15: August Thelin | C15: =_xlfn.XLOOKUP($B15,Resultat!$D:$D,Resultat!$AA:$AA,-1,0) -> 11 | D15: =OFFSET(_xlfn.XLOOKUP($B15,Resultat!$D:$D,Resultat!$AL:$AL,-1,0),0,D$2-1) -> 11 | E15: =OFFSET(_xlfn.XLOOKUP($B15,Resultat!$D:$D,Resultat!$E:$E,-1,0),0,D$2-1) -> 28.34 | F15: =OFFSET(_xlfn.XLOOKUP($B15,Resultat!$D:$D,Resultat!$AL:$AL,-1,0),0,F$2-1) -> 0 | G15: =OFFSET(_xlfn.XLOOKUP($B15,Resultat!$D:$D,Resultat!$E:$E,-1,0),0,F$2-1) -> 0 | H15: =OFFSET(_xlfn.XLOOKUP($B15,Resultat!$D:$D,Resultat!$AL:$AL,-1,0),0,H$2-1) -> 0 | I15: =OFFSET(_xlfn.XLOOKUP($B15,Resultat!$D:$D,Resultat!$E:$E,-1,0),0,H$2-1) -> 0 | J15: =OFFSET(_xlfn.XLOOKUP($B15,Resultat!$D:$D,Resultat!$AL:$AL,-1,0),0,J$2-1) -> 0 | K15: =OFFSET(_xlfn.XLOOKUP($B15,Resultat!$D:$D,Resultat!$E:$E,-1,0),0,J$2-1) -> 0 | L15: =OFFSET(_xlfn.XLOOKUP($B15,Resultat!$D:$D,Resultat!$AL:$AL,-1,0),0,L$2-1) -> 0 | M15: =OFFSET(_xlfn.XLOOKUP($B15,Resultat!$D:$D,Resultat!$E:$E,-1,0),0,L$2-1) -> 0 | N15: =OFFSET(_xlfn.XLOOKUP($B15,Resultat!$D:$D,Resultat!$AL:$AL,-1,0),0,N$2-1) -> 0 | O15: =OFFSET(_xlfn.XLOOKUP($B15,Resultat!$D:$D,Resultat!$E:$E,-1,0),0,N$2-1) -> 0 | P15: =OFFSET(_xlfn.XLOOKUP($B15,Resultat!$D:$D,Resultat!$AL:$AL,-1,0),0,P$2-1) -> 0 | Q15: =OFFSET(_xlfn.XLOOKUP($B15,Resultat!$D:$D,Resultat!$E:$E,-1,0),0,P$2-1) -> 0 | R15: =OFFSET(_xlfn.XLOOKUP($B15,Resultat!$D:$D,Resultat!$AL:$AL,-1,0),0,R$2-1) -> 0 | S15: =OFFSET(_xlfn.XLOOKUP($B15,Resultat!$D:$D,Resultat!$E:$E,-1,0),0,R$2-1) -> 0 | T15: =OFFSET(_xlfn.XLOOKUP($B15,Resultat!$D:$D,Resultat!$AL:$AL,-1,0),0,T$2-1) -> 0 | U15: =OFFSET(_xlfn.XLOOKUP($B15,Resultat!$D:$D,Resultat!$E:$E,-1,0),0,T$2-1) -> 0 | V15: =OFFSET(_xlfn.XLOOKUP($B15,Resultat!$D:$D,Resultat!$AL:$AL,-1,0),0,V$2-1) -> 0 | W15: =OFFSET(_xlfn.XLOOKUP($B15,Resultat!$D:$D,Resultat!$E:$E,-1,0),0,V$2-1) -> 0 | X15: =OFFSET(_xlfn.XLOOKUP($B15,Resultat!$D:$D,Resultat!$AL:$AL,-1,0),0,X$2-1) -> 0 | Y15: =OFFSET(_xlfn.XLOOKUP($B15,Resultat!$D:$D,Resultat!$E:$E,-1,0),0,X$2-1) -> 0 | Z15: =OFFSET(_xlfn.XLOOKUP($B15,Resultat!$D:$D,Resultat!$AL:$AL,-1,0),0,Z$2-1) -> 0 | AA15: =OFFSET(_xlfn.XLOOKUP($B15,Resultat!$D:$D,Resultat!$E:$E,-1,0),0,Z$2-1) -> 0 | AB15: =OFFSET(_xlfn.XLOOKUP($B15,Resultat!$D:$D,Resultat!$AL:$AL,-1,0),0,AB$2-1) -> 0 | AC15: =OFFSET(_xlfn.XLOOKUP($B15,Resultat!$D:$D,Resultat!$E:$E,-1,0),0,AB$2-1) -> 0 | AD15: =OFFSET(_xlfn.XLOOKUP($B15,Resultat!$D:$D,Resultat!$AL:$AL,-1,0),0,AD$2-1) -> 0 | AE15: =OFFSET(_xlfn.XLOOKUP($B15,Resultat!$D:$D,Resultat!$E:$E,-1,0),0,AD$2-1) -> 0 | AF15: =OFFSET(_xlfn.XLOOKUP($B15,Resultat!$D:$D,Resultat!$AL:$AL,-1,0),0,AF$2-1) -> 0 | AG15: =OFFSET(_xlfn.XLOOKUP($B15,Resultat!$D:$D,Resultat!$E:$E,-1,0),0,AF$2-1) -> 0
A16: =_xlfn.XLOOKUP($B16,Resultat!$D:$D,Resultat!$Z:$Z,-1,0) -> 12 | B16: Michael Nordström | C16: =_xlfn.XLOOKUP($B16,Resultat!$D:$D,Resultat!$AA:$AA,-1,0) -> 12 | D16: =OFFSET(_xlfn.XLOOKUP($B16,Resultat!$D:$D,Resultat!$AL:$AL,-1,0),0,D$2-1) -> 12 | E16: =OFFSET(_xlfn.XLOOKUP($B16,Resultat!$D:$D,Resultat!$E:$E,-1,0),0,D$2-1) -> 27.73 | F16: =OFFSET(_xlfn.XLOOKUP($B16,Resultat!$D:$D,Resultat!$AL:$AL,-1,0),0,F$2-1) -> 0 | G16: =OFFSET(_xlfn.XLOOKUP($B16,Resultat!$D:$D,Resultat!$E:$E,-1,0),0,F$2-1) -> 0 | H16: =OFFSET(_xlfn.XLOOKUP($B16,Resultat!$D:$D,Resultat!$AL:$AL,-1,0),0,H$2-1) -> 0 | I16: =OFFSET(_xlfn.XLOOKUP($B16,Resultat!$D:$D,Resultat!$E:$E,-1,0),0,H$2-1) -> 0 | J16: =OFFSET(_xlfn.XLOOKUP($B16,Resultat!$D:$D,Resultat!$AL:$AL,-1,0),0,J$2-1) -> 0 | K16: =OFFSET(_xlfn.XLOOKUP($B16,Resultat!$D:$D,Resultat!$E:$E,-1,0),0,J$2-1) -> 0 | L16: =OFFSET(_xlfn.XLOOKUP($B16,Resultat!$D:$D,Resultat!$AL:$AL,-1,0),0,L$2-1) -> 0 | M16: =OFFSET(_xlfn.XLOOKUP($B16,Resultat!$D:$D,Resultat!$E:$E,-1,0),0,L$2-1) -> 0 | N16: =OFFSET(_xlfn.XLOOKUP($B16,Resultat!$D:$D,Resultat!$AL:$AL,-1,0),0,N$2-1) -> 0 | O16: =OFFSET(_xlfn.XLOOKUP($B16,Resultat!$D:$D,Resultat!$E:$E,-1,0),0,N$2-1) -> 0 | P16: =OFFSET(_xlfn.XLOOKUP($B16,Resultat!$D:$D,Resultat!$AL:$AL,-1,0),0,P$2-1) -> 0 | Q16: =OFFSET(_xlfn.XLOOKUP($B16,Resultat!$D:$D,Resultat!$E:$E,-1,0),0,P$2-1) -> 0 | R16: =OFFSET(_xlfn.XLOOKUP($B16,Resultat!$D:$D,Resultat!$AL:$AL,-1,0),0,R$2-1) -> 0 | S16: =OFFSET(_xlfn.XLOOKUP($B16,Resultat!$D:$D,Resultat!$E:$E,-1,0),0,R$2-1) -> 0 | T16: =OFFSET(_xlfn.XLOOKUP($B16,Resultat!$D:$D,Resultat!$AL:$AL,-1,0),0,T$2-1) -> 0 | U16: =OFFSET(_xlfn.XLOOKUP($B16,Resultat!$D:$D,Resultat!$E:$E,-1,0),0,T$2-1) -> 0 | V16: =OFFSET(_xlfn.XLOOKUP($B16,Resultat!$D:$D,Resultat!$AL:$AL,-1,0),0,V$2-1) -> 0 | W16: =OFFSET(_xlfn.XLOOKUP($B16,Resultat!$D:$D,Resultat!$E:$E,-1,0),0,V$2-1) -> 0 | X16: =OFFSET(_xlfn.XLOOKUP($B16,Resultat!$D:$D,Resultat!$AL:$AL,-1,0),0,X$2-1) -> 0 | Y16: =OFFSET(_xlfn.XLOOKUP($B16,Resultat!$D:$D,Resultat!$E:$E,-1,0),0,X$2-1) -> 0 | Z16: =OFFSET(_xlfn.XLOOKUP($B16,Resultat!$D:$D,Resultat!$AL:$AL,-1,0),0,Z$2-1) -> 0 | AA16: =OFFSET(_xlfn.XLOOKUP($B16,Resultat!$D:$D,Resultat!$E:$E,-1,0),0,Z$2-1) -> 0 | AB16: =OFFSET(_xlfn.XLOOKUP($B16,Resultat!$D:$D,Resultat!$AL:$AL,-1,0),0,AB$2-1) -> 0 | AC16: =OFFSET(_xlfn.XLOOKUP($B16,Resultat!$D:$D,Resultat!$E:$E,-1,0),0,AB$2-1) -> 0 | AD16: =OFFSET(_xlfn.XLOOKUP($B16,Resultat!$D:$D,Resultat!$AL:$AL,-1,0),0,AD$2-1) -> 0 | AE16: =OFFSET(_xlfn.XLOOKUP($B16,Resultat!$D:$D,Resultat!$E:$E,-1,0),0,AD$2-1) -> 0 | AF16: =OFFSET(_xlfn.XLOOKUP($B16,Resultat!$D:$D,Resultat!$AL:$AL,-1,0),0,AF$2-1) -> 0 | AG16: =OFFSET(_xlfn.XLOOKUP($B16,Resultat!$D:$D,Resultat!$E:$E,-1,0),0,AF$2-1) -> 0
... A36: =_xlfn.XLOOKUP($B36,Resultat!$D:$D,Resultat!$Z:$Z,-1,0) -> 15 | B36: Radical Ronald | C36: =_xlfn.XLOOKUP($B36,Resultat!$D:$D,Resultat!$AA:$AA,-1,0) -> 9999 | D36: =OFFSET(_xlfn.XLOOKUP($B36,Resultat!$D:$D,Resultat!$AL:$AL,-1,0),0,D$2-1) -> 15 | E36: =OFFSET(_xlfn.XLOOKUP($B36,Resultat!$D:$D,Resultat!$E:$E,-1,0),0,D$2-1) -> 0 | F36: =OFFSET(_xlfn.XLOOKUP($B36,Resultat!$D:$D,Resultat!$AL:$AL,-1,0),0,F$2-1) -> 0 | G36: =OFFSET(_xlfn.XLOOKUP($B36,Resultat!$D:$D,Resultat!$E:$E,-1,0),0,F$2-1) -> 0 | H36: =OFFSET(_xlfn.XLOOKUP($B36,Resultat!$D:$D,Resultat!$AL:$AL,-1,0),0,H$2-1) -> 0 | I36: =OFFSET(_xlfn.XLOOKUP($B36,Resultat!$D:$D,Resultat!$E:$E,-1,0),0,H$2-1) -> 0 | J36: =OFFSET(_xlfn.XLOOKUP($B36,Resultat!$D:$D,Resultat!$AL:$AL,-1,0),0,J$2-1) -> 0 | K36: =OFFSET(_xlfn.XLOOKUP($B36,Resultat!$D:$D,Resultat!$E:$E,-1,0),0,J$2-1) -> 0 | L36: =OFFSET(_xlfn.XLOOKUP($B36,Resultat!$D:$D,Resultat!$AL:$AL,-1,0),0,L$2-1) -> 0 | M36: =OFFSET(_xlfn.XLOOKUP($B36,Resultat!$D:$D,Resultat!$E:$E,-1,0),0,L$2-1) -> 0 | N36: =OFFSET(_xlfn.XLOOKUP($B36,Resultat!$D:$D,Resultat!$AL:$AL,-1,0),0,N$2-1) -> 0 | O36: =OFFSET(_xlfn.XLOOKUP($B36,Resultat!$D:$D,Resultat!$E:$E,-1,0),0,N$2-1) -> 0 | P36: =OFFSET(_xlfn.XLOOKUP($B36,Resultat!$D:$D,Resultat!$AL:$AL,-1,0),0,P$2-1) -> 0 | Q36: =OFFSET(_xlfn.XLOOKUP($B36,Resultat!$D:$D,Resultat!$E:$E,-1,0),0,P$2-1) -> 0 | R36: =OFFSET(_xlfn.XLOOKUP($B36,Resultat!$D:$D,Resultat!$AL:$AL,-1,0),0,R$2-1) -> 0 | S36: =OFFSET(_xlfn.XLOOKUP($B36,Resultat!$D:$D,Resultat!$E:$E,-1,0),0,R$2-1) -> 0 | T36: =OFFSET(_xlfn.XLOOKUP($B36,Resultat!$D:$D,Resultat!$AL:$AL,-1,0),0,T$2-1) -> 0 | U36: =OFFSET(_xlfn.XLOOKUP($B36,Resultat!$D:$D,Resultat!$E:$E,-1,0),0,T$2-1) -> 0 | V36: =OFFSET(_xlfn.XLOOKUP($B36,Resultat!$D:$D,Resultat!$AL:$AL,-1,0),0,V$2-1) -> 0 | W36: =OFFSET(_xlfn.XLOOKUP($B36,Resultat!$D:$D,Resultat!$E:$E,-1,0),0,V$2-1) -> 0 | X36: =OFFSET(_xlfn.XLOOKUP($B36,Resultat!$D:$D,Resultat!$AL:$AL,-1,0),0,X$2-1) -> 0 | Y36: =OFFSET(_xlfn.XLOOKUP($B36,Resultat!$D:$D,Resultat!$E:$E,-1,0),0,X$2-1) -> 0 | Z36: =OFFSET(_xlfn.XLOOKUP($B36,Resultat!$D:$D,Resultat!$AL:$AL,-1,0),0,Z$2-1) -> 0 | AA36: =OFFSET(_xlfn.XLOOKUP($B36,Resultat!$D:$D,Resultat!$E:$E,-1,0),0,Z$2-1) -> 0 | AB36: =OFFSET(_xlfn.XLOOKUP($B36,Resultat!$D:$D,Resultat!$AL:$AL,-1,0),0,AB$2-1) -> 0 | AC36: =OFFSET(_xlfn.XLOOKUP($B36,Resultat!$D:$D,Resultat!$E:$E,-1,0),0,AB$2-1) -> 0 | AD36: =OFFSET(_xlfn.XLOOKUP($B36,Resultat!$D:$D,Resultat!$AL:$AL,-1,0),0,AD$2-1) -> 0 | AE36: =OFFSET(_xlfn.XLOOKUP($B36,Resultat!$D:$D,Resultat!$E:$E,-1,0),0,AD$2-1) -> 0 | AF36: =OFFSET(_xlfn.XLOOKUP($B36,Resultat!$D:$D,Resultat!$AL:$AL,-1,0),0,AF$2-1) -> 0 | AG36: =OFFSET(_xlfn.XLOOKUP($B36,Resultat!$D:$D,Resultat!$E:$E,-1,0),0,AF$2-1) -> 0
C71: Ove Jansson

Sheet Resultat
A1: Nbr Kof | B1: Borträknat | E1: 45802 | F1: 45815 | G1: 45817 | H1: 45837
A2: =SUM(E2:X2) -> 1 | B2: =VLOOKUP(A2,Regler!A2:B30,2) -> 0 | E2: =IF(SUM(E5:E36)>0,1,0) -> 1 | F2: =IF(SUM(F5:F36)>0,1,0) -> 0 | G2: =IF(SUM(G5:G36)>0,1,0) -> 0 | H2: =IF(SUM(H5:H36)>0,1,0) -> 0 | I2: =IF(SUM(I5:I36)>0,1,0) -> 0 | J2: =IF(SUM(J5:J36)>0,1,0) -> 0 | K2: =IF(SUM(K5:K36)>0,1,0) -> 0 | L2: =IF(SUM(L5:L36)>0,1,0) -> 0 | ... S2: =IF(SUM(S5:S36)>0,1,0) -> 0 | AL2: =E2 -> 1 | AM2: =F2 -> 0 | AN2: =G2 -> 0 | AO2: =H2 -> 0 | AP2: =I2 -> 0 | AQ2: =J2 -> 0 | AR2: =K2 -> 0 | AS2: =L2 -> 0 | ... BE2: =X2 -> 0
A3: =SUM(B5:B36) -> 14 | E3: Avg of 5 10s | AB3: 9 | AC3: 8 | AD3: 7 | AE3: 6 | AF3: 5 | AG3: 4 | AH3: 3 | AI3: 2 | AJ3: 1 | AL3: Rank
A4: # | B4: Is incl. | C4: All KoF AVG | D4: Surf Dude | E4: 1 | F4: 2 | G4: 3 | H4: 4 | I4: 5 | J4: 6 | K4: 7 | L4: 8 | M4: 9 | N4: 10 | O4: 11 | P4: 12 | Q4: 13 | R4: 14 | S4: 15 | Z4: Total Rank | AA4: Sum-X | AB4: Sum-9 | AC4: Sum-8 | AD4: Sum-7 | AE4: Sum-6 | AF4: Sum-5 | AG4: Sum-4 | AH4: Sum-3 | AI4: Sum-2 | AJ4: Sum-1 | AK4: Sum | AL4: 1 | AM4: 2 | AN4: 3 | AO4: 4 | AP4: 5 | AQ4: 6 | AR4: 7 | AS4: 8 | AT4: 9 | AU4: 10 | AV4: 11 | AW4: 12 | AX4: 13 | AY4: 14 | AZ4: 15
A5: 1 | B5: =IF(C5>0,1,0) -> 0 | C5: =SUM($E5:$S5)/$A$2 -> 0 | D5: Anders Bjorkqvist | E5: {=_xlfn.XLOOKUP($D5&E$1,Results_of_the_day!$C:$C&Results_of_the_day!$B:$B,Results_of_the_day!$D:$D,0,0)} -> 0 | F5: {=_xlfn.XLOOKUP($D5&F$1,Results_of_the_day!$C:$C&Results_of_the_day!$B:$B,Results_of_the_day!$D:$D,0,0)} -> 0 | G5: {=_xlfn.XLOOKUP($D5&G$1,Results_of_the_day!$C:$C&Results_of_the_day!$B:$B,Results_of_the_day!$D:$D,0,0)} -> 0 | H5: {=_xlfn.XLOOKUP($D5&H$1,Results_of_the_day!$C:$C&Results_of_the_day!$B:$B,Results_of_the_day!$D:$D,0,0)} -> 0 | I5: {=_xlfn.XLOOKUP($D5&I$1,Results_of_the_day!$C:$C&Results_of_the_day!$B:$B,Results_of_the_day!$D:$D,0,0)} -> 0 | J5: {=_xlfn.XLOOKUP($D5&J$1,Results_of_the_day!$C:$C&Results_of_the_day!$B:$B,Results_of_the_day!$D:$D,0,0)} -> 0 | K5: {=_xlfn.XLOOKUP($D5&K$1,Results_of_the_day!$C:$C&Results_of_the_day!$B:$B,Results_of_the_day!$D:$D,0,0)} -> 0 | L5: {=_xlfn.XLOOKUP($D5&L$1,Results_of_the_day!$C:$C&Results_of_the_day!$B:$B,Results_of_the_day!$D:$D,0,0)} -> 0 | ... S5: {=_xlfn.XLOOKUP($D5&S$1,Results_of_the_day!$C:$C&Results_of_the_day!$B:$B,Results_of_the_day!$D:$D,0,0)} -> 0 | Z5: =_xlfn.RANK.EQ(AA5,$AA$5:$AA$36,1) -> 15 | AA5: =IF($B5,OFFSET(AK5,0,-$B$2),9999) -> 9999 | AB5: =AC5-LARGE($AL5:$AZ5,AB$3) -> 0 | AC5: =AD5-LARGE($AL5:$AZ5,AC$3) -> 0 | AD5: =AE5-LARGE($AL5:$AZ5,AD$3) -> 0 | AE5: =AF5-LARGE($AL5:$AZ5,AE$3) -> 0 | AF5: =AG5-LARGE($AL5:$AZ5,AF$3) -> 0 | AG5: =AH5-LARGE($AL5:$AZ5,AG$3) -> 0 | AH5: =AI5-LARGE($AL5:$AZ5,AH$3) -> 0 | AI5: =AJ5-LARGE($AL5:$AZ5,AI$3) -> 0 | AJ5: =AK5-LARGE($AL5:$AZ5,AJ$3) -> 0 | AK5: =SUM(AL5:AZ5) -> 15 | AL5: =IF(E5>0,_xlfn.RANK.EQ(E5,E$5:E$36,0),$A$3+1)*AL$2 -> 15 | AM5: =IF(F5>0,_xlfn.RANK.EQ(F5,F$5:F$36,0),$A$3+1)*AM$2 -> 0 | AN5: =IF(G5>0,_xlfn.RANK.EQ(G5,G$5:G$36,0),$A$3+1)*AN$2 -> 0 | AO5: =IF(H5>0,_xlfn.RANK.EQ(H5,H$5:H$36,0),$A$3+1)*AO$2 -> 0 | AP5: =IF(I5>0,_xlfn.RANK.EQ(I5,I$5:I$36,0),$A$3+1)*AP$2 -> 0 | AQ5: =IF(J5>0,_xlfn.RANK.EQ(J5,J$5:J$36,0),$A$3+1)*AQ$2 -> 0 | AR5: =IF(K5>0,_xlfn.RANK.EQ(K5,K$5:K$36,0),$A$3+1)*AR$2 -> 0 | AS5: =IF(L5>0,_xlfn.RANK.EQ(L5,L$5:L$36,0),$A$3+1)*AS$2 -> 0 | ... AZ5: =IF(S5>0,_xlfn.RANK.EQ(S5,S$5:S$36,0),$A$3+1)*AZ$2 -> 0
A6: 2 | B6: =IF(C6>0,1,0) -> 0 | C6: =SUM($E6:$S6)/$A$2 -> 0 | D6: Anders Nilsson | E6: {=_xlfn.XLOOKUP($D6&E$1,Results_of_the_day!$C:$C&Results_of_the_day!$B:$B,Results_of_the_day!$D:$D,0,0)} -> 0 | F6: {=_xlfn.XLOOKUP($D6&F$1,Results_of_the_day!$C:$C&Results_of_the_day!$B:$B,Results_of_the_day!$D:$D,0,0)} -> 0 | G6: {=_xlfn.XLOOKUP($D6&G$1,Results_of_the_day!$C:$C&Results_of_the_day!$B:$B,Results_of_the_day!$D:$D,0,0)} -> 0 | H6: {=_xlfn.XLOOKUP($D6&H$1,Results_of_the_day!$C:$C&Results_of_the_day!$B:$B,Results_of_the_day!$D:$D,0,0)} -> 0 | I6: {=_xlfn.XLOOKUP($D6&I$1,Results_of_the_day!$C:$C&Results_of_the_day!$B:$B,Results_of_the_day!$D:$D,0,0)} -> 0 | J6: {=_xlfn.XLOOKUP($D6&J$1,Results_of_the_day!$C:$C&Results_of_the_day!$B:$B,Results_of_the_day!$D:$D,0,0)} -> 0 | K6: {=_xlfn.XLOOKUP($D6&K$1,Results_of_the_day!$C:$C&Results_of_the_day!$B:$B,Results_of_the_day!$D:$D,0,0)} -> 0 | L6: {=_xlfn.XLOOKUP($D6&L$1,Results_of_the_day!$C:$C&Results_of_the_day!$B:$B,Results_of_the_day!$D:$D,0,0)} -> 0 | ... S6: {=_xlfn.XLOOKUP($D6&S$1,Results_of_the_day!$C:$C&Results_of_the_day!$B:$B,Results_of_the_day!$D:$D,0,0)} -> 0 | Z6: =_xlfn.RANK.EQ(AA6,$AA$5:$AA$36,1) -> 15 | AA6: =IF($B6,OFFSET(AK6,0,-$B$2),9999) -> 9999 | AB6: =AC6-LARGE($AL6:$AZ6,AB$3) -> 0 | AC6: =AD6-LARGE($AL6:$AZ6,AC$3) -> 0 | AD6: =AE6-LARGE($AL6:$AZ6,AD$3) -> 0 | AE6: =AF6-LARGE($AL6:$AZ6,AE$3) -> 0 | AF6: =AG6-LARGE($AL6:$AZ6,AF$3) -> 0 | AG6: =AH6-LARGE($AL6:$AZ6,AG$3) -> 0 | AH6: =AI6-LARGE($AL6:$AZ6,AH$3) -> 0 | AI6: =AJ6-LARGE($AL6:$AZ6,AI$3) -> 0 | AJ6: =AK6-LARGE($AL6:$AZ6,AJ$3) -> 0 | AK6: =SUM(AL6:AZ6) -> 15 | AL6: =IF(E6>0,_xlfn.RANK.EQ(E6,E$5:E$36,0),$A$3+1)*AL$2 -> 15 | AM6: =IF(F6>0,_xlfn.RANK.EQ(F6,F$5:F$36,0),$A$3+1)*AM$2 -> 0 | AN6: =IF(G6>0,_xlfn.RANK.EQ(G6,G$5:G$36,0),$A$3+1)*AN$2 -> 0 | AO6: =IF(H6>0,_xlfn.RANK.EQ(H6,H$5:H$36,0),$A$3+1)*AO$2 -> 0 | AP6: =IF(I6>0,_xlfn.RANK.EQ(I6,I$5:I$36,0),$A$3+1)*AP$2 -> 0 | AQ6: =IF(J6>0,_xlfn.RANK.EQ(J6,J$5:J$36,0),$A$3+1)*AQ$2 -> 0 | AR6: =IF(K6>0,_xlfn.RANK.EQ(K6,K$5:K$36,0),$A$3+1)*AR$2 -> 0 | AS6: =IF(L6>0,_xlfn.RANK.EQ(L6,L$5:L$36,0),$A$3+1)*AS$2 -> 0 | ... AZ6: =IF(S6>0,_xlfn.RANK.EQ(S6,S$5:S$36,0),$A$3+1)*AZ$2 -> 0
A7: 3 | B7: =IF(C7>0,1,0) -> 1 | C7: =SUM($E7:$S7)/$A$2 -> 28.9 | D7: Arne Samuelsson | E7: {=_xlfn.XLOOKUP($D7&E$1,Results_of_the_day!$C:$C&Results_of_the_day!$B:$B,Results_of_the_day!$D:$D,0,0)} -> 28.9 | F7: {=_xlfn.XLOOKUP($D7&F$1,Results_of_the_day!$C:$C&Results_of_the_day!$B:$B,Results_of_the_day!$D:$D,0,0)} -> 0 | G7: {=_xlfn.XLOOKUP($D7&G$1,Results_of_the_day!$C:$C&Results_of_the_day!$B:$B,Results_of_the_day!$D:$D,0,0)} -> 0 | H7: {=_xlfn.XLOOKUP($D7&H$1,Results_of_the_day!$C:$C&Results_of_the_day!$B:$B,Results_of_the_day!$D:$D,0,0)} -> 0 | I7: {=_xlfn.XLOOKUP($D7&I$1,Results_of_the_day!$C:$C&Results_of_the_day!$B:$B,Results_of_the_day!$D:$D,0,0)} -> 0 | J7: {=_xlfn.XLOOKUP($D7&J$1,Results_of_the_day!$C:$C&Results_of_the_day!$B:$B,Results_of_the_day!$D:$D,0,0)} -> 0 | K7: {=_xlfn.XLOOKUP($D7&K$1,Results_of_the_day!$C:$C&Results_of_the_day!$B:$B,Results_of_the_day!$D:$D,0,0)} -> 0 | L7: {=_xlfn.XLOOKUP($D7&L$1,Results_of_the_day!$C:$C&Results_of_the_day!$B:$B,Results_of_the_day!$D:$D,0,0)} -> 0 | ... S7: {=_xlfn.XLOOKUP($D7&S$1,Results_of_the_day!$C:$C&Results_of_the_day!$B:$B,Results_of_the_day!$D:$D,0,0)} -> 0 | Z7: =_xlfn.RANK.EQ(AA7,$AA$5:$AA$36,1) -> 10 | AA7: =IF($B7,OFFSET(AK7,0,-$B$2),9999) -> 10 | AB7: =AC7-LARGE($AL7:$AZ7,AB$3) -> 0 | AC7: =AD7-LARGE($AL7:$AZ7,AC$3) -> 0 | AD7: =AE7-LARGE($AL7:$AZ7,AD$3) -> 0 | AE7: =AF7-LARGE($AL7:$AZ7,AE$3) -> 0 | AF7: =AG7-LARGE($AL7:$AZ7,AF$3) -> 0 | AG7: =AH7-LARGE($AL7:$AZ7,AG$3) -> 0 | AH7: =AI7-LARGE($AL7:$AZ7,AH$3) -> 0 | AI7: =AJ7-LARGE($AL7:$AZ7,AI$3) -> 0 | AJ7: =AK7-LARGE($AL7:$AZ7,AJ$3) -> 0 | AK7: =SUM(AL7:AZ7) -> 10 | AL7: =IF(E7>0,_xlfn.RANK.EQ(E7,E$5:E$36,0),$A$3+1)*AL$2 -> 10 | AM7: =IF(F7>0,_xlfn.RANK.EQ(F7,F$5:F$36,0),$A$3+1)*AM$2 -> 0 | AN7: =IF(G7>0,_xlfn.RANK.EQ(G7,G$5:G$36,0),$A$3+1)*AN$2 -> 0 | AO7: =IF(H7>0,_xlfn.RANK.EQ(H7,H$5:H$36,0),$A$3+1)*AO$2 -> 0 | AP7: =IF(I7>0,_xlfn.RANK.EQ(I7,I$5:I$36,0),$A$3+1)*AP$2 -> 0 | AQ7: =IF(J7>0,_xlfn.RANK.EQ(J7,J$5:J$36,0),$A$3+1)*AQ$2 -> 0 | AR7: =IF(K7>0,_xlfn.RANK.EQ(K7,K$5:K$36,0),$A$3+1)*AR$2 -> 0 | AS7: =IF(L7>0,_xlfn.RANK.EQ(L7,L$5:L$36,0),$A$3+1)*AS$2 -> 0 | ... AZ7: =IF(S7>0,_xlfn.RANK.EQ(S7,S$5:S$36,0),$A$3+1)*AZ$2 -> 0
A8: 4 | B8: =IF(C8>0,1,0) -> 1 | C8: =SUM($E8:$S8)/$A$2 -> 28.34 | D8: August Thelin | E8: {=_xlfn.XLOOKUP($D8&E$1,Results_of_the_day!$C:$C&Results_of_the_day!$B:$B,Results_of_the_day!$D:$D,0,0)} -> 28.34 | F8: {=_xlfn.XLOOKUP($D8&F$1,Results_of_the_day!$C:$C&Results_of_the_day!$B:$B,Results_of_the_day!$D:$D,0,0)} -> 0 | G8: {=_xlfn.XLOOKUP($D8&G$1,Results_of_the_day!$C:$C&Results_of_the_day!$B:$B,Results_of_the_day!$D:$D,0,0)} -> 0 | H8: {=_xlfn.XLOOKUP($D8&H$1,Results_of_the_day!$C:$C&Results_of_the_day!$B:$B,Results_of_the_day!$D:$D,0,0)} -> 0 | I8: {=_xlfn.XLOOKUP($D8&I$1,Results_of_the_day!$C:$C&Results_of_the_day!$B:$B,Results_of_the_day!$D:$D,0,0)} -> 0 | J8: {=_xlfn.XLOOKUP($D8&J$1,Results_of_the_day!$C:$C&Results_of_the_day!$B:$B,Results_of_the_day!$D:$D,0,0)} -> 0 | K8: {=_xlfn.XLOOKUP($D8&K$1,Results_of_the_day!$C:$C&Results_of_the_day!$B:$B,Results_of_the_day!$D:$D,0,0)} -> 0 | L8: {=_xlfn.XLOOKUP($D8&L$1,Results_of_the_day!$C:$C&Results_of_the_day!$B:$B,Results_of_the_day!$D:$D,0,0)} -> 0 | ... S8: {=_xlfn.XLOOKUP($D8&S$1,Results_of_the_day!$C:$C&Results_of_the_day!$B:$B,Results_of_the_day!$D:$D,0,0)} -> 0 | Z8: =_xlfn.RANK.EQ(AA8,$AA$5:$AA$36,1) -> 11 | AA8: =IF($B8,OFFSET(AK8,0,-$B$2),9999) -> 11 | AB8: =AC8-LARGE($AL8:$AZ8,AB$3) -> 0 | AC8: =AD8-LARGE($AL8:$AZ8,AC$3) -> 0 | AD8: =AE8-LARGE($AL8:$AZ8,AD$3) -> 0 | AE8: =AF8-LARGE($AL8:$AZ8,AE$3) -> 0 | AF8: =AG8-LARGE($AL8:$AZ8,AF$3) -> 0 | AG8: =AH8-LARGE($AL8:$AZ8,AG$3) -> 0 | AH8: =AI8-LARGE($AL8:$AZ8,AH$3) -> 0 | AI8: =AJ8-LARGE($AL8:$AZ8,AI$3) -> 0 | AJ8: =AK8-LARGE($AL8:$AZ8,AJ$3) -> 0 | AK8: =SUM(AL8:AZ8) -> 11 | AL8: =IF(E8>0,_xlfn.RANK.EQ(E8,E$5:E$36,0),$A$3+1)*AL$2 -> 11 | AM8: =IF(F8>0,_xlfn.RANK.EQ(F8,F$5:F$36,0),$A$3+1)*AM$2 -> 0 | AN8: =IF(G8>0,_xlfn.RANK.EQ(G8,G$5:G$36,0),$A$3+1)*AN$2 -> 0 | AO8: =IF(H8>0,_xlfn.RANK.EQ(H8,H$5:H$36,0),$A$3+1)*AO$2 -> 0 | AP8: =IF(I8>0,_xlfn.RANK.EQ(I8,I$5:I$36,0),$A$3+1)*AP$2 -> 0 | AQ8: =IF(J8>0,_xlfn.RANK.EQ(J8,J$5:J$36,0),$A$3+1)*AQ$2 -> 0 | AR8: =IF(K8>0,_xlfn.RANK.EQ(K8,K$5:K$36,0),$A$3+1)*AR$2 -> 0 | AS8: =IF(L8>0,_xlfn.RANK.EQ(L8,L$5:L$36,0),$A$3+1)*AS$2 -> 0 | ... AZ8: =IF(S8>0,_xlfn.RANK.EQ(S8,S$5:S$36,0),$A$3+1)*AZ$2 -> 0
A9: 5 | B9: =IF(C9>0,1,0) -> 1 | C9: =SUM($E9:$S9)/$A$2 -> 26.47 | D9: Björn Johansson | E9: {=_xlfn.XLOOKUP($D9&E$1,Results_of_the_day!$C:$C&Results_of_the_day!$B:$B,Results_of_the_day!$D:$D,0,0)} -> 26.47 | F9: {=_xlfn.XLOOKUP($D9&F$1,Results_of_the_day!$C:$C&Results_of_the_day!$B:$B,Results_of_the_day!$D:$D,0,0)} -> 0 | G9: {=_xlfn.XLOOKUP($D9&G$1,Results_of_the_day!$C:$C&Results_of_the_day!$B:$B,Results_of_the_day!$D:$D,0,0)} -> 0 | H9: {=_xlfn.XLOOKUP($D9&H$1,Results_of_the_day!$C:$C&Results_of_the_day!$B:$B,Results_of_the_day!$D:$D,0,0)} -> 0 | I9: {=_xlfn.XLOOKUP($D9&I$1,Results_of_the_day!$C:$C&Results_of_the_day!$B:$B,Results_of_the_day!$D:$D,0,0)} -> 0 | J9: {=_xlfn.XLOOKUP($D9&J$1,Results_of_the_day!$C:$C&Results_of_the_day!$B:$B,Results_of_the_day!$D:$D,0,0)} -> 0 | K9: {=_xlfn.XLOOKUP($D9&K$1,Results_of_the_day!$C:$C&Results_of_the_day!$B:$B,Results_of_the_day!$D:$D,0,0)} -> 0 | L9: {=_xlfn.XLOOKUP($D9&L$1,Results_of_the_day!$C:$C&Results_of_the_day!$B:$B,Results_of_the_day!$D:$D,0,0)} -> 0 | ... S9: {=_xlfn.XLOOKUP($D9&S$1,Results_of_the_day!$C:$C&Results_of_the_day!$B:$B,Results_of_the_day!$D:$D,0,0)} -> 0 | Z9: =_xlfn.RANK.EQ(AA9,$AA$5:$AA$36,1) -> 13 | AA9: =IF($B9,OFFSET(AK9,0,-$B$2),9999) -> 13 | AB9: =AC9-LARGE($AL9:$AZ9,AB$3) -> 0 | AC9: =AD9-LARGE($AL9:$AZ9,AC$3) -> 0 | AD9: =AE9-LARGE($AL9:$AZ9,AD$3) -> 0 | AE9: =AF9-LARGE($AL9:$AZ9,AE$3) -> 0 | AF9: =AG9-LARGE($AL9:$AZ9,AF$3) -> 0 | AG9: =AH9-LARGE($AL9:$AZ9,AG$3) -> 0 | AH9: =AI9-LARGE($AL9:$AZ9,AH$3) -> 0 | AI9: =AJ9-LARGE($AL9:$AZ9,AI$3) -> 0 | AJ9: =AK9-LARGE($AL9:$AZ9,AJ$3) -> 0 | AK9: =SUM(AL9:AZ9) -> 13 | AL9: =IF(E9>0,_xlfn.RANK.EQ(E9,E$5:E$36,0),$A$3+1)*AL$2 -> 13 | AM9: =IF(F9>0,_xlfn.RANK.EQ(F9,F$5:F$36,0),$A$3+1)*AM$2 -> 0 | AN9: =IF(G9>0,_xlfn.RANK.EQ(G9,G$5:G$36,0),$A$3+1)*AN$2 -> 0 | AO9: =IF(H9>0,_xlfn.RANK.EQ(H9,H$5:H$36,0),$A$3+1)*AO$2 -> 0 | AP9: =IF(I9>0,_xlfn.RANK.EQ(I9,I$5:I$36,0),$A$3+1)*AP$2 -> 0 | AQ9: =IF(J9>0,_xlfn.RANK.EQ(J9,J$5:J$36,0),$A$3+1)*AQ$2 -> 0 | AR9: =IF(K9>0,_xlfn.RANK.EQ(K9,K$5:K$36,0),$A$3+1)*AR$2 -> 0 | AS9: =IF(L9>0,_xlfn.RANK.EQ(L9,L$5:L$36,0),$A$3+1)*AS$2 -> 0 | ... AZ9: =IF(S9>0,_xlfn.RANK.EQ(S9,S$5:S$36,0),$A$3+1)*AZ$2 -> 0
A10: 6 | B10: =IF(C10>0,1,0) -> 0 | C10: =SUM($E10:$S10)/$A$2 -> 0 | D10: Bjorn Sandberg | E10: {=_xlfn.XLOOKUP($D10&E$1,Results_of_the_day!$C:$C&Results_of_the_day!$B:$B,Results_of_the_day!$D:$D,0,0)} -> 0 | F10: {=_xlfn.XLOOKUP($D10&F$1,Results_of_the_day!$C:$C&Results_of_the_day!$B:$B,Results_of_the_day!$D:$D,0,0)} -> 0 | G10: {=_xlfn.XLOOKUP($D10&G$1,Results_of_the_day!$C:$C&Results_of_the_day!$B:$B,Results_of_the_day!$D:$D,0,0)} -> 0 | H10: {=_xlfn.XLOOKUP($D10&H$1,Results_of_the_day!$C:$C&Results_of_the_day!$B:$B,Results_of_the_day!$D:$D,0,0)} -> 0 | I10: {=_xlfn.XLOOKUP($D10&I$1,Results_of_the_day!$C:$C&Results_of_the_day!$B:$B,Results_of_the_day!$D:$D,0,0)} -> 0 | J10: {=_xlfn.XLOOKUP($D10&J$1,Results_of_the_day!$C:$C&Results_of_the_day!$B:$B,Results_of_the_day!$D:$D,0,0)} -> 0 | K10: {=_xlfn.XLOOKUP($D10&K$1,Results_of_the_day!$C:$C&Results_of_the_day!$B:$B,Results_of_the_day!$D:$D,0,0)} -> 0 | L10: {=_xlfn.XLOOKUP($D10&L$1,Results_of_the_day!$C:$C&Results_of_the_day!$B:$B,Results_of_the_day!$D:$D,0,0)} -> 0 | ... S10: {=_xlfn.XLOOKUP($D10&S$1,Results_of_the_day!$C:$C&Results_of_the_day!$B:$B,Results_of_the_day!$D:$D,0,0)} -> 0 | Z10: =_xlfn.RANK.EQ(AA10,$AA$5:$AA$36,1) -> 15 | AA10: =IF($B10,OFFSET(AK10,0,-$B$2),9999) -> 9999 | AB10: =AC10-LARGE($AL10:$AZ10,AB$3) -> 0 | AC10: =AD10-LARGE($AL10:$AZ10,AC$3) -> 0 | AD10: =AE10-LARGE($AL10:$AZ10,AD$3) -> 0 | AE10: =AF10-LARGE($AL10:$AZ10,AE$3) -> 0 | AF10: =AG10-LARGE($AL10:$AZ10,AF$3) -> 0 | AG10: =AH10-LARGE($AL10:$AZ10,AG$3) -> 0 | AH10: =AI10-LARGE($AL10:$AZ10,AH$3) -> 0 | AI10: =AJ10-LARGE($AL10:$AZ10,AI$3) -> 0 | AJ10: =AK10-LARGE($AL10:$AZ10,AJ$3) -> 0 | AK10: =SUM(AL10:AZ10) -> 15 | AL10: =IF(E10>0,_xlfn.RANK.EQ(E10,E$5:E$36,0),$A$3+1)*AL$2 -> 15 | AM10: =IF(F10>0,_xlfn.RANK.EQ(F10,F$5:F$36,0),$A$3+1)*AM$2 -> 0 | AN10: =IF(G10>0,_xlfn.RANK.EQ(G10,G$5:G$36,0),$A$3+1)*AN$2 -> 0 | AO10: =IF(H10>0,_xlfn.RANK.EQ(H10,H$5:H$36,0),$A$3+1)*AO$2 -> 0 | AP10: =IF(I10>0,_xlfn.RANK.EQ(I10,I$5:I$36,0),$A$3+1)*AP$2 -> 0 | AQ10: =IF(J10>0,_xlfn.RANK.EQ(J10,J$5:J$36,0),$A$3+1)*AQ$2 -> 0 | AR10: =IF(K10>0,_xlfn.RANK.EQ(K10,K$5:K$36,0),$A$3+1)*AR$2 -> 0 | AS10: =IF(L10>0,_xlfn.RANK.EQ(L10,L$5:L$36,0),$A$3+1)*AS$2 -> 0 | ... AZ10: =IF(S10>0,_xlfn.RANK.EQ(S10,S$5:S$36,0),$A$3+1)*AZ$2 -> 0
A11: 7 | B11: =IF(C11>0,1,0) -> 0 | C11: =SUM($E11:$S11)/$A$2 -> 0 | D11: Daniel Borgelind | E11: {=_xlfn.XLOOKUP($D11&E$1,Results_of_the_day!$C:$C&Results_of_the_day!$B:$B,Results_of_the_day!$D:$D,0,0)} -> 0 | F11: {=_xlfn.XLOOKUP($D11&F$1,Results_of_the_day!$C:$C&Results_of_the_day!$B:$B,Results_of_the_day!$D:$D,0,0)} -> 0 | G11: {=_xlfn.XLOOKUP($D11&G$1,Results_of_the_day!$C:$C&Results_of_the_day!$B:$B,Results_of_the_day!$D:$D,0,0)} -> 0 | H11: {=_xlfn.XLOOKUP($D11&H$1,Results_of_the_day!$C:$C&Results_of_the_day!$B:$B,Results_of_the_day!$D:$D,0,0)} -> 0 | I11: {=_xlfn.XLOOKUP($D11&I$1,Results_of_the_day!$C:$C&Results_of_the_day!$B:$B,Results_of_the_day!$D:$D,0,0)} -> 0 | J11: {=_xlfn.XLOOKUP($D11&J$1,Results_of_the_day!$C:$C&Results_of_the_day!$B:$B,Results_of_the_day!$D:$D,0,0)} -> 0 | K11: {=_xlfn.XLOOKUP($D11&K$1,Results_of_the_day!$C:$C&Results_of_the_day!$B:$B,Results_of_the_day!$D:$D,0,0)} -> 0 | L11: {=_xlfn.XLOOKUP($D11&L$1,Results_of_the_day!$C:$C&Results_of_the_day!$B:$B,Results_of_the_day!$D:$D,0,0)} -> 0 | ... S11: {=_xlfn.XLOOKUP($D11&S$1,Results_of_the_day!$C:$C&Results_of_the_day!$B:$B,Results_of_the_day!$D:$D,0,0)} -> 0 | Z11: =_xlfn.RANK.EQ(AA11,$AA$5:$AA$36,1) -> 15 | AA11: =IF($B11,OFFSET(AK11,0,-$B$2),9999) -> 9999 | AB11: =AC11-LARGE($AL11:$AZ11,AB$3) -> 0 | AC11: =AD11-LARGE($AL11:$AZ11,AC$3) -> 0 | AD11: =AE11-LARGE($AL11:$AZ11,AD$3) -> 0 | AE11: =AF11-LARGE($AL11:$AZ11,AE$3) -> 0 | AF11: =AG11-LARGE($AL11:$AZ11,AF$3) -> 0 | AG11: =AH11-LARGE($AL11:$AZ11,AG$3) -> 0 | AH11: =AI11-LARGE($AL11:$AZ11,AH$3) -> 0 | AI11: =AJ11-LARGE($AL11:$AZ11,AI$3) -> 0 | AJ11: =AK11-LARGE($AL11:$AZ11,AJ$3) -> 0 | AK11: =SUM(AL11:AZ11) -> 15 | AL11: =IF(E11>0,_xlfn.RANK.EQ(E11,E$5:E$36,0),$A$3+1)*AL$2 -> 15 | AM11: =IF(F11>0,_xlfn.RANK.EQ(F11,F$5:F$36,0),$A$3+1)*AM$2 -> 0 | AN11: =IF(G11>0,_xlfn.RANK.EQ(G11,G$5:G$36,0),$A$3+1)*AN$2 -> 0 | AO11: =IF(H11>0,_xlfn.RANK.EQ(H11,H$5:H$36,0),$A$3+1)*AO$2 -> 0 | AP11: =IF(I11>0,_xlfn.RANK.EQ(I11,I$5:I$36,0),$A$3+1)*AP$2 -> 0 | AQ11: =IF(J11>0,_xlfn.RANK.EQ(J11,J$5:J$36,0),$A$3+1)*AQ$2 -> 0 | AR11: =IF(K11>0,_xlfn.RANK.EQ(K11,K$5:K$36,0),$A$3+1)*AR$2 -> 0 | AS11: =IF(L11>0,_xlfn.RANK.EQ(L11,L$5:L$36,0),$A$3+1)*AS$2 -> 0 | ... AZ11: =IF(S11>0,_xlfn.RANK.EQ(S11,S$5:S$36,0),$A$3+1)*AZ$2 -> 0
A12: 8 | B12: =IF(C12>0,1,0) -> 0 | C12: =SUM($E12:$S12)/$A$2 -> 0 | D12: Daniel E.A. Gustafsson | E12: {=_xlfn.XLOOKUP($D12&E$1,Results_of_the_day!$C:$C&Results_of_the_day!$B:$B,Results_of_the_day!$D:$D,0,0)} -> 0 | F12: {=_xlfn.XLOOKUP($D12&F$1,Results_of_the_day!$C:$C&Results_of_the_day!$B:$B,Results_of_the_day!$D:$D,0,0)} -> 0 | G12: {=_xlfn.XLOOKUP($D12&G$1,Results_of_the_day!$C:$C&Results_of_the_day!$B:$B,Results_of_the_day!$D:$D,0,0)} -> 0 | H12: {=_xlfn.XLOOKUP($D12&H$1,Results_of_the_day!$C:$C&Results_of_the_day!$B:$B,Results_of_the_day!$D:$D,0,0)} -> 0 | I12: {=_xlfn.XLOOKUP($D12&I$1,Results_of_the_day!$C:$C&Results_of_the_day!$B:$B,Results_of_the_day!$D:$D,0,0)} -> 0 | J12: {=_xlfn.XLOOKUP($D12&J$1,Results_of_the_day!$C:$C&Results_of_the_day!$B:$B,Results_of_the_day!$D:$D,0,0)} -> 0 | K12: {=_xlfn.XLOOKUP($D12&K$1,Results_of_the_day!$C:$C&Results_of_the_day!$B:$B,Results_of_the_day!$D:$D,0,0)} -> 0 | L12: {=_xlfn.XLOOKUP($D12&L$1,Results_of_the_day!$C:$C&Results_of_the_day!$B:$B,Results_of_the_day!$D:$D,0,0)} -> 0 | ... S12: {=_xlfn.XLOOKUP($D12&S$1,Results_of_the_day!$C:$C&Results_of_the_day!$B:$B,Results_of_the_day!$D:$D,0,0)} -> 0 | Z12: =_xlfn.RANK.EQ(AA12,$AA$5:$AA$36,1) -> 15 | AA12: =IF($B12,OFFSET(AK12,0,-$B$2),9999) -> 9999 | AB12: =AC12-LARGE($AL12:$AZ12,AB$3) -> 0 | AC12: =AD12-LARGE($AL12:$AZ12,AC$3) -> 0 | AD12: =AE12-LARGE($AL12:$AZ12,AD$3) -> 0 | AE12: =AF12-LARGE($AL12:$AZ12,AE$3) -> 0 | AF12: =AG12-LARGE($AL12:$AZ12,AF$3) -> 0 | AG12: =AH12-LARGE($AL12:$AZ12,AG$3) -> 0 | AH12: =AI12-LARGE($AL12:$AZ12,AH$3) -> 0 | AI12: =AJ12-LARGE($AL12:$AZ12,AI$3) -> 0 | AJ12: =AK12-LARGE($AL12:$AZ12,AJ$3) -> 0 | AK12: =SUM(AL12:AZ12) -> 15 | AL12: =IF(E12>0,_xlfn.RANK.EQ(E12,E$5:E$36,0),$A$3+1)*AL$2 -> 15 | AM12: =IF(F12>0,_xlfn.RANK.EQ(F12,F$5:F$36,0),$A$3+1)*AM$2 -> 0 | AN12: =IF(G12>0,_xlfn.RANK.EQ(G12,G$5:G$36,0),$A$3+1)*AN$2 -> 0 | AO12: =IF(H12>0,_xlfn.RANK.EQ(H12,H$5:H$36,0),$A$3+1)*AO$2 -> 0 | AP12: =IF(I12>0,_xlfn.RANK.EQ(I12,I$5:I$36,0),$A$3+1)*AP$2 -> 0 | AQ12: =IF(J12>0,_xlfn.RANK.EQ(J12,J$5:J$36,0),$A$3+1)*AQ$2 -> 0 | AR12: =IF(K12>0,_xlfn.RANK.EQ(K12,K$5:K$36,0),$A$3+1)*AR$2 -> 0 | AS12: =IF(L12>0,_xlfn.RANK.EQ(L12,L$5:L$36,0),$A$3+1)*AS$2 -> 0 | ... AZ12: =IF(S12>0,_xlfn.RANK.EQ(S12,S$5:S$36,0),$A$3+1)*AZ$2 -> 0
