Workbook

Sheet User
A1: # | B1: Alias | C1: Name | D1: UserId | E1: Link User | F1: Link Equip. | G1: Link Sessions | H1: UserDetails | I1: UserEquip. | J1: Sessions
A2: 1 | B2: BQ | C2: Anders Björkqvist | D2: 2558 | E2: =IF(D2>0,HYPERLINK(_xlfn.CONCAT(H2,D2),IF(B2="",C2,B2)),"") -> BQ | F2: =IF(D2>0,HYPERLINK(_xlfn.CONCAT(I2,D2),IF(B2="",C2,B2)),"") -> BQ | G2: =IF(D2>0,HYPERLINK(_xlfn.CONCAT(J2,D2),IF(B2="",C2,B2)),"") -> BQ | H2: =_xlfn.XLOOKUP($H$1,BaseUrl!$B:$B,BaseUrl!$C:$C,"",0) -> https://www.gps-speedsurfing.com/UserDetails?Id= | I2: =_xlfn.XLOOKUP($I$1,BaseUrl!$B:$B,BaseUrl!$C:$C,"",0) -> https://www.gps-speedsurfing.com/sessions/userequipment?userid= | J2: =_xlfn.XLOOKUP($J$1,BaseUrl!$B:$B,BaseUrl!$C:$C,"",0) -> https://www.gps-speedsurfing.com/sessions/usersessions?userid=
A3: 2 | B3: AN | C3: Anders Nilsson | D3: 25610 | E3: =IF(D3>0,HYPERLINK(_xlfn.CONCAT(H3,D3),IF(B3="",C3,B3)),"") -> AN | F3: =IF(D3>0,HYPERLINK(_xlfn.CONCAT(I3,D3),IF(B3="",C3,B3)),"") -> AN | G3: =IF(D3>0,HYPERLINK(_xlfn.CONCAT(J3,D3),IF(B3="",C3,B3)),"") -> AN | H3: =_xlfn.XLOOKUP($H$1,BaseUrl!$B:$B,BaseUrl!$C:$C,"",0) -> https://www.gps-speedsurfing.com/UserDetails?Id= | I3: =_xlfn.XLOOKUP($I$1,BaseUrl!$B:$B,BaseUrl!$C:$C,"",0) -> https://www.gps-speedsurfing.com/sessions/userequipment?userid= | J3: =_xlfn.XLOOKUP($J$1,BaseUrl!$B:$B,BaseUrl!$C:$C,"",0) -> https://www.gps-speedsurfing.com/sessions/usersessions?userid=
A4: 3 | B4: Arne | C4: Arne Samuelsson | D4: 497225 | E4: =IF(D4>0,HYPERLINK(_xlfn.CONCAT(H4,D4),IF(B4="",C4,B4)),"") -> Arne | F4: =IF(D4>0,HYPERLINK(_xlfn.CONCAT(I4,D4),IF(B4="",C4,B4)),"") -> Arne | G4: =IF(D4>0,HYPERLINK(_xlfn.CONCAT(J4,D4),IF(B4="",C4,B4)),"") -> Arne | H4: =_xlfn.XLOOKUP($H$1,BaseUrl!$B:$B,BaseUrl!$C:$C,"",0) -> https://www.gps-speedsurfing.com/UserDetails?Id= | I4: =_xlfn.XLOOKUP($I$1,BaseUrl!$B:$B,BaseUrl!$C:$C,"",0) -> https://www.gps-speedsurfing.com/sessions/userequipment?userid= | J4: =_xlfn.XLOOKUP($J$1,BaseUrl!$B:$B,BaseUrl!$C:$C,"",0) -> https://www.gps-speedsurfing.com/sessions/usersessions?userid=
A5: 4 | B5: AT | C5: August Thelin | D5: 469015 | E5: =IF(D5>0,HYPERLINK(_xlfn.CONCAT(H5,D5),IF(B5="",C5,B5)),"") -> AT | F5: =IF(D5>0,HYPERLINK(_xlfn.CONCAT(I5,D5),IF(B5="",C5,B5)),"") -> AT | G5: =IF(D5>0,HYPERLINK(_xlfn.CONCAT(J5,D5),IF(B5="",C5,B5)),"") -> AT | H5: =_xlfn.XLOOKUP($H$1,BaseUrl!$B:$B,BaseUrl!$C:$C,"",0) -> https://www.gps-speedsurfing.com/UserDetails?Id= | I5: =_xlfn.XLOOKUP($I$1,BaseUrl!$B:$B,BaseUrl!$C:$C,"",0) -> https://www.gps-speedsurfing.com/sessions/userequipment?userid= | J5: =_xlfn.XLOOKUP($J$1,BaseUrl!$B:$B,BaseUrl!$C:$C,"",0) -> https://www.gps-speedsurfing.com/sessions/usersessions?userid=
A6: 5 | B6: J&B | C6: Bergström | D6: 22378 | E6: =IF(D6>0,HYPERLINK(_xlfn.CONCAT(H6,D6),IF(B6="",C6,B6)),"") -> J&B | F6: =IF(D6>0,HYPERLINK(_xlfn.CONCAT(I6,D6),IF(B6="",C6,B6)),"") -> J&B | G6: =IF(D6>0,HYPERLINK(_xlfn.CONCAT(J6,D6),IF(B6="",C6,B6)),"") -> J&B | H6: =_xlfn.XLOOKUP($H$1,BaseUrl!$B:$B,BaseUrl!$C:$C,"",0) -> https://www.gps-speedsurfing.com/UserDetails?Id= | I6: =_xlfn.XLOOKUP($I$1,BaseUrl!$B:$B,BaseUrl!$C:$C,"",0) -> https://www.gps-speedsurfing.com/sessions/userequipment?userid= | J6: =_xlfn.XLOOKUP($J$1,BaseUrl!$B:$B,BaseUrl!$C:$C,"",0) -> https://www.gps-speedsurfing.com/sessions/usersessions?userid=
A7: 6 | B7: Berra | C7: Björn Johansson | D7: 23841 | E7: =IF(D7>0,HYPERLINK(_xlfn.CONCAT(H7,D7),IF(B7="",C7,B7)),"") -> Berra | F7: =IF(D7>0,HYPERLINK(_xlfn.CONCAT(I7,D7),IF(B7="",C7,B7)),"") -> Berra | G7: =IF(D7>0,HYPERLINK(_xlfn.CONCAT(J7,D7),IF(B7="",C7,B7)),"") -> Berra | H7: =_xlfn.XLOOKUP($H$1,BaseUrl!$B:$B,BaseUrl!$C:$C,"",0) -> https://www.gps-speedsurfing.com/UserDetails?Id= | I7: =_xlfn.XLOOKUP($I$1,BaseUrl!$B:$B,BaseUrl!$C:$C,"",0) -> https://www.gps-speedsurfing.com/sessions/userequipment?userid= | J7: =_xlfn.XLOOKUP($J$1,BaseUrl!$B:$B,BaseUrl!$C:$C,"",0) -> https://www.gps-speedsurfing.com/sessions/usersessions?userid=
A8: 7 | C8: Bjorn Sandberg | E8: =IF(D8>0,HYPERLINK(_xlfn.CONCAT(H8,D8),IF(B8="",C8,B8)),"") | F8: =IF(D8>0,HYPERLINK(_xlfn.CONCAT(I8,D8),IF(B8="",C8,B8)),"") | G8: =IF(D8>0,HYPERLINK(_xlfn.CONCAT(J8,D8),IF(B8="",C8,B8)),"") | H8: =_xlfn.XLOOKUP($H$1,BaseUrl!$B:$B,BaseUrl!$C:$C,"",0) -> https://www.gps-speedsurfing.com/UserDetails?Id= | I8: =_xlfn.XLOOKUP($I$1,BaseUrl!$B:$B,BaseUrl!$C:$C,"",0) -> https://www.gps-speedsurfing.com/sessions/userequipment?userid= | J8: =_xlfn.XLOOKUP($J$1,BaseUrl!$B:$B,BaseUrl!$C:$C,"",0) -> https://www.gps-speedsurfing.com/sessions/usersessions?userid=
A9: 8 | C9: Carl Ribbegaardh | E9: =IF(D9>0,HYPERLINK(_xlfn.CONCAT(H9,D9),IF(B9="",C9,B9)),"") | F9: =IF(D9>0,HYPERLINK(_xlfn.CONCAT(I9,D9),IF(B9="",C9,B9)),"") | G9: =IF(D9>0,HYPERLINK(_xlfn.CONCAT(J9,D9),IF(B9="",C9,B9)),"") | H9: =_xlfn.XLOOKUP($H$1,BaseUrl!$B:$B,BaseUrl!$C:$C,"",0) -> https://www.gps-speedsurfing.com/UserDetails?Id= | I9: =_xlfn.XLOOKUP($I$1,BaseUrl!$B:$B,BaseUrl!$C:$C,"",0) -> https://www.gps-speedsurfing.com/sessions/userequipment?userid= | J9: =_xlfn.XLOOKUP($J$1,BaseUrl!$B:$B,BaseUrl!$C:$C,"",0) -> https://www.gps-speedsurfing.com/sessions/usersessions?userid=
A10: 9 | B10: Borgelind | C10: Daniel Borgelind | D10: 587 | E10: =IF(D10>0,HYPERLINK(_xlfn.CONCAT(H10,D10),IF(B10="",C10,B10)),"") -> Borgelind | F10: =IF(D10>0,HYPERLINK(_xlfn.CONCAT(I10,D10),IF(B10="",C10,B10)),"") -> Borgelind | G10: =IF(D10>0,HYPERLINK(_xlfn.CONCAT(J10,D10),IF(B10="",C10,B10)),"") -> Borgelind | H10: =_xlfn.XLOOKUP($H$1,BaseUrl!$B:$B,BaseUrl!$C:$C,"",0) -> https://www.gps-speedsurfing.com/UserDetails?Id= | I10: =_xlfn.XLOOKUP($I$1,BaseUrl!$B:$B,BaseUrl!$C:$C,"",0) -> https://www.gps-speedsurfing.com/sessions/userequipment?userid= | J10: =_xlfn.XLOOKUP($J$1,BaseUrl!$B:$B,BaseUrl!$C:$C,"",0) -> https://www.gps-speedsurfing.com/sessions/usersessions?userid=
A11: 10 | B11: EA | C11: Daniel E.A. Gustafsson | D11: 4051 | E11: =IF(D11>0,HYPERLINK(_xlfn.CONCAT(H11,D11),IF(B11="",C11,B11)),"") -> EA | F11: =IF(D11>0,HYPERLINK(_xlfn.CONCAT(I11,D11),IF(B11="",C11,B11)),"") -> EA | G11: =IF(D11>0,HYPERLINK(_xlfn.CONCAT(J11,D11),IF(B11="",C11,B11)),"") -> EA | H11: =_xlfn.XLOOKUP($H$1,BaseUrl!$B:$B,BaseUrl!$C:$C,"",0) -> https://www.gps-speedsurfing.com/UserDetails?Id= | I11: =_xlfn.XLOOKUP($I$1,BaseUrl!$B:$B,BaseUrl!$C:$C,"",0) -> https://www.gps-speedsurfing.com/sessions/userequipment?userid= | J11: =_xlfn.XLOOKUP($J$1,BaseUrl!$B:$B,BaseUrl!$C:$C,"",0) -> https://www.gps-speedsurfing.com/sessions/usersessions?userid=
A12: 11 | B12: Grimberg | C12: Daniel Grimberg | D12: 27753 | E12: =IF(D12>0,HYPERLINK(_xlfn.CONCAT(H12,D12),IF(B12="",C12,B12)),"") -> Grimberg | F12: =IF(D12>0,HYPERLINK(_xlfn.CONCAT(I12,D12),IF(B12="",C12,B12)),"") -> Grimberg | G12: =IF(D12>0,HYPERLINK(_xlfn.CONCAT(J12,D12),IF(B12="",C12,B12)),"") -> Grimberg | H12: =_xlfn.XLOOKUP($H$1,BaseUrl!$B:$B,BaseUrl!$C:$C,"",0) -> https://www.gps-speedsurfing.com/UserDetails?Id= | I12: =_xlfn.XLOOKUP($I$1,BaseUrl!$B:$B,BaseUrl!$C:$C,"",0) -> https://www.gps-speedsurfing.com/sessions/userequipment?userid= | J12: =_xlfn.XLOOKUP($J$1,BaseUrl!$B:$B,BaseUrl!$C:$C,"",0) -> https://www.gps-speedsurfing.com/sessions/usersessions?userid=
A13: 12 | C13: Daniel Hoffmann | E13: =IF(D13>0,HYPERLINK(_xlfn.CONCAT(H13,D13),IF(B13="",C13,B13)),"") | F13: =IF(D13>0,HYPERLINK(_xlfn.CONCAT(I13,D13),IF(B13="",C13,B13)),"") | G13: =IF(D13>0,HYPERLINK(_xlfn.CONCAT(J13,D13),IF(B13="",C13,B13)),"") | H13: =_xlfn.XLOOKUP($H$1,BaseUrl!$B:$B,BaseUrl!$C:$C,"",0) -> https://www.gps-speedsurfing.com/UserDetails?Id= | I13: =_xlfn.XLOOKUP($I$1,BaseUrl!$B:$B,BaseUrl!$C:$C,"",0) -> https://www.gps-speedsurfing.com/sessions/userequipment?userid= | J13: =_xlfn.XLOOKUP($J$1,BaseUrl!$B:$B,BaseUrl!$C:$C,"",0) -> https://www.gps-speedsurfing.com/sessions/usersessions?userid=
A14: 13 | B14: Budda | C14: Daniel Tobiasson | D14: 1007 | E14: =IF(D14>0,HYPERLINK(_xlfn.CONCAT(H14,D14),IF(B14="",C14,B14)),"") -> Budda | F14: =IF(D14>0,HYPERLINK(_xlfn.CONCAT(I14,D14),IF(B14="",C14,B14)),"") -> Budda | G14: =IF(D14>0,HYPERLINK(_xlfn.CONCAT(J14,D14),IF(B14="",C14,B14)),"") -> Budda | H14: =_xlfn.XLOOKUP($H$1,BaseUrl!$B:$B,BaseUrl!$C:$C,"",0) -> https://www.gps-speedsurfing.com/UserDetails?Id= | I14: =_xlfn.XLOOKUP($I$1,BaseUrl!$B:$B,BaseUrl!$C:$C,"",0) -> https://www.gps-speedsurfing.com/sessions/userequipment?userid= | J14: =_xlfn.XLOOKUP($J$1,BaseUrl!$B:$B,BaseUrl!$C:$C,"",0) -> https://www.gps-speedsurfing.com/sessions/usersessions?userid=
A15: 14 | C15: David Giaina | E15: =IF(D15>0,HYPERLINK(_xlfn.CONCAT(H15,D15),IF(B15="",C15,B15)),"") | F15: =IF(D15>0,HYPERLINK(_xlfn.CONCAT(I15,D15),IF(B15="",C15,B15)),"") | G15: =IF(D15>0,HYPERLINK(_xlfn.CONCAT(J15,D15),IF(B15="",C15,B15)),"") | H15: =_xlfn.XLOOKUP($H$1,BaseUrl!$B:$B,BaseUrl!$C:$C,"",0) -> https://www.gps-speedsurfing.com/UserDetails?Id= | I15: =_xlfn.XLOOKUP($I$1,BaseUrl!$B:$B,BaseUrl!$C:$C,"",0) -> https://www.gps-speedsurfing.com/sessions/userequipment?userid= | J15: =_xlfn.XLOOKUP($J$1,BaseUrl!$B:$B,BaseUrl!$C:$C,"",0) -> https://www.gps-speedsurfing.com/sessions/usersessions?userid=
A16: 15 | B16: djong1 | C16: Dylan de Jong | D16: 53 | E16: =IF(D16>0,HYPERLINK(_xlfn.CONCAT(H16,D16),IF(B16="",C16,B16)),"") -> djong1 | F16: =IF(D16>0,HYPERLINK(_xlfn.CONCAT(I16,D16),IF(B16="",C16,B16)),"") -> djong1 | G16: =IF(D16>0,HYPERLINK(_xlfn.CONCAT(J16,D16),IF(B16="",C16,B16)),"") -> djong1 | H16: =_xlfn.XLOOKUP($H$1,BaseUrl!$B:$B,BaseUrl!$C:$C,"",0) -> https://www.gps-speedsurfing.com/UserDetails?Id= | I16: =_xlfn.XLOOKUP($I$1,BaseUrl!$B:$B,BaseUrl!$C:$C,"",0) -> https://www.gps-speedsurfing.com/sessions/userequipment?userid= | J16: =_xlfn.XLOOKUP($J$1,BaseUrl!$B:$B,BaseUrl!$C:$C,"",0) -> https://www.gps-speedsurfing.com/sessions/usersessions?userid=
A17: 16 | B17: E Larsson | C17: Erik Larsson | D17: 713 | E17: =IF(D17>0,HYPERLINK(_xlfn.CONCAT(H17,D17),IF(B17="",C17,B17)),"") -> E Larsson | F17: =IF(D17>0,HYPERLINK(_xlfn.CONCAT(I17,D17),IF(B17="",C17,B17)),"") -> E Larsson | G17: =IF(D17>0,HYPERLINK(_xlfn.CONCAT(J17,D17),IF(B17="",C17,B17)),"") -> E Larsson | H17: =_xlfn.XLOOKUP($H$1,BaseUrl!$B:$B,BaseUrl!$C:$C,"",0) -> https://www.gps-speedsurfing.com/UserDetails?Id= | I17: =_xlfn.XLOOKUP($I$1,BaseUrl!$B:$B,BaseUrl!$C:$C,"",0) -> https://www.gps-speedsurfing.com/sessions/userequipment?userid= | J17: =_xlfn.XLOOKUP($J$1,BaseUrl!$B:$B,BaseUrl!$C:$C,"",0) -> https://www.gps-speedsurfing.com/sessions/usersessions?userid=
A18: 17 | B18: Ryden | C18: Erik Ryden | E18: =IF(D18>0,HYPERLINK(_xlfn.CONCAT(H18,D18),IF(B18="",C18,B18)),"") | F18: =IF(D18>0,HYPERLINK(_xlfn.CONCAT(I18,D18),IF(B18="",C18,B18)),"") | G18: =IF(D18>0,HYPERLINK(_xlfn.CONCAT(J18,D18),IF(B18="",C18,B18)),"") | H18: =_xlfn.XLOOKUP($H$1,BaseUrl!$B:$B,BaseUrl!$C:$C,"",0) -> https://www.gps-speedsurfing.com/UserDetails?Id= | I18: =_xlfn.XLOOKUP($I$1,BaseUrl!$B:$B,BaseUrl!$C:$C,"",0) -> https://www.gps-speedsurfing.com/sessions/userequipment?userid= | J18: =_xlfn.XLOOKUP($J$1,BaseUrl!$B:$B,BaseUrl!$C:$C,"",0) -> https://www.gps-speedsurfing.com/sessions/usersessions?userid=
A19: 18 | B19: Plettil | C19: François Pettorelli | D19: 18200 | E19: =IF(D19>0,HYPERLINK(_xlfn.CONCAT(H19,D19),IF(B19="",C19,B19)),"") -> Plettil | F19: =IF(D19>0,HYPERLINK(_xlfn.CONCAT(I19,D19),IF(B19="",C19,B19)),"") -> Plettil | G19: =IF(D19>0,HYPERLINK(_xlfn.CONCAT(J19,D19),IF(B19="",C19,B19)),"") -> Plettil | H19: =_xlfn.XLOOKUP($H$1,BaseUrl!$B:$B,BaseUrl!$C:$C,"",0) -> https://www.gps-speedsurfing.com/UserDetails?Id= | I19: =_xlfn.XLOOKUP($I$1,BaseUrl!$B:$B,BaseUrl!$C:$C,"",0) -> https://www.gps-speedsurfing.com/sessions/userequipment?userid= | J19: =_xlfn.XLOOKUP($J$1,BaseUrl!$B:$B,BaseUrl!$C:$C,"",0) -> https://www.gps-speedsurfing.com/sessions/usersessions?userid=
A20: 19 | C20: Fredrk Wettervik Lööf | E20: =IF(D20>0,HYPERLINK(_xlfn.CONCAT(H20,D20),IF(B20="",C20,B20)),"") | F20: =IF(D20>0,HYPERLINK(_xlfn.CONCAT(I20,D20),IF(B20="",C20,B20)),"") | G20: =IF(D20>0,HYPERLINK(_xlfn.CONCAT(J20,D20),IF(B20="",C20,B20)),"") | H20: =_xlfn.XLOOKUP($H$1,BaseUrl!$B:$B,BaseUrl!$C:$C,"",0) -> https://www.gps-speedsurfing.com/UserDetails?Id= | I20: =_xlfn.XLOOKUP($I$1,BaseUrl!$B:$B,BaseUrl!$C:$C,"",0) -> https://www.gps-speedsurfing.com/sessions/userequipment?userid= | J20: =_xlfn.XLOOKUP($J$1,BaseUrl!$B:$B,BaseUrl!$C:$C,"",0) -> https://www.gps-speedsurfing.com/sessions/usersessions?userid=
A21: 20 | B21: Harald | C21: Harald Jeppsson | D21: 26470 | E21: =IF(D21>0,HYPERLINK(_xlfn.CONCAT(H21,D21),IF(B21="",C21,B21)),"") -> Harald | F21: =IF(D21>0,HYPERLINK(_xlfn.CONCAT(I21,D21),IF(B21="",C21,B21)),"") -> Harald | G21: =IF(D21>0,HYPERLINK(_xlfn.CONCAT(J21,D21),IF(B21="",C21,B21)),"") -> Harald | H21: =_xlfn.XLOOKUP($H$1,BaseUrl!$B:$B,BaseUrl!$C:$C,"",0) -> https://www.gps-speedsurfing.com/UserDetails?Id= | I21: =_xlfn.XLOOKUP($I$1,BaseUrl!$B:$B,BaseUrl!$C:$C,"",0) -> https://www.gps-speedsurfing.com/sessions/userequipment?userid= | J21: =_xlfn.XLOOKUP($J$1,BaseUrl!$B:$B,BaseUrl!$C:$C,"",0) -> https://www.gps-speedsurfing.com/sessions/usersessions?userid=
B22: Henke Torslanda | C22: Henrik Larsson | D22: 27859 | E22: =IF(D22>0,HYPERLINK(_xlfn.CONCAT(H22,D22),IF(B22="",C22,B22)),"") -> Henke Torslanda | F22: =IF(D22>0,HYPERLINK(_xlfn.CONCAT(I22,D22),IF(B22="",C22,B22)),"") -> Henke Torslanda | G22: =IF(D22>0,HYPERLINK(_xlfn.CONCAT(J22,D22),IF(B22="",C22,B22)),"") -> Henke Torslanda | H22: =_xlfn.XLOOKUP($H$1,BaseUrl!$B:$B,BaseUrl!$C:$C,"",0) -> https://www.gps-speedsurfing.com/UserDetails?Id= | I22: =_xlfn.XLOOKUP($I$1,BaseUrl!$B:$B,BaseUrl!$C:$C,"",0) -> https://www.gps-speedsurfing.com/sessions/userequipment?userid= | J22: =_xlfn.XLOOKUP($J$1,BaseUrl!$B:$B,BaseUrl!$C:$C,"",0) -> https://www.gps-speedsurfing.com/sessions/usersessions?userid=
A23: 21 | C23: Henrick Schill | E23: =IF(D23>0,HYPERLINK(_xlfn.CONCAT(H23,D23),IF(B23="",C23,B23)),"") | F23: =IF(D23>0,HYPERLINK(_xlfn.CONCAT(I23,D23),IF(B23="",C23,B23)),"") | G23: =IF(D23>0,HYPERLINK(_xlfn.CONCAT(J23,D23),IF(B23="",C23,B23)),"") | H23: =_xlfn.XLOOKUP($H$1,BaseUrl!$B:$B,BaseUrl!$C:$C,"",0) -> https://www.gps-speedsurfing.com/UserDetails?Id= | I23: =_xlfn.XLOOKUP($I$1,BaseUrl!$B:$B,BaseUrl!$C:$C,"",0) -> https://www.gps-speedsurfing.com/sessions/userequipment?userid= | J23: =_xlfn.XLOOKUP($J$1,BaseUrl!$B:$B,BaseUrl!$C:$C,"",0) -> https://www.gps-speedsurfing.com/sessions/usersessions?userid=
A24: 22 | B24: JesPer | C24: Jesper Kropp Axelsson | D24: 495257 | E24: =IF(D24>0,HYPERLINK(_xlfn.CONCAT(H24,D24),IF(B24="",C24,B24)),"") -> JesPer | F24: =IF(D24>0,HYPERLINK(_xlfn.CONCAT(I24,D24),IF(B24="",C24,B24)),"") -> JesPer | G24: =IF(D24>0,HYPERLINK(_xlfn.CONCAT(J24,D24),IF(B24="",C24,B24)),"") -> JesPer | H24: =_xlfn.XLOOKUP($H$1,BaseUrl!$B:$B,BaseUrl!$C:$C,"",0) -> https://www.gps-speedsurfing.com/UserDetails?Id= | I24: =_xlfn.XLOOKUP($I$1,BaseUrl!$B:$B,BaseUrl!$C:$C,"",0) -> https://www.gps-speedsurfing.com/sessions/userequipment?userid= | J24: =_xlfn.XLOOKUP($J$1,BaseUrl!$B:$B,BaseUrl!$C:$C,"",0) -> https://www.gps-speedsurfing.com/sessions/usersessions?userid=
A25: 23 | B25: Jocke | C25: Joakim Hansson | D25: 26191 | E25: =IF(D25>0,HYPERLINK(_xlfn.CONCAT(H25,D25),IF(B25="",C25,B25)),"") -> Jocke | F25: =IF(D25>0,HYPERLINK(_xlfn.CONCAT(I25,D25),IF(B25="",C25,B25)),"") -> Jocke | G25: =IF(D25>0,HYPERLINK(_xlfn.CONCAT(J25,D25),IF(B25="",C25,B25)),"") -> Jocke | H25: =_xlfn.XLOOKUP($H$1,BaseUrl!$B:$B,BaseUrl!$C:$C,"",0) -> https://www.gps-speedsurfing.com/UserDetails?Id= | I25: =_xlfn.XLOOKUP($I$1,BaseUrl!$B:$B,BaseUrl!$C:$C,"",0) -> https://www.gps-speedsurfing.com/sessions/userequipment?userid= | J25: =_xlfn.XLOOKUP($J$1,BaseUrl!$B:$B,BaseUrl!$C:$C,"",0) -> https://www.gps-speedsurfing.com/sessions/usersessions?userid=
A26: 24 | C26: Johan Gelander | D26: 604 | E26: =IF(D26>0,HYPERLINK(_xlfn.CONCAT(H26,D26),IF(B26="",C26,B26)),"") -> Johan Gelander | F26: =IF(D26>0,HYPERLINK(_xlfn.CONCAT(I26,D26),IF(B26="",C26,B26)),"") -> Johan Gelander | G26: =IF(D26>0,HYPERLINK(_xlfn.CONCAT(J26,D26),IF(B26="",C26,B26)),"") -> Johan Gelander | H26: =_xlfn.XLOOKUP($H$1,BaseUrl!$B:$B,BaseUrl!$C:$C,"",0) -> https://www.gps-speedsurfing.com/UserDetails?Id= | I26: =_xlfn.XLOOKUP($I$1,BaseUrl!$B:$B,BaseUrl!$C:$C,"",0) -> https://www.gps-speedsurfing.com/sessions/userequipment?userid= | J26: =_xlfn.XLOOKUP($J$1,BaseUrl!$B:$B,BaseUrl!$C:$C,"",0) -> https://www.gps-speedsurfing.com/sessions/usersessions?userid=
A27: 25 | B27: Millbergs | C27: Johan Millbergs | D27: 470910 | E27: =IF(D27>0,HYPERLINK(_xlfn.CONCAT(H27,D27),IF(B27="",C27,B27)),"") -> Millbergs | F27: =IF(D27>0,HYPERLINK(_xlfn.CONCAT(I27,D27),IF(B27="",C27,B27)),"") -> Millbergs | G27: =IF(D27>0,HYPERLINK(_xlfn.CONCAT(J27,D27),IF(B27="",C27,B27)),"") -> Millbergs | H27: =_xlfn.XLOOKUP($H$1,BaseUrl!$B:$B,BaseUrl!$C:$C,"",0) -> https://www.gps-speedsurfing.com/UserDetails?Id= | I27: =_xlfn.XLOOKUP($I$1,BaseUrl!$B:$B,BaseUrl!$C:$C,"",0) -> https://www.gps-speedsurfing.com/sessions/userequipment?userid= | J27: =_xlfn.XLOOKUP($J$1,BaseUrl!$B:$B,BaseUrl!$C:$C,"",0) -> https://www.gps-speedsurfing.com/sessions/usersessions?userid=
A28: 26 | B28: Joko | C28: Joko Mrnjavac | D28: 6195 | E28: =IF(D28>0,HYPERLINK(_xlfn.CONCAT(H28,D28),IF(B28="",C28,B28)),"") -> Joko | F28: =IF(D28>0,HYPERLINK(_xlfn.CONCAT(I28,D28),IF(B28="",C28,B28)),"") -> Joko | G28: =IF(D28>0,HYPERLINK(_xlfn.CONCAT(J28,D28),IF(B28="",C28,B28)),"") -> Joko | H28: =_xlfn.XLOOKUP($H$1,BaseUrl!$B:$B,BaseUrl!$C:$C,"",0) -> https://www.gps-speedsurfing.com/UserDetails?Id= | I28: =_xlfn.XLOOKUP($I$1,BaseUrl!$B:$B,BaseUrl!$C:$C,"",0) -> https://www.gps-speedsurfing.com/sessions/userequipment?userid= | J28: =_xlfn.XLOOKUP($J$1,BaseUrl!$B:$B,BaseUrl!$C:$C,"",0) -> https://www.gps-speedsurfing.com/sessions/usersessions?userid=
A29: 27 | B29: Bergström | C29: Jonas Bergström | D29: 469112 | E29: =IF(D29>0,HYPERLINK(_xlfn.CONCAT(H29,D29),IF(B29="",C29,B29)),"") -> Bergström | F29: =IF(D29>0,HYPERLINK(_xlfn.CONCAT(I29,D29),IF(B29="",C29,B29)),"") -> Bergström | G29: =IF(D29>0,HYPERLINK(_xlfn.CONCAT(J29,D29),IF(B29="",C29,B29)),"") -> Bergström | H29: =_xlfn.XLOOKUP($H$1,BaseUrl!$B:$B,BaseUrl!$C:$C,"",0) -> https://www.gps-speedsurfing.com/UserDetails?Id= | I29: =_xlfn.XLOOKUP($I$1,BaseUrl!$B:$B,BaseUrl!$C:$C,"",0) -> https://www.gps-speedsurfing.com/sessions/userequipment?userid= | J29: =_xlfn.XLOOKUP($J$1,BaseUrl!$B:$B,BaseUrl!$C:$C,"",0) -> https://www.gps-speedsurfing.com/sessions/usersessions?userid=
A30: 28 | B30: Göran | C30: Jonas Göransson | D30: 26663 | E30: =IF(D30>0,HYPERLINK(_xlfn.CONCAT(H30,D30),IF(B30="",C30,B30)),"") -> Göran | F30: =IF(D30>0,HYPERLINK(_xlfn.CONCAT(I30,D30),IF(B30="",C30,B30)),"") -> Göran | G30: =IF(D30>0,HYPERLINK(_xlfn.CONCAT(J30,D30),IF(B30="",C30,B30)),"") -> Göran | H30: =_xlfn.XLOOKUP($H$1,BaseUrl!$B:$B,BaseUrl!$C:$C,"",0) -> https://www.gps-speedsurfing.com/UserDetails?Id= | I30: =_xlfn.XLOOKUP($I$1,BaseUrl!$B:$B,BaseUrl!$C:$C,"",0) -> https://www.gps-speedsurfing.com/sessions/userequipment?userid= | J30: =_xlfn.XLOOKUP($J$1,BaseUrl!$B:$B,BaseUrl!$C:$C,"",0) -> https://www.gps-speedsurfing.com/sessions/usersessions?userid=
A31: 29 | B31: Sören | C31: Jonas Sörensen | D31: 494504 | E31: =IF(D31>0,HYPERLINK(_xlfn.CONCAT(H31,D31),IF(B31="",C31,B31)),"") -> Sören | F31: =IF(D31>0,HYPERLINK(_xlfn.CONCAT(I31,D31),IF(B31="",C31,B31)),"") -> Sören | G31: =IF(D31>0,HYPERLINK(_xlfn.CONCAT(J31,D31),IF(B31="",C31,B31)),"") -> Sören | H31: =_xlfn.XLOOKUP($H$1,BaseUrl!$B:$B,BaseUrl!$C:$C,"",0) -> https://www.gps-speedsurfing.com/UserDetails?Id= | I31: =_xlfn.XLOOKUP($I$1,BaseUrl!$B:$B,BaseUrl!$C:$C,"",0) -> https://www.gps-speedsurfing.com/sessions/userequipment?userid= | J31: =_xlfn.XLOOKUP($J$1,BaseUrl!$B:$B,BaseUrl!$C:$C,"",0) -> https://www.gps-speedsurfing.com/sessions/usersessions?userid=
A32: 30 | B32: Kate | C32: Kate Christensen | D32: 469141 | E32: =IF(D32>0,HYPERLINK(_xlfn.CONCAT(H32,D32),IF(B32="",C32,B32)),"") -> Kate | F32: =IF(D32>0,HYPERLINK(_xlfn.CONCAT(I32,D32),IF(B32="",C32,B32)),"") -> Kate | G32: =IF(D32>0,HYPERLINK(_xlfn.CONCAT(J32,D32),IF(B32="",C32,B32)),"") -> Kate | H32: =_xlfn.XLOOKUP($H$1,BaseUrl!$B:$B,BaseUrl!$C:$C,"",0) -> https://www.gps-speedsurfing.com/UserDetails?Id= | I32: =_xlfn.XLOOKUP($I$1,BaseUrl!$B:$B,BaseUrl!$C:$C,"",0) -> https://www.gps-speedsurfing.com/sessions/userequipment?userid= | J32: =_xlfn.XLOOKUP($J$1,BaseUrl!$B:$B,BaseUrl!$C:$C,"",0) -> https://www.gps-speedsurfing.com/sessions/usersessions?userid=
A33: 31 | B33: Kim | C33: Kim Born | E33: =IF(D33>0,HYPERLINK(_xlfn.CONCAT(H33,D33),IF(B33="",C33,B33)),"") | F33: =IF(D33>0,HYPERLINK(_xlfn.CONCAT(I33,D33),IF(B33="",C33,B33)),"") | G33: =IF(D33>0,HYPERLINK(_xlfn.CONCAT(J33,D33),IF(B33="",C33,B33)),"") | H33: =_xlfn.XLOOKUP($H$1,BaseUrl!$B:$B,BaseUrl!$C:$C,"",0) -> https://www.gps-speedsurfing.com/UserDetails?Id= | I33: =_xlfn.XLOOKUP($I$1,BaseUrl!$B:$B,BaseUrl!$C:$C,"",0) -> https://www.gps-speedsurfing.com/sessions/userequipment?userid= | J33: =_xlfn.XLOOKUP($J$1,BaseUrl!$B:$B,BaseUrl!$C:$C,"",0) -> https://www.gps-speedsurfing.com/sessions/usersessions?userid=
A34: 32 | B34: Richardsson | C34: Marcus Richardson | D34: 2250 | E34: =IF(D34>0,HYPERLINK(_xlfn.CONCAT(H34,D34),IF(B34="",C34,B34)),"") -> Richardsson | F34: =IF(D34>0,HYPERLINK(_xlfn.CONCAT(I34,D34),IF(B34="",C34,B34)),"") -> Richardsson | G34: =IF(D34>0,HYPERLINK(_xlfn.CONCAT(J34,D34),IF(B34="",C34,B34)),"") -> Richardsson | H34: =_xlfn.XLOOKUP($H$1,BaseUrl!$B:$B,BaseUrl!$C:$C,"",0) -> https://www.gps-speedsurfing.com/UserDetails?Id= | I34: =_xlfn.XLOOKUP($I$1,BaseUrl!$B:$B,BaseUrl!$C:$C,"",0) -> https://www.gps-speedsurfing.com/sessions/userequipment?userid= | J34: =_xlfn.XLOOKUP($J$1,BaseUrl!$B:$B,BaseUrl!$C:$C,"",0) -> https://www.gps-speedsurfing.com/sessions/usersessions?userid=
A35: 33 | B35: Emanuelsson | C35: Markus Emanuelsson | E35: =IF(D35>0,HYPERLINK(_xlfn.CONCAT(H35,D35),IF(B35="",C35,B35)),"") | F35: =IF(D35>0,HYPERLINK(_xlfn.CONCAT(I35,D35),IF(B35="",C35,B35)),"") | G35: =IF(D35>0,HYPERLINK(_xlfn.CONCAT(J35,D35),IF(B35="",C35,B35)),"") | H35: =_xlfn.XLOOKUP($H$1,BaseUrl!$B:$B,BaseUrl!$C:$C,"",0) -> https://www.gps-speedsurfing.com/UserDetails?Id= | I35: =_xlfn.XLOOKUP($I$1,BaseUrl!$B:$B,BaseUrl!$C:$C,"",0) -> https://www.gps-speedsurfing.com/sessions/userequipment?userid= | J35: =_xlfn.XLOOKUP($J$1,BaseUrl!$B:$B,BaseUrl!$C:$C,"",0) -> https://www.gps-speedsurfing.com/sessions/usersessions?userid=
A36: 34 | B36: Distner | C36: Martin Distner | D36: 48391 | E36: =IF(D36>0,HYPERLINK(_xlfn.CONCAT(H36,D36),IF(B36="",C36,B36)),"") -> Distner | F36: =IF(D36>0,HYPERLINK(_xlfn.CONCAT(I36,D36),IF(B36="",C36,B36)),"") -> Distner | G36: =IF(D36>0,HYPERLINK(_xlfn.CONCAT(J36,D36),IF(B36="",C36,B36)),"") -> Distner | H36: =_xlfn.XLOOKUP($H$1,BaseUrl!$B:$B,BaseUrl!$C:$C,"",0) -> https://www.gps-speedsurfing.com/UserDetails?Id= | I36: =_xlfn.XLOOKUP($I$1,BaseUrl!$B:$B,BaseUrl!$C:$C,"",0) -> https://www.gps-speedsurfing.com/sessions/userequipment?userid= | J36: =_xlfn.XLOOKUP($J$1,BaseUrl!$B:$B,BaseUrl!$C:$C,"",0) -> https://www.gps-speedsurfing.com/sessions/usersessions?userid=
A37: 35 | C37: Martin Hultman | E37: =IF(D37>0,HYPERLINK(_xlfn.CONCAT(H37,D37),IF(B37="",C37,B37)),"") | F37: =IF(D37>0,HYPERLINK(_xlfn.CONCAT(I37,D37),IF(B37="",C37,B37)),"") | G37: =IF(D37>0,HYPERLINK(_xlfn.CONCAT(J37,D37),IF(B37="",C37,B37)),"") | H37: =_xlfn.XLOOKUP($H$1,BaseUrl!$B:$B,BaseUrl!$C:$C,"",0) -> https://www.gps-speedsurfing.com/UserDetails?Id= | I37: =_xlfn.XLOOKUP($I$1,BaseUrl!$B:$B,BaseUrl!$C:$C,"",0) -> https://www.gps-speedsurfing.com/sessions/userequipment?userid= | J37: =_xlfn.XLOOKUP($J$1,BaseUrl!$B:$B,BaseUrl!$C:$C,"",0) -> https://www.gps-speedsurfing.com/sessions/usersessions?userid=
A38: 36 | C38: Mats Abrahamsson | E38: =IF(D38>0,HYPERLINK(_xlfn.CONCAT(H38,D38),IF(B38="",C38,B38)),"") | F38: =IF(D38>0,HYPERLINK(_xlfn.CONCAT(I38,D38),IF(B38="",C38,B38)),"") | G38: =IF(D38>0,HYPERLINK(_xlfn.CONCAT(J38,D38),IF(B38="",C38,B38)),"") | H38: =_xlfn.XLOOKUP($H$1,BaseUrl!$B:$B,BaseUrl!$C:$C,"",0) -> https://www.gps-speedsurfing.com/UserDetails?Id= | I38: =_xlfn.XLOOKUP($I$1,BaseUrl!$B:$B,BaseUrl!$C:$C,"",0) -> https://www.gps-speedsurfing.com/sessions/userequipment?userid= | J38: =_xlfn.XLOOKUP($J$1,BaseUrl!$B:$B,BaseUrl!$C:$C,"",0) -> https://www.gps-speedsurfing.com/sessions/usersessions?userid=
A39: 37 | B39: M Dahlberg | C39: Mats Dahlberg | D39: 4774 | E39: =IF(D39>0,HYPERLINK(_xlfn.CONCAT(H39,D39),IF(B39="",C39,B39)),"") -> M Dahlberg | F39: =IF(D39>0,HYPERLINK(_xlfn.CONCAT(I39,D39),IF(B39="",C39,B39)),"") -> M Dahlberg | G39: =IF(D39>0,HYPERLINK(_xlfn.CONCAT(J39,D39),IF(B39="",C39,B39)),"") -> M Dahlberg | H39: =_xlfn.XLOOKUP($H$1,BaseUrl!$B:$B,BaseUrl!$C:$C,"",0) -> https://www.gps-speedsurfing.com/UserDetails?Id= | I39: =_xlfn.XLOOKUP($I$1,BaseUrl!$B:$B,BaseUrl!$C:$C,"",0) -> https://www.gps-speedsurfing.com/sessions/userequipment?userid= | J39: =_xlfn.XLOOKUP($J$1,BaseUrl!$B:$B,BaseUrl!$C:$C,"",0) -> https://www.gps-speedsurfing.com/sessions/usersessions?userid=
A40: 38 | B40: Räkan | C40: Mats Morén | D40: 494474 | E40: =IF(D40>0,HYPERLINK(_xlfn.CONCAT(H40,D40),IF(B40="",C40,B40)),"") -> Räkan | F40: =IF(D40>0,HYPERLINK(_xlfn.CONCAT(I40,D40),IF(B40="",C40,B40)),"") -> Räkan | G40: =IF(D40>0,HYPERLINK(_xlfn.CONCAT(J40,D40),IF(B40="",C40,B40)),"") -> Räkan | H40: =_xlfn.XLOOKUP($H$1,BaseUrl!$B:$B,BaseUrl!$C:$C,"",0) -> https://www.gps-speedsurfing.com/UserDetails?Id= | I40: =_xlfn.XLOOKUP($I$1,BaseUrl!$B:$B,BaseUrl!$C:$C,"",0) -> https://www.gps-speedsurfing.com/sessions/userequipment?userid= | J40: =_xlfn.XLOOKUP($J$1,BaseUrl!$B:$B,BaseUrl!$C:$C,"",0) -> https://www.gps-speedsurfing.com/sessions/usersessions?userid=
...

Sheet BaseUrl
A1: # | B1: Name | C1: Url
A2: 1 | B2: UserEquip. | C2: https://www.gps-speedsurfing.com/sessions/userequipment?userid=
A3: 3 | B3: Sessions | C3: https://www.gps-speedsurfing.com/sessions/usersessions?userid=
A4: 4 | B4: UserDetails | C4: https://www.gps-speedsurfing.com/UserDetails?Id=
